Workbook
Name 프로젝트유형: [1]기준!$B$28:$B$34

Sheet 250117 (제출본-최초)
C3: 현대백화점 New 커머스 플랫폼 구축
C4: 45674
C6: 업무구분 | D6: 역할 | E6: 계약등급 | F6: 이름 | G6: 실등급 | H6: 계약투입일 | I6: 계약철수일 | J6: 실투입일 | K6: 실철수일 | L6: M1 (2월) | M6: M2 (3월) | N6: M3 (4월) | O6: M4 (5월) | P6: M5 (6월) | Q6: M6 (7월) | R6: M7 (8월) | S6: M8 (9월) | T6: M9 (10월) | U6: M10 (11월) | V6: M11 (12월) | W6: M12 (1월) | X6: M13 (2월) | Y6: M14 (3월) | Z6: M15 (4월) | AI6: M/M계
C7: 현장관리 | D7: 기획/디자인 총괄 (바이널씨 PM) | E7: 고급 | F7: 황세진 | G7: 특급 | H7: 45691 | I7: 46127 | L7: 1 | M7: 1 | N7: 1 | O7: 1 | P7: 1 | Q7: 1 | R7: 1 | S7: 1 | T7: 1 | U7: 1 | V7: 1 | W7: 1 | X7: 1 | Y7: 1 | Z7: 0.5 | AI7: =SUM(L7:AH7) -> 14.5
C8: 기획 | D8: PL (제작가이드, 산출물 검수) | E8: 고급 | F8: 고우정 | G8: 특급 | H8: 45705 | I8: 46127 | L8: 0.5 | M8: 1 | N8: 1 | O8: 1 | P8: 1 | Q8: 1 | R8: 1 | S8: 1 | T8: 1 | U8: 1 | V8: 1 | W8: 1 | X8: 1 | Y8: 1 | Z8: 0.5 | AI8: =SUM(L8:AH8) -> 14
D9: 앱웹 Front UXUI 상세 화면설계 | E9: 고급 | F9: 우미숙 | G9: 특급 | H9: 45691 | I9: 46096 | L9: 1 | M9: 1 | N9: 1 | O9: 1 | P9: 1 | Q9: 1 | R9: 1 | S9: 1 | T9: 1 | U9: 1 | V9: 1 | W9: 1 | X9: 1 | Y9: 0.5 | AI9: =SUM(L9:AH9) -> 13.5
E10: 고급 | F10: 정수정 | G10: - | H10: 45691 | I10: 46081 | L10: 1 | M10: 1 | N10: 1 | O10: 1 | P10: 1 | Q10: 1 | R10: 1 | S10: 1 | T10: 1 | U10: 1 | V10: 1 | W10: 1 | X10: 1 | AI10: =SUM(L10:AH10) -> 13
C11: 현장관리 | E11: 중급 | F11: 최철원 | G11: 고급 | H11: 45719 | I11: 46096 | L11: 0 | M11: 1 | N11: 1 | O11: 1 | P11: 1 | Q11: 1 | R11: 1 | S11: 1 | T11: 1 | U11: 1 | V11: 1 | W11: 1 | X11: 1 | Y11: 0.5 | AI11: =SUM(L11:AH11) -> 12.5
C12: 현장관리 | E12: 중급 | F12: 김강현 | G12: 고급 | H12: 45691 | I12: 46068 | L12: 1 | M12: 1 | N12: 1 | O12: 1 | P12: 1 | Q12: 1 | R12: 1 | S12: 1 | T12: 1 | U12: 1 | V12: 1 | W12: 1 | X12: 0.5 | AI12: =SUM(L12:AH12) -> 12.5
C13: 현장관리 | E13: 초급 | F13: 김세진 | G13: - | H13: 45691 | I13: 46022 | L13: 1 | M13: 1 | N13: 1 | O13: 1 | P13: 1 | Q13: 1 | R13: 1 | S13: 1 | T13: 1 | U13: 1 | V13: 1 | AI13: =SUM(L13:AH13) -> 11
C14: 현장관리 | E14: 초급 | F14: 이태림 | G14: - | H14: 45691 | I14: 45930 | L14: 1 | M14: 1 | N14: 1 | O14: 1 | P14: 1 | Q14: 1 | R14: 1 | S14: 1 | AI14: =SUM(L14:AH14) -> 8
C15: 현장관리 | E15: 고급 | AI15: 0
C16: 현장관리 | E16: 중급 | AI16: 0
C17: 현장관리 | E17: 초급 | AI17: 0
C18: 현장관리 | E18: 고급 | AI18: 0
C19: 현장관리 | E19: 중급 | AI19: 0
C20: 현장관리 | E20: 초급 | AI20: 0
C21: 현장관리 | D21: 합계 | I21: mm | L21: =SUM(L7:L20) -> 6.5 | M21: =SUM(M7:M20) -> 8 | N21: =SUM(N7:N20) -> 8 | O21: =SUM(O7:O20) -> 8 | P21: =SUM(P7:P20) -> 8 | Q21: =SUM(Q7:Q20) -> 8 | R21: =SUM(R7:R20) -> 8 | S21: =SUM(S7:S20) -> 8 | ... Z21: =SUM(Z7:Z20) -> 1 | AI21: =SUM(AI7:AI20) -> 99
C23: 디자인 | D23: PL (제작가이드, 산출물 검수) | E23: 중급 | F23: 배지효 | G23: - | H23: 45740 | I23: 46127 | M23: 0.25 | N23: 1 | O23: 1 | P23: 1 | Q23: 1 | R23: 1 | S23: 1 | T23: 1 | U23: 1 | V23: 1 | W23: 1 | X23: 1 | Y23: 1 | Z23: 0.5 | AI23: =SUM(M23:AH23) -> 12.75
D24: 앱웹 화면 UI 디자인 | E24: 중급 | F24: 윤혜림 | G24: - | H24: 45740 | I24: 46112 | M24: 0.25 | N24: 1 | O24: 1 | P24: 1 | Q24: 1 | R24: 1 | S24: 1 | T24: 1 | U24: 1 | V24: 1 | W24: 1 | X24: 1 | Y24: 1 | AI24: =SUM(M24:AH24) -> 12.25
E25: 중급 | F25: 박민정 | G25: 고급 | H25: 45748 | I25: 46112 | N25: 1 | O25: 1 | P25: 1 | Q25: 1 | R25: 1 | S25: 1 | T25: 1 | U25: 1 | V25: 1 | W25: 1 | X25: 1 | Y25: 1 | AI25: =SUM(M25:AH25) -> 12
C26: 디자인 | E26: 초급 | F26: 김민지 | G26: - | H26: 45740 | I26: 46112 | M26: 0.25 | N26: 1 | O26: 1 | P26: 1 | Q26: 1 | R26: 1 | S26: 1 | T26: 1 | U26: 1 | V26: 1 | W26: 1 | X26: 1 | Y26: 1 | AI26: =SUM(M26:AH26) -> 12.25
C27: 디자인 | E27: 초급 | F27: 이경진 | G27: - | H27: 45740 | I27: 45991 | M27: 0.25 | N27: 1 | O27: 1 | P27: 1 | Q27: 1 | R27: 1 | S27: 1 | T27: 1 | U27: 1 | AI27: =SUM(M27:AH27) -> 8.25
C28: 디자인 | E28: 초급 | F28: 민수연 | G28: - | H28: 45748 | I28: 45991 | N28: 1 | O28: 1 | P28: 1 | Q28: 1 | R28: 1 | S28: 1 | T28: 1 | U28: 1 | AI28: =SUM(M28:AH28) -> 8
C29: 디자인 | E29: 초급 | F29: 박성호 | G29: 고급 | H29: 45748 | I29: 45976 | N29: 1 | O29: 1 | P29: 1 | Q29: 1 | R29: 1 | S29: 1 | T29: 1 | U29: 0.5 | AI29: =SUM(M29:AH29) -> 7.5
C30: 디자인 | E30: 고급 | AI30: 0
C31: 디자인 | E31: 중급 | AI31: 0
C32: 디자인 | E32: 초급 | AI32: 0
C33: 디자인 | E33: 고급 | AI33: 0
C34: 디자인 | E34: 중급 | AI34: 0
C35: 디자인 | E35: 초급 | AI35: 0
C36: 디자인 | D36: 인터렉션 디자인 (Interaction 설계 및 구현) | E36: 고급 | AI36: 0
C37: 디자인 | E37: 중급 | AI37: 0
C38: 디자인 | E38: 초급 | AI38: 0
C39: 디자인 | D39: 합계 | I39: mm | L39: =SUM(L23:L38) -> 0 | M39: =SUM(M23:M38) -> 1 | N39: =SUM(N23:N38) -> 7 | O39: =SUM(O23:O38) -> 7 | P39: =SUM(P23:P38) -> 7 | Q39: =SUM(Q23:Q38) -> 7 | R39: =SUM(R23:R38) -> 7 | S39: =SUM(S23:S38) -> 7 | ... Z39: =SUM(Z23:Z38) -> 0.5 | AI39: =SUM(AI23:AI38) -> 73
C41: 합계 | I41: MM | L41: =L21+L39 -> 6.5 | M41: =M21+M39 -> 9 | N41: =N21+N39 -> 15 | O41: =O21+O39 -> 15 | P41: =P21+P39 -> 15 | Q41: =Q21+Q39 -> 15 | R41: =R21+R39 -> 15 | S41: =S21+S39 -> 15 | ... Z41: =Z21+Z39 -> 1.5 | AI41: =AI21+AI39 -> 172
S44: 등급별 계획공수 | X44: 계획공수
S45: 부문 | T45: 등급 | U45: 공수 | V45: 합계 | X45: 계약공수 | Z45: 172
S46: 기획 | T46: 고급 | U46: =SUMIF($E$7:$E$14,"고급",$AI$7:$AI$14) -> 55 | V46: =SUM(U46:U48) -> 99 | X46: 본사 추가지원 공수 | Z46: =204.5-Z45 -> 32.5
T47: 중급 | U47: =SUMIF($E$7:$E$14,"중급",$AI$7:$AI$14) -> 25 | X47: 총 가용 공수 | Z47: 204.5
...

Sheet @250217 (제출본-최종)
C3: 현대백화점 New 커머스 플랫폼 구축
C4: 45705
C5: 월별 인력 투입 계획
C6: 업무구분 | D6: 역할 | E6: 계약등급 | F6: 이름 | G6: 실등급 | H6: 계약투입일 | I6: 계약철수일 | J6: 실투입일 | K6: 실철수일 | L6: M1 (2월) | M6: M2 (3월) | N6: M3 (4월) | O6: M4 (5월) | P6: M5 (6월) | Q6: M6 (7월) | R6: M7 (8월) | S6: M8 (9월) | T6: M9 (10월) | U6: M10 (11월) | V6: M11 (12월) | W6: M12 (1월) | X6: M13 (2월) | Y6: M14 (3월) | Z6: M15 (4월) | AI6: M/M계
C7: 현장관리 | D7: 기획/디자인 총괄 (바이널씨 PM) | E7: 고급 | F7: 황세진 | G7: 특급 | H7: 45691 | I7: 46127 | L7: 1 | M7: 1 | N7: 1 | O7: 1 | P7: 1 | Q7: 1 | R7: 1 | S7: 1 | T7: 1 | U7: 1 | V7: 1 | W7: 1 | X7: 1 | Y7: 1 | Z7: 0.5 | AI7: =SUM(L7:AH7) -> 14.5
C8: 기획 | D8: PL (제작가이드, 산출물 검수) | E8: 고급 | F8: 고우정 | G8: 특급 | H8: 45705 | I8: 46127 | L8: 0.5 | M8: 1 | N8: 1 | O8: 1 | P8: 1 | Q8: 1 | R8: 1 | S8: 1 | T8: 1 | U8: 1 | V8: 1 | W8: 1 | X8: 1 | Y8: 1 | Z8: 0.5 | AI8: =SUM(L8:AH8) -> 14
D9: 앱웹 Front UXUI 상세 화면설계 | E9: 고급 | F9: 우미숙 | G9: 특급 | H9: 45691 | I9: 46096 | L9: 1 | M9: 1 | N9: 1 | O9: 1 | P9: 1 | Q9: 1 | R9: 1 | S9: 1 | T9: 1 | U9: 1 | V9: 0.5 | AI9: =SUM(L9:AH9) -> 10.5
E10: 고급 | F10: 정수정 | G10: 특급 | H10: 45691 | I10: 45989 | L10: 1 | M10: 1 | N10: 1 | O10: 1 | P10: 1 | Q10: 1 | R10: 1 | S10: 1 | T10: 1 | U10: 1 | AI10: =SUM(L10:AH10) -> 10
C11: 현장관리 | E11: 고급 | F11: TBD | G11: 고급 | H11: 45748 | I11: 45930 | N11: 1 | O11: 1 | P11: 1 | Q11: 1 | R11: 1 | S11: 1 | AI11: =SUM(L11:AH11) -> 6
C12: 현장관리 | E12: 중급 | F12: 김강현 | G12: 고급 | H12: 45691 | I12: 45960 | L12: 1 | M12: 1 | N12: 1 | O12: 1 | P12: 1 | Q12: 1 | R12: 1 | S12: 1 | T12: 1 | AI12: =SUM(L12:AH12) -> 9
C13: 현장관리 | E13: 중급 | F13: 장익준 | G13: 고급 | H13: 45720 | I13: 46022 | M13: 1 | N13: 1 | O13: 1 | P13: 1 | Q13: 1 | R13: 1 | S13: 1 | T13: 1 | U13: 1 | V13: 1 | AI13: =SUM(L13:AH13) -> 10
C14: 현장관리 | E14: 중급 | F14: 김영근 | G14: 고급 | H14: 45720 | I14: 45900 | M14: 1 | N14: 1 | O14: 1 | P14: 1 | Q14: 1 | R14: 1 | AI14: =SUM(L14:AH14) -> 6
C15: 현장관리 | E15: 초급 | F15: 김세진 | G15: 초급 | H15: 45691 | I15: 45991 | L15: 1 | M15: 1 | N15: 1 | O15: 1 | P15: 1 | Q15: 1 | R15: 1 | S15: 1 | T15: 1 | U15: 1 | AI15: =SUM(L15:AH15) -> 10
C16: 현장관리 | E16: 초급 | F16: 이태림 | G16: 초급 | H16: 45691 | I16: 45961 | L16: 1 | M16: 1 | N16: 1 | O16: 1 | P16: 1 | Q16: 1 | R16: 1 | S16: 1 | T16: 1 | AI16: =SUM(L16:Z16) -> 9
C17: 현장관리 | AI17: =SUM(L17:Z17) -> 0
C18: 현장관리 | AI18: =SUM(L18:AH18) -> 0
C19: 현장관리 | AI19: =SUM(L19:AH19) -> 0
C20: 현장관리 | AI20: =SUM(L20:AH20) -> 0
C21: 현장관리 | AI21: =SUM(L21:AH21) -> 0
C22: 현장관리 | AI22: =SUM(L22:AH22) -> 0
C23: 현장관리 | D23: 합계 | I23: mm | L23: =SUM(L7:L22) -> 6.5 | M23: =SUM(M7:M22) -> 9 | N23: =SUM(N7:N22) -> 10 | O23: =SUM(O7:O22) -> 10 | P23: =SUM(P7:P22) -> 10 | Q23: =SUM(Q7:Q22) -> 10 | R23: =SUM(R7:R22) -> 10 | S23: =SUM(S7:S22) -> 9 | ... Z23: =SUM(Z7:Z22) -> 1 | AI23: =SUM(AI7:AI22) -> 99
C25: 디자인 | D25: PL (제작가이드, 산출물 검수) | E25: 중급 | F25: 배지효 | G25: - | H25: 45726 | I25: 46127 | M25: 0.75 | N25: 1 | O25: 1 | P25: 1 | Q25: 1 | R25: 1 | S25: 1 | T25: 1 | U25: 1 | V25: 1 | W25: 1 | X25: 1 | Y25: 1 | Z25: 0.5 | AI25: =SUM(L25:AH25) -> 13.25
D26: 앱웹 화면 UI 디자인 | E26: 중급 | F26: 윤혜림 | G26: - | H26: 45726 | I26: 46127 | M26: 0.75 | N26: 1 | O26: 1 | P26: 1 | Q26: 1 | R26: 1 | S26: 1 | T26: 1 | U26: 1 | V26: 1 | W26: 1 | X26: 1 | Y26: 1 | Z26: 0.5 | AI26: =SUM(L26:AH26) -> 13.25
E27: 중급 | F27: 박민정 | G27: 고급 | H27: 45748 | I27: 46066 | N27: 1 | O27: 1 | P27: 1 | Q27: 1 | R27: 1 | S27: 1 | T27: 1 | U27: 1 | V27: 1 | W27: 1 | X27: 0.5 | AI27: =SUM(L27:AH27) -> 10.5
C28: 디자인 | E28: 초급 | F28: 김민지 | G28: - | H28: 45726 | I28: 46127 | M28: 0.75 | N28: 1 | O28: 1 | P28: 1 | Q28: 1 | R28: 1 | S28: 1 | T28: 1 | U28: 1 | V28: 1 | W28: 1 | X28: 1 | Y28: 1 | Z28: 0.5 | AI28: =SUM(L28:AH28) -> 13.25
C29: 디자인 | E29: 초급 | F29: 이경진 | G29: - | H29: 45748 | I29: 45961 | N29: 1 | O29: 1 | P29: 1 | Q29: 1 | R29: 1 | S29: 1 | T29: 1 | AI29: =SUM(L29:AH29) -> 7
C30: 디자인 | E30: 초급 | F30: 민수연 | G30: - | H30: 45726 | I30: 45989 | M30: 0.75 | N30: 1 | O30: 1 | P30: 1 | Q30: 1 | R30: 1 | S30: 1 | T30: 1 | U30: 1 | AI30: =SUM(L30:AH30) -> 8.75
C31: 디자인 | E31: 초급 | F31: 박성호 | G31: - | H31: 45748 | I31: 45961 | N31: 1 | O31: 1 | P31: 1 | Q31: 1 | R31: 1 | S31: 1 | T31: 1 | AI31: =SUM(L31:AH31) -> 7
C32: 디자인 | E32: 고급 | AI32: 0
C33: 디자인 | E33: 중급 | AI33: 0
C34: 디자인 | E34: 초급 | AI34: 0
C35: 디자인 | E35: 고급 | AI35: 0
C36: 디자인 | E36: 중급 | AI36: 0
C37: 디자인 | E37: 초급 | AI37: 0
C38: 디자인 | D38: 인터렉션 디자인 (Interaction 설계 및 구현) | E38: 고급 | AI38: 0
C39: 디자인 | E39: 중급 | AI39: 0
C40: 디자인 | E40: 초급 | AI40: 0
C41: 디자인 | D41: 합계 | I41: mm | L41: =SUM(L25:L40) -> 0 | M41: =SUM(M25:M40) -> 3 | N41: =SUM(N25:N40) -> 7 | O41: =SUM(O25:O40) -> 7 | P41: =SUM(P25:P40) -> 7 | Q41: =SUM(Q25:Q40) -> 7 | R41: =SUM(R25:R40) -> 7 | S41: =SUM(S25:S40) -> 7 | ... Z41: =SUM(Z25:Z40) -> 1.5 | AI41: =SUM(AI25:AI40) -> 73
C43: 합계 | I43: MM | L43: =L23+L41 -> 6.5 | M43: =M23+M41 -> 12 | N43: =N23+N41 -> 17 | O43: =O23+O41 -> 17 | P43: =P23+P41 -> 17 | Q43: =Q23+Q41 -> 17 | R43: =R23+R41 -> 17 | S43: =S23+S41 -> 16 | ... Z43: =Z23+Z41 -> 2.5 | AI43: =AI23+AI41 -> 172
C45: > 최초 인력투입 계획 (1/17)에서는 정수정님, 김강현님이 2월까지로 되어 있었으나, 실제 두 분 계약은 각각 11월/10월로 되어있어서 수정
...

Sheet @250305
C3: 현대백화점 New 커머스 플랫폼 구축
C4: 45742
C5: 월별 인력 투입 계획
C6: 업무구분 | D6: 역할 | E6: 계약등급 | F6: 이름 | G6: 실등급 | H6: 계약투입일 | I6: 계약철수일 | J6: 실투입일 | K6: 실철수일 | L6: M1 (2월) | M6: M2 (3월) | N6: M3 (4월) | O6: M4 (5월) | P6: M5 (6월) | Q6: M6 (7월) | R6: M7 (8월) | S6: M8 (9월) | T6: M9 (10월) | U6: M10 (11월) | V6: M11 (12월) | W6: M12 (1월) | X6: M13 (2월) | Y6: M14 (3월) | Z6: M15 (4월) | AI6: M/M계
C7: 현장관리 | D7: 기획/디자인 총괄 (바이널씨 PM) | E7: 고급 | F7: 황세진 | G7: 특급 | H7: 45691 | I7: 46127 | L7: 1 | M7: 1 | N7: 1 | O7: 1 | P7: 1 | Q7: 1 | R7: 1 | S7: 1 | T7: 1 | U7: 1 | V7: 1 | W7: 1 | X7: 1 | Y7: 1 | Z7: 0.5 | AI7: =SUM(L7:AH7) -> 14.5
C8: 기획 | D8: PL (제작가이드, 산출물 검수) | E8: 고급 | F8: 고우정 | G8: 특급 | H8: 45705 | I8: 46127 | L8: 0.5 | M8: 1 | N8: 1 | O8: 1 | P8: 1 | Q8: 1 | R8: 1 | S8: 1 | T8: 1 | U8: 1 | V8: 1 | W8: 1 | X8: 1 | Y8: 1 | Z8: 0.5 | AI8: =SUM(L8:AH8) -> 14
D9: 앱웹 Front UXUI 상세 화면설계 | E9: 고급 | F9: 우미숙 | G9: 특급 | H9: 45691 | I9: 46096 | L9: 1 | M9: 1 | N9: 1 | O9: 1 | P9: 1 | Q9: 1 | R9: 1 | S9: 1 | T9: 1 | U9: 1 | V9: 0.5 | AI9: =SUM(L9:AH9) -> 10.5
E10: 고급 | F10: 정수정 | G10: 특급 | H10: 45691 | I10: 45989 | L10: 1 | M10: 1 | N10: 1 | O10: 1 | P10: 1 | Q10: 1 | R10: 1 | S10: 1 | T10: 1 | U10: 1 | AI10: =SUM(L10:AH10) -> 10
C11: 현장관리 | E11: 고급 | F11: 유경구 | G11: 고급 | H11: 45733 | I11: 45916 | M11: 0.5 | N11: 1 | O11: 1 | P11: 1 | Q11: 1 | R11: 1 | S11: 0.5 | AI11: =SUM(L11:AH11) -> 6
C12: 현장관리 | E12: 중급 | F12: 김강현 | G12: 고급 | H12: 45691 | I12: 45960 | L12: 1 | M12: 1 | N12: 1 | O12: 1 | P12: 1 | Q12: 1 | R12: 1 | S12: 1 | T12: 1 | AI12: =SUM(L12:AH12) -> 9
C13: 현장관리 | E13: 중급 | F13: 장익준 | G13: 고급 | H13: 45720 | I13: 46022 | M13: 1 | N13: 1 | O13: 1 | P13: 1 | Q13: 1 | R13: 1 | S13: 1 | T13: 1 | U13: 1 | V13: 1 | AI13: =SUM(L13:AH13) -> 10
C14: 현장관리 | E14: 중급 | F14: 김영근 | G14: 고급 | H14: 45720 | I14: 45900 | M14: 1 | N14: 1 | O14: 1 | P14: 1 | Q14: 1 | R14: 1 | AI14: =SUM(L14:AH14) -> 6
C15: 현장관리 | E15: 초급 | F15: 김세진 | G15: 초급 | H15: 45691 | I15: 45991 | L15: 1 | M15: 1 | N15: 1 | O15: 1 | P15: 1 | Q15: 1 | R15: 1 | S15: 1 | T15: 1 | U15: 1 | AI15: =SUM(L15:AH15) -> 10
C16: 현장관리 | E16: 초급 | F16: 이태림 | G16: 초급 | H16: 45691 | I16: 45961 | L16: 1 | M16: 1 | N16: 1 | O16: 1 | P16: 1 | Q16: 1 | R16: 1 | S16: 1 | T16: 1 | AI16: =SUM(L16:Z16) -> 9
C17: 현장관리 | AI17: =SUM(L17:Z17) -> 0
C18: 현장관리 | AI18: =SUM(L18:AH18) -> 0
C19: 현장관리 | AI19: =SUM(L19:AH19) -> 0
C20: 현장관리 | AI20: =SUM(L20:AH20) -> 0
C21: 현장관리 | AI21: =SUM(L21:AH21) -> 0
C22: 현장관리 | AI22: =SUM(L22:AH22) -> 0
C23: 현장관리 | D23: 합계 | I23: mm | L23: =SUM(L7:L22) -> 6.5 | M23: =SUM(M7:M22) -> 9.5 | N23: =SUM(N7:N22) -> 10 | O23: =SUM(O7:O22) -> 10 | P23: =SUM(P7:P22) -> 10 | Q23: =SUM(Q7:Q22) -> 10 | R23: =SUM(R7:R22) -> 10 | S23: =SUM(S7:S22) -> 8.5 | ... Z23: =SUM(Z7:Z22) -> 1 | AI23: =SUM(AI7:AI22) -> 99
C25: 디자인 | D25: PL (제작가이드, 산출물 검수) | E25: 중급 | F25: 배지효 | G25: - | H25: 45726 | I25: 46127 | M25: 0.75 | N25: 1 | O25: 1 | P25: 1 | Q25: 1 | R25: 1 | S25: 1 | T25: 1 | U25: 1 | V25: 1 | W25: 1 | X25: 1 | Y25: 1 | Z25: 0.5 | AI25: =SUM(L25:AH25) -> 13.25
D26: 앱웹 화면 UI 디자인 | E26: 중급 | F26: 윤혜림 | G26: - | H26: 45726 | I26: 46127 | M26: 0.75 | N26: 1 | O26: 1 | P26: 1 | Q26: 1 | R26: 1 | S26: 1 | T26: 1 | U26: 1 | V26: 1 | W26: 1 | X26: 1 | Y26: 1 | Z26: 0.5 | AI26: =SUM(L26:AH26) -> 13.25
E27: 중급 | F27: 박민정 | G27: 고급 | H27: 45748 | I27: 46066 | N27: 1 | O27: 1 | P27: 1 | Q27: 1 | R27: 1 | S27: 1 | T27: 1 | U27: 1 | V27: 1 | W27: 1 | X27: 0.5 | AI27: =SUM(L27:AH27) -> 10.5
C28: 디자인 | E28: 초급 | F28: 김민지 | G28: - | H28: 45726 | I28: 46127 | M28: 0.75 | N28: 1 | O28: 1 | P28: 1 | Q28: 1 | R28: 1 | S28: 1 | T28: 1 | U28: 1 | V28: 1 | W28: 1 | X28: 1 | Y28: 1 | Z28: 0.5 | AI28: =SUM(L28:AH28) -> 13.25
C29: 디자인 | E29: 초급 | F29: 이경진 | G29: - | H29: 45748 | I29: 45961 | N29: 1 | O29: 1 | P29: 1 | Q29: 1 | R29: 1 | S29: 1 | T29: 1 | AI29: =SUM(L29:AH29) -> 7
C30: 디자인 | E30: 초급 | F30: 민수연 | G30: - | H30: 45726 | I30: 45989 | M30: 0.75 | N30: 1 | O30: 1 | P30: 1 | Q30: 1 | R30: 1 | S30: 1 | T30: 1 | U30: 1 | AI30: =SUM(L30:AH30) -> 8.75
C31: 디자인 | E31: 초급 | F31: 박성호 | G31: - | H31: 45748 | I31: 45961 | N31: 1 | O31: 1 | P31: 1 | Q31: 1 | R31: 1 | S31: 1 | T31: 1 | AI31: =SUM(L31:AH31) -> 7
C32: 디자인 | E32: 고급 | AI32: 0
C33: 디자인 | E33: 중급 | AI33: 0
C34: 디자인 | E34: 초급 | AI34: 0
C35: 디자인 | E35: 고급 | AI35: 0
C36: 디자인 | E36: 중급 | AI36: 0
C37: 디자인 | E37: 초급 | AI37: 0
C38: 디자인 | D38: 인터렉션 디자인 (Interaction 설계 및 구현) | E38: 고급 | AI38: 0
C39: 디자인 | E39: 중급 | AI39: 0
C40: 디자인 | E40: 초급 | AI40: 0
C41: 디자인 | D41: 합계 | I41: mm | L41: =SUM(L25:L40) -> 0 | M41: =SUM(M25:M40) -> 3 | N41: =SUM(N25:N40) -> 7 | O41: =SUM(O25:O40) -> 7 | P41: =SUM(P25:P40) -> 7 | Q41: =SUM(Q25:Q40) -> 7 | R41: =SUM(R25:R40) -> 7 | S41: =SUM(S25:S40) -> 7 | ... Z41: =SUM(Z25:Z40) -> 1.5 | AI41: =SUM(AI25:AI40) -> 73
C43: 합계 | I43: MM | L43: =L23+L41 -> 6.5 | M43: =M23+M41 -> 12.5 | N43: =N23+N41 -> 17 | O43: =O23+O41 -> 17 | P43: =P23+P41 -> 17 | Q43: =Q23+Q41 -> 17 | R43: =R23+R41 -> 17 | S43: =S23+S41 -> 15.5 | ... Z43: =Z23+Z41 -> 2.5 | AI43: =AI23+AI41 -> 172
C45: > 최초 인력투입 계획 (1/17)에서는 정수정님, 김강현님이 2월까지로 되어 있었으나, 실제 두 분 계약은 각각 11월/10월로 되어있어서 수정
...

Sheet 250728_기획디자인변경(계약기준)
C3: 현대백화점 New 커머스 플랫폼 구축
C4: 45861 | AD4: 바이널씨 PM/기획,디자인 인력투입 변경 사항
C5: 월별 인력 투입 계획 | AA5: 변경버전 | AD5: 25/02/17 | AE5: =TODAY() -> 45867 | AF5: 작성 : 25/07/18
C6: 업무구분 | D6: 역할 | E6: 계약등급 | F6: 이름 | G6: 실등급 | H6: 계약투입일 | I6: 계약철수일 | J6: 실투입일 | K6: 실철수일 | L6: M1 (2월) | M6: M2 (3월) | N6: M3 (4월) | O6: M4 (5월) | P6: M5 (6월) | Q6: M6 (7월) | R6: M7 (8월) | S6: M8 (9월) | T6: M9 (10월) | U6: M10 (11월) | V6: M11 (12월) | W6: M12 (1월) | X6: M13 (2월) | Y6: M14 (3월) | Z6: M15 (4월) | AA6: M/M계 | AD6: 계약MM | AE6: Gap | AF6: 비고(KTDS 이번 공유사항) | AH6: 1. 기간별 TASK
C7: 현장관리 | D7: 기획/디자인 총괄 (바이널씨 PM) | E7: 고급 | F7: 황세진 | G7: 특급 | H7: 45691 | I7: 45831 | L7: 1 | M7: 1 | N7: 1 | O7: 1 | P7: 0.75 | AA7: =SUM(L7:Z7) -> 4.75 | AD7: 14.5 | AE7: =AA7-AD7 -> -9.75 | AF7: 조기철수(확정)_특급아님(고급) | AH7: 8월 - 9월 | AI7: 단위테스트케이스 산출물 관리 / 테스트 시행 | AJ7: 추가요건에 대한 설계
E8: 고급 | F8: 고우정 | G8: 특급 | H8: 45705 | I8: 46127 | L8: 0.5 | M8: 1 | N8: 1 | O8: 1 | P8: 1 | Q8: 1 | R8: 1 | S8: 1 | T8: 1 | U8: 1 | V8: 1 | W8: 1 | X8: 1 | Y8: 1 | Z8: 0.5 | AA8: =SUM(L8:Z8) -> 14 | AD8: 14 | AE8: =AA8-AD8 -> 0 | AF8: PM교체 | AI8: 산출물(설계) 품질관리 및 현행화
C9: 기획 | D9: PL (제작가이드, 산출물 검수) | E9: 고급 | F9: 유경구 | G9: 고급 | H9: 45733 | I9: 46112 | M9: 0.5 | N9: 1 | O9: 1 | P9: 1 | Q9: 1 | R9: 1 | S9: 1 | T9: 1 | U9: 1 | V9: 1 | W9: 1 | X9: 1 | Y9: 1 | AA9: =SUM(L9:Z9) -> 12.5 | AD9: 6 | AE9: =AA9-AD9 -> 6.5 | AF9: PL연장확정(전PM공수) | AI9: 요구사항 추적표 관리
D10: PL (제작가이드, 산출물 검수) | E10: 고급 | F10: 조선자 | G10: 특급 | H10: 45748 | I10: 46112 | N10: 1 | O10: 1 | P10: 1 | Q10: 1 | R10: 1 | S10: 1 | T10: 1 | U10: 1 | V10: 1 | W10: 1 | X10: 1 | Y10: 1 | AA10: =SUM(L10:Z10) -> 12 | AD10: 0 | AE10: =AA10-AD10 -> 12 | AF10: PL연장확정(전PM공수) | AI10: 메뉴구조도 관리
D11: 앱웹 Front UXUI 상세 화면설계 | E11: 고급 | F11: 정수정 | G11: 특급 | H11: 45691 | I11: 45989 | L11: 1 | M11: 1 | N11: 1 | O11: 1 | P11: 1 | Q11: 1 | R11: 1 | S11: 1 | T11: 1 | U11: 1 | AA11: =SUM(L11:Z11) -> 10 | AD11: 10 | AE11: =AA11-AD11 -> 0 | AH11: 10월 ~ 12월 | AI11: 산출물(설계) 품질관리 및 현행화
D12: 앱웹 Front UXUI 상세 화면설계 | E12: 고급 | F12: 우미숙 | G12: 특급 | H12: 45691 | I12: 45900 | L12: 1 | M12: 1 | N12: 1 | O12: 1 | P12: 1 | Q12: 1 | R12: 0.75 | AA12: =SUM(L12:Z12) -> 6.75 | AD12: 10.5 | AE12: =AA12-AD12 -> -3.75 | AF12: 조기철수(확정) | AI12: 요구사항 추적표 관리
A13: ` | C13: 현장관리 | D13: 앱웹 Front UXUI 상세 화면설계 | E13: 고급 | F13: 박지황 | H13: 45810 | I13: 45817 | P13: 0.25 | AA13: =SUM(L13:Z13) -> 0.25 | AD13: 0 | AE13: =AA13-AD13 -> 0.25 | AF13: 추가투입(철수상태) | AH13: 1월 ~ 3월 | AI13: 통합테스트 (개발대응)
C14: 현장관리 | D14: 앱웹 Front UXUI 상세 화면설계 | E14: 고급 | F14: 유지현 | G14: 특급 | H14: 45824 | I14: 45900 | P14: 0.5 | Q14: 1 | R14: 0.75 | AA14: =SUM(L14:Z14) -> 2.25 | AD14: 0 | AE14: =AA14-AD14 -> 2.25 | AF14: 추가투입 | AI14: 산출물(설계) 품질관리 및 현행화
A15: ` | C15: 현장관리 | D15: 앱웹 Front UXUI 상세 화면설계 | E15: 고급 | F15: 유승용 | H15: 45824 | I15: 46022 | P15: 0.5 | Q15: 1 | R15: 1 | S15: 1 | T15: 1 | U15: 1 | V15: 1 | AA15: =SUM(L15:Z15) -> 6.5 | AD15: 0 | AE15: =AA15-AD15 -> 6.5 | AF15: 추가투입(연장)
C16: 현장관리 | D16: 앱웹 Front UXUI 상세 화면설계 | E16: 고급 | F16: 안광훈 | G16: 특급 | H16: 45748 | I16: 45961 | N16: 1 | O16: 1 | P16: 1 | Q16: 1 | R16: 1 | S16: 1 | T16: 1 | AA16: =SUM(L16:Z16) -> 7 | AD16: 0 | AE16: =AA16-AD16 -> 7 | AF16: 추가투입
C17: 현장관리 | D17: 앱웹 Front UXUI 상세 화면설계 | E17: 중급 | F17: 김강현 | G17: 고급 | H17: 45691 | I17: 45930 | L17: 1 | M17: 1 | N17: 1 | O17: 1 | P17: 1 | Q17: 1 | R17: 1 | S17: 1 | T17: 1 | AA17: =SUM(L17:Z17) -> 9 | AD17: 9 | AE17: =AA17-AD17 -> 0 | AF17: 조기철수(검토) | AH17: 2. 각 파트별 작업 영역
C18: 현장관리 | D18: 앱웹 Front UXUI 상세 화면설계 | E18: 중급 | F18: 장익준 | G18: 고급 | H18: 45720 | I18: 45900 | M18: 1 | N18: 1 | O18: 1 | P18: 1 | Q18: 1 | R18: 1 | AA18: =SUM(L18:Z18) -> 6 | AD18: 10 | AE18: =AA18-AD18 -> -4 | AF18: 조기철수(검토) | AH18: 조선자 | AI18: 로그인, 회원, 상품, 주문, 마이페이지 관리
C19: 현장관리 | D19: 앱웹 Front UXUI 상세 화면설계 | E19: 중급 | F19: 김영근 | G19: 고급 | H19: 45720 | I19: 46022 | M19: 1 | N19: 1 | O19: 1 | P19: 1 | Q19: 1 | R19: 1 | S19: 1 | T19: 1 | U19: 1 | V19: 1 | AA19: =SUM(L19:Z19) -> 10 | AD19: 6 | AE19: =AA19-AD19 -> 4 | AF19: 연장확정 | AH19: 정수정 | AI19: 장바구니, 주문서, 주문완료
C20: 현장관리 | D20: 앱웹 Front UXUI 상세 화면설계 | E20: 초급 | F20: 김세진 | H20: 45691 | I20: 45930 | L20: 1 | M20: 1 | N20: 1 | O20: 1 | P20: 1 | Q20: 1 | R20: 0.75 | AA20: =SUM(L20:Z20) -> 6.75 | AD20: 10 | AE20: =AA20-AD20 -> -3.25 | AF20: 조기철수(희망검토) | AH20: 김영근 | AI20: 구독, 마이페이지(주문관리)
C21: 현장관리 | D21: 앱웹 Front UXUI 상세 화면설계 | E21: 초급 | F21: 이태림 | H21: 45691 | I21: 46022 | L21: 1 | M21: 1 | N21: 1 | O21: 1 | P21: 1 | Q21: 1 | R21: 1 | S21: 1 | T21: 1 | U21: 1 | V21: 1 | W21: 0.75 | AA21: =SUM(L21:Z21) -> 11.75 | AD21: 9 | AE21: =AA21-AD21 -> 2.75 | AF21: 연장검토 | AH21: 안광훈 | AI21: 프로모션, 이벤트, 마이페이지(나의활동, 나의혜택)
C22: 현장관리 | D22: 합계 | I22: mm | L22: =SUM(L7:L21) -> 6.5 | M22: =SUM(M7:M21) -> 9.5 | N22: =SUM(N7:N21) -> 12 | O22: =SUM(O7:O21) -> 12 | P22: =SUM(P7:P21) -> 13 | Q22: =SUM(Q7:Q21) -> 13 | R22: =SUM(R7:R21) -> 12.25 | S22: =SUM(S7:S21) -> 9 | ... AA22: =SUM(AA7:AA21) -> 119.5 | AD22: =SUM(AD7:AD21) -> 99 | AE22: =SUM(AE7:AE21) -> 20.5 | AH22: (김강현) | AI22: 로그인, 회원가입, 마이페이지(나의정보)
AH23: (장익준) | AI23: 상품 (유형, 무형)
C24: 디자인 | D24: PL (제작가이드, 산출물 검수) | E24: 중급 | F24: 배지효 | H24: 45726 | I24: 46127 | M24: 0.75 | N24: 1 | O24: 1 | P24: 1 | Q24: 1 | R24: 1 | S24: 1 | T24: 1 | U24: 1 | V24: 1 | W24: 1 | X24: 1 | Y24: 1 | Z24: 0.5 | AA24: =SUM(L24:Z24) -> 13.25 | AD24: 13.25 | AE24: =AA24-AD24 -> 0 | AH24: 유경구 | AI24: 모듈, 피드/샵메인, 전문관, 브랜드관, 콘텐츠, 신규기능(미스페이스, 잼/마이컬렉션) 고객센터, 공통
D25: 앱웹 화면 UI 디자인 | E25: 중급 | F25: 윤혜림 | H25: 45726 | I25: 46127 | M25: 0.75 | N25: 1 | O25: 1 | P25: 1 | Q25: 1 | R25: 1 | S25: 1 | T25: 1 | U25: 1 | V25: 1 | W25: 1 | X25: 1 | Y25: 1 | Z25: 0.5 | AA25: =SUM(L25:Z25) -> 13.25 | AD25: 13.25 | AE25: =AA25-AD25 -> 0 | AH25: 김세진 | AI25: 모듈, 브랜드관, 콘텐츠
D26: 앱웹 화면 UI 디자인 | E26: 중급 | F26: 박민정 | H26: 45748 | I26: 45877 | N26: 1 | O26: 1 | P26: 1 | Q26: 1 | R26: 0.25 | AA26: =SUM(L26:Z26) -> 4.25 | AD26: 10.5 | AE26: =AA26-AD26 -> -6.25 | AF26: 조기철수 | AH26: 이태림 | AI26: 신규기능(미스페이스, 잼/마이컬렉션), 고객센터, 공통, 전문관
C27: 디자인 | D27: 앱웹 화면 UI 디자인 | E27: 초급 | F27: 김민지 | H27: 45726 | I27: 45877 | M27: 0.75 | N27: 1 | O27: 1 | P27: 1 | Q27: 1 | R27: 0.25 | AA27: =SUM(L27:Z27) -> 5 | AD27: 13.25 | AE27: =AA27-AD27 -> -8.25 | AF27: 조기철수
C28: 디자인 | D28: 앱웹 화면 UI 디자인 | E28: 초급 | F28: 민수연 | H28: 45726 | I28: 46094 | M28: 0.75 | N28: 1 | O28: 1 | P28: 1 | Q28: 1 | R28: 1 | S28: 1 | T28: 1 | U28: 1 | V28: 1 | W28: 1 | X28: 1 | Y28: 0.5 | AA28: =SUM(L28:Z28) -> 12.25 | AD28: 8.75 | AE28: =AA28-AD28 -> 3.5 | AF28: 연장
C29: 디자인 | D29: 앱웹 화면 UI 디자인 | E29: 초급 | F29: 김단비 | H29: 45810 | I29: 45991 | P29: 1 | Q29: 1 | R29: 1 | S29: 1 | T29: 1 | U29: 1 | AA29: =SUM(L29:Z29) -> 6 | AD29: 0 | AE29: =AA29-AD29 -> 6 | AF29: 연장
C30: 디자인 | D30: 앱웹 화면 UI 디자인 | E30: 초급 | F30: 김원경 | H30: 45810 | I30: 45991 | P30: 1 | Q30: 1 | R30: 1 | S30: 1 | T30: 1 | U30: 1 | AA30: =SUM(L30:Z30) -> 6 | AD30: 0 | AE30: =AA30-AD30 -> 6 | AF30: 연장
C31: 디자인 | D31: 앱웹 화면 UI 디자인 | E31: 초급 | F31: 김유진 | H31: 45883 | I31: 45930 | R31: 0.75 | S31: 1 | AA31: =SUM(L31:Z31) -> 1.75 | AD31: 0 | AE31: =AA31-AD31 -> 1.75 | AF31: 추가투입
A32: ` | C32: 디자인 | D32: 앱웹 화면 UI 디자인 | E32: 초급 | F32: 손성미 | H32: 45883 | I32: 45930 | R32: 0.75 | S32: 1 | AA32: =SUM(L32:Z32) -> 1.75 | AD32: 0 | AE32: =AA32-AD32 -> 1.75 | AF32: 추가투입
C33: 디자인 | D33: 앱웹 화면 UI 디자인 | E33: 초급 | F33: 이경진 | H33: 45748 | I33: 45961 | N33: 1 | O33: 1 | P33: 1 | Q33: 1 | R33: 1 | S33: 1 | T33: 1 | AA33: =SUM(L33:Z33) -> 7 | AD33: 7 | AE33: =AA33-AD33 -> 0
C34: 디자인 | D34: 앱웹 화면 UI 디자인 | E34: 초급 | F34: 박성호 | H34: 45748 | I34: 45961 | N34: 1 | O34: 1 | P34: 1 | Q34: 1 | R34: 1 | S34: 1 | T34: 1 | AA34: =SUM(L34:Z34) -> 7 | AD34: 7 | AE34: =AA34-AD34 -> 0
C35: 디자인 | D35: 합계 | I35: mm | L35: =SUM(L24:L34) -> 0 | M35: =SUM(M24:M34) -> 3 | N35: =SUM(N24:N34) -> 7 | O35: =SUM(O24:O34) -> 7 | P35: =SUM(P24:P34) -> 9 | Q35: =SUM(Q24:Q34) -> 9 | R35: =SUM(R24:R34) -> 9 | S35: =SUM(S24:S34) -> 9 | ... AA35: =SUM(AA24:AA34) -> 77.5 | AD35: =SUM(AD24:AD34) -> 73 | AE35: =SUM(AE24:AE34) -> 4.5
C37: 합계 | I37: MM | L37: =L22+L35 -> 6.5 | M37: =M22+M35 -> 12.5 | N37: =N22+N35 -> 19 | O37: =O22+O35 -> 19 | P37: =P22+P35 -> 22 | Q37: =Q22+Q35 -> 22 | R37: =R22+R35 -> 21.25 | S37: =S22+S35 -> 18 | ... AA37: =AA22+AA35 -> 197 | AD37: =AD22+AD35 -> 172 | AE37: =AE22+AE35 -> 25 | AF37: 바이널씨 인력투입 추가 공수(계획)
E40: 바이널씨 내부 계획 공수 | L40: 25/02/17 시작 버전 | Q40: =TODAY() -> 45867 | R40: 현재 | W40: 투입변경 상세 내용
E41: 계약공수 | G41: 172 | L41: 등급별 계약공수 | Q41: 등급별 계획공수 | W41: 기획 부문 인력 변경
E42: 본사 추가지원 가능 공수 | G42: =204.5-G41 -> 32.5 | L42: 부문 | M42: 등급 | N42: 공수 | O42: 합계 | Q42: 부문 | R42: 등급 | S42: 공수 | T42: 합계 | U42: 차이 | W42: 변경MM | X42: 조기철수 | Y42: 추가연장
E43: 총 가용 공수 | G43: 204.5 | L43: 기획 | M43: 고급 | N43: 55 | O43: =SUM(N43:N45) -> 99 | Q43: 기획 | R43: 고급 | S43: =SUMIF($E$7:$E$21,"고급",$AA$7:$AA$21) -> 76 | T43: =SUM(S43:S45) -> 119.5 | U43: =N43-S43 -> -21 | V43: 고 | W43: =SUM(X43:Y43) -> 21 | X43: =AE7+AE12 -> -13.5 | Y43: =AE9+AE10+AE13+AE14+AE15+AE16 -> 34.5 | Z43: 황세진,우미숙 조기철수 ▶ 조선자,유경구,안광훈 연장, *유승용,유지현 추가
E44: *추가지원 가능 공수는 내부적으로만 소통 | M44: 중급 | N44: 25 | R44: 중급 | S44: =SUMIF($E$7:$E$21,"중급",$AA$7:$AA$21) -> 25 | U44: =N44-S44 -> 0 | V44: 중 | W44: =SUM(X44:Y44) -> 0 | X44: =AE17+AE18 -> -4 | Y44: =AE19 -> 4 | Z44: 김강현,장익준 조기철수 ▶ 김영근 연장
E45: *고객/협력사 노출 금지 | M45: 초급 | N45: 19 | R45: 초급 | S45: =SUMIF($E$7:$E$21,"초급",$AA$7:$AA$21) -> 18.5 | U45: =N45-S45 -> 0.5 | V45: 초 | W45: =SUM(X45:Y45) -> -0.5 | X45: =AE20 -> -3.25 | Y45: =AE21 -> 2.75 | Z45: 김세진 조기철수 ▶ 이태림 연장
...

Sheet 250718_기획디자인변경(계약기준)
C3: 현대백화점 New 커머스 플랫폼 구축
C4: 45861 | AD4: 바이널씨 PM/기획,디자인 인력투입 변경 사항
C5: 월별 인력 투입 계획 | AA5: 변경버전 | AD5: 25/02/17 | AE5: =TODAY() -> 45867 | AF5: 작성 : 25/07/18
C6: 업무구분 | D6: 역할 | E6: 계약등급 | F6: 이름 | G6: 실등급 | H6: 계약투입일 | I6: 계약철수일 | J6: 실투입일 | K6: 실철수일 | L6: M1 (2월) | M6: M2 (3월) | N6: M3 (4월) | O6: M4 (5월) | P6: M5 (6월) | Q6: M6 (7월) | R6: M7 (8월) | S6: M8 (9월) | T6: M9 (10월) | U6: M10 (11월) | V6: M11 (12월) | W6: M12 (1월) | X6: M13 (2월) | Y6: M14 (3월) | Z6: M15 (4월) | AA6: M/M계 | AD6: 계약MM | AE6: Gap | AF6: 비고(KTDS 이번 공유사항) | AH6: 1. 기간별 TASK
C7: 현장관리 | D7: 기획/디자인 총괄 (바이널씨 PM) | E7: 고급 | F7: 황세진 | G7: 특급 | H7: 45691 | I7: 45831 | L7: 1 | M7: 1 | N7: 1 | O7: 1 | P7: 0.75 | AA7: =SUM(L7:Z7) -> 4.75 | AD7: 14.5 | AE7: =AA7-AD7 -> -9.75 | AF7: 조기철수(확정)_특급아님(고급) | AH7: 8월 - 9월 | AI7: 단위테스트케이스 산출물 관리 / 테스트 시행 | AJ7: 추가요건에 대한 설계
E8: 고급 | F8: 고우정 | G8: 특급 | H8: 45705 | I8: 46127 | L8: 0.5 | M8: 1 | N8: 1 | O8: 1 | P8: 1 | Q8: 1 | R8: 1 | S8: 1 | T8: 1 | U8: 1 | V8: 1 | W8: 1 | X8: 1 | Y8: 1 | Z8: 0.5 | AA8: =SUM(L8:Z8) -> 14 | AD8: 14 | AE8: =AA8-AD8 -> 0 | AF8: PM교체 | AI8: 산출물(설계) 품질관리 및 현행화
C9: 기획 | D9: PL (제작가이드, 산출물 검수) | E9: 고급 | F9: 유경구 | G9: 고급 | H9: 45733 | I9: 46112 | M9: 0.5 | N9: 1 | O9: 1 | P9: 1 | Q9: 1 | R9: 1 | S9: 1 | T9: 1 | U9: 1 | V9: 1 | W9: 1 | X9: 1 | Y9: 1 | AA9: =SUM(L9:Z9) -> 12.5 | AD9: 6 | AE9: =AA9-AD9 -> 6.5 | AF9: PL연장확정(전PM공수) | AI9: 요구사항 추적표 관리
D10: PL (제작가이드, 산출물 검수) | E10: 고급 | F10: 조선자 | G10: 특급 | H10: 45748 | I10: 46112 | N10: 1 | O10: 1 | P10: 1 | Q10: 1 | R10: 1 | S10: 1 | T10: 1 | U10: 1 | V10: 1 | W10: 1 | X10: 1 | Y10: 1 | AA10: =SUM(L10:Z10) -> 12 | AD10: 0 | AE10: =AA10-AD10 -> 12 | AF10: PL연장확정(전PM공수) | AI10: 메뉴구조도 관리
D11: 앱웹 Front UXUI 상세 화면설계 | E11: 고급 | F11: 정수정 | G11: 특급 | H11: 45691 | I11: 45989 | L11: 1 | M11: 1 | N11: 1 | O11: 1 | P11: 1 | Q11: 1 | R11: 1 | S11: 1 | T11: 1 | U11: 1 | AA11: =SUM(L11:Z11) -> 10 | AD11: 10 | AE11: =AA11-AD11 -> 0 | AH11: 10월 ~ 12월 | AI11: 산출물(설계) 품질관리 및 현행화
D12: 앱웹 Front UXUI 상세 화면설계 | E12: 고급 | F12: 우미숙 | G12: 특급 | H12: 45691 | I12: 45900 | L12: 1 | M12: 1 | N12: 1 | O12: 1 | P12: 1 | Q12: 1 | R12: 1 | AA12: =SUM(L12:Z12) -> 7 | AD12: 10.5 | AE12: =AA12-AD12 -> -3.5 | AF12: 조기철수(확정) | AI12: 요구사항 추적표 관리
A13: ` | C13: 현장관리 | D13: 앱웹 Front UXUI 상세 화면설계 | E13: 고급 | F13: 박지황 | H13: 45810 | I13: 45817 | P13: 0.25 | AA13: =SUM(L13:Z13) -> 0.25 | AD13: 0 | AE13: =AA13-AD13 -> 0.25 | AF13: 추가투입(철수상태) | AH13: 1월 ~ 3월 | AI13: 통합테스트 (개발대응)
C14: 현장관리 | D14: 앱웹 Front UXUI 상세 화면설계 | E14: 고급 | F14: 유지현 | G14: 특급 | H14: 45824 | I14: 45900 | P14: 0.5 | Q14: 1 | R14: 1 | AA14: =SUM(L14:Z14) -> 2.5 | AD14: 0 | AE14: =AA14-AD14 -> 2.5 | AF14: 추가투입 | AI14: 산출물(설계) 품질관리 및 현행화
A15: ` | C15: 현장관리 | D15: 앱웹 Front UXUI 상세 화면설계 | E15: 고급 | F15: 유승용 | H15: 45824 | I15: 46022 | P15: 0.5 | Q15: 1 | R15: 1 | S15: 1 | T15: 1 | U15: 1 | V15: 1 | AA15: =SUM(L15:Z15) -> 6.5 | AD15: 0 | AE15: =AA15-AD15 -> 6.5 | AF15: 추가투입(연장)
C16: 현장관리 | D16: 앱웹 Front UXUI 상세 화면설계 | E16: 고급 | F16: 안광훈 | G16: 특급 | H16: 45748 | I16: 45961 | N16: 1 | O16: 1 | P16: 1 | Q16: 1 | R16: 1 | S16: 1 | T16: 1 | AA16: =SUM(L16:Z16) -> 7 | AD16: 0 | AE16: =AA16-AD16 -> 7 | AF16: 추가투입
C17: 현장관리 | D17: 앱웹 Front UXUI 상세 화면설계 | E17: 중급 | F17: 김강현 | G17: 고급 | H17: 45691 | I17: 45930 | L17: 1 | M17: 1 | N17: 1 | O17: 1 | P17: 1 | Q17: 1 | R17: 1 | S17: 1 | T17: 1 | AA17: =SUM(L17:Z17) -> 9 | AD17: 9 | AE17: =AA17-AD17 -> 0 | AF17: 조기철수(검토) | AH17: 2. 각 파트별 작업 영역
C18: 현장관리 | D18: 앱웹 Front UXUI 상세 화면설계 | E18: 중급 | F18: 장익준 | G18: 고급 | H18: 45720 | I18: 45900 | M18: 1 | N18: 1 | O18: 1 | P18: 1 | Q18: 1 | R18: 1 | AA18: =SUM(L18:Z18) -> 6 | AD18: 10 | AE18: =AA18-AD18 -> -4 | AF18: 조기철수(검토) | AH18: 조선자 | AI18: 로그인, 회원, 상품, 주문, 마이페이지 관리
C19: 현장관리 | D19: 앱웹 Front UXUI 상세 화면설계 | E19: 중급 | F19: 김영근 | G19: 고급 | H19: 45720 | I19: 46022 | M19: 1 | N19: 1 | O19: 1 | P19: 1 | Q19: 1 | R19: 1 | S19: 1 | T19: 1 | U19: 1 | V19: 1 | AA19: =SUM(L19:Z19) -> 10 | AD19: 6 | AE19: =AA19-AD19 -> 4 | AF19: 연장확정 | AH19: 정수정 | AI19: 장바구니, 주문서, 주문완료
C20: 현장관리 | D20: 앱웹 Front UXUI 상세 화면설계 | E20: 초급 | F20: 김세진 | H20: 45691 | I20: 45930 | L20: 1 | M20: 1 | N20: 1 | O20: 1 | P20: 1 | Q20: 1 | R20: 1 | AA20: =SUM(L20:Z20) -> 7 | AD20: 10 | AE20: =AA20-AD20 -> -3 | AF20: 조기철수(희망검토) | AH20: 김영근 | AI20: 구독, 마이페이지(주문관리)
C21: 현장관리 | D21: 앱웹 Front UXUI 상세 화면설계 | E21: 초급 | F21: 이태림 | H21: 45691 | I21: 46022 | L21: 1 | M21: 1 | N21: 1 | O21: 1 | P21: 1 | Q21: 1 | R21: 1 | S21: 1 | T21: 1 | U21: 1 | V21: 1 | AA21: =SUM(L21:Z21) -> 11 | AD21: 9 | AE21: =AA21-AD21 -> 2 | AF21: 연장검토 | AH21: 안광훈 | AI21: 프로모션, 이벤트, 마이페이지(나의활동, 나의혜택)
C22: 현장관리 | D22: 합계 | I22: mm | L22: =SUM(L7:L21) -> 6.5 | M22: =SUM(M7:M21) -> 9.5 | N22: =SUM(N7:N21) -> 12 | O22: =SUM(O7:O21) -> 12 | P22: =SUM(P7:P21) -> 13 | Q22: =SUM(Q7:Q21) -> 13 | R22: =SUM(R7:R21) -> 13 | S22: =SUM(S7:S21) -> 9 | ... AA22: =SUM(AA7:AA21) -> 119.5 | AD22: =SUM(AD7:AD21) -> 99 | AE22: =SUM(AE7:AE21) -> 20.5 | AH22: (김강현) | AI22: 로그인, 회원가입, 마이페이지(나의정보)
AH23: (장익준) | AI23: 상품 (유형, 무형)
C24: 디자인 | D24: PL (제작가이드, 산출물 검수) | E24: 중급 | F24: 배지효 | H24: 45726 | I24: 46127 | M24: 0.75 | N24: 1 | O24: 1 | P24: 1 | Q24: 1 | R24: 1 | S24: 1 | T24: 1 | U24: 1 | V24: 1 | W24: 1 | X24: 1 | Y24: 1 | Z24: 0.5 | AA24: =SUM(L24:Z24) -> 13.25 | AD24: 13.25 | AE24: =AA24-AD24 -> 0 | AH24: 유경구 | AI24: 모듈, 피드/샵메인, 전문관, 브랜드관, 콘텐츠, 신규기능(미스페이스, 잼/마이컬렉션) 고객센터, 공통
D25: 앱웹 화면 UI 디자인 | E25: 중급 | F25: 윤혜림 | H25: 45726 | I25: 46127 | M25: 0.75 | N25: 1 | O25: 1 | P25: 1 | Q25: 1 | R25: 1 | S25: 1 | T25: 1 | U25: 1 | V25: 1 | W25: 1 | X25: 1 | Y25: 1 | Z25: 0.5 | AA25: =SUM(L25:Z25) -> 13.25 | AD25: 13.25 | AE25: =AA25-AD25 -> 0 | AH25: 김세진 | AI25: 모듈, 브랜드관, 콘텐츠
D26: 앱웹 화면 UI 디자인 | E26: 중급 | F26: 박민정 | H26: 45748 | I26: 45877 | N26: 1 | O26: 1 | P26: 1 | Q26: 1 | R26: 0.25 | AA26: =SUM(L26:Z26) -> 4.25 | AD26: 10.5 | AE26: =AA26-AD26 -> -6.25 | AF26: 조기철수 | AH26: 이태림 | AI26: 신규기능(미스페이스, 잼/마이컬렉션), 고객센터, 공통, 전문관
C27: 디자인 | D27: 앱웹 화면 UI 디자인 | E27: 초급 | F27: 김민지 | H27: 45726 | I27: 45877 | M27: 0.75 | N27: 1 | O27: 1 | P27: 1 | Q27: 1 | R27: 0.25 | AA27: =SUM(L27:Z27) -> 5 | AD27: 13.25 | AE27: =AA27-AD27 -> -8.25 | AF27: 조기철수
C28: 디자인 | D28: 앱웹 화면 UI 디자인 | E28: 초급 | F28: 민수연 | H28: 45726 | I28: 46094 | M28: 0.75 | N28: 1 | O28: 1 | P28: 1 | Q28: 1 | R28: 1 | S28: 1 | T28: 1 | U28: 1 | V28: 1 | W28: 1 | X28: 1 | Y28: 0.5 | AA28: =SUM(L28:Z28) -> 12.25 | AD28: 8.75 | AE28: =AA28-AD28 -> 3.5 | AF28: 연장
C29: 디자인 | D29: 앱웹 화면 UI 디자인 | E29: 초급 | F29: 김단비 | H29: 45810 | I29: 45991 | P29: 1 | Q29: 1 | R29: 1 | S29: 1 | T29: 1 | U29: 1 | AA29: =SUM(L29:Z29) -> 6 | AD29: 0 | AE29: =AA29-AD29 -> 6 | AF29: 연장
C30: 디자인 | D30: 앱웹 화면 UI 디자인 | E30: 초급 | F30: 김원경 | H30: 45810 | I30: 45991 | P30: 1 | Q30: 1 | R30: 1 | S30: 1 | T30: 1 | U30: 1 | AA30: =SUM(L30:Z30) -> 6 | AD30: 0 | AE30: =AA30-AD30 -> 6 | AF30: 연장
C31: 디자인 | D31: 앱웹 화면 UI 디자인 | E31: 초급 | F31: 김유진 | H31: 45883 | I31: 45930 | R31: 0.75 | S31: 1 | AA31: =SUM(L31:Z31) -> 1.75 | AD31: 0 | AE31: =AA31-AD31 -> 1.75 | AF31: 추가투입
A32: ` | C32: 디자인 | D32: 앱웹 화면 UI 디자인 | E32: 초급 | F32: 손성미 | H32: 45883 | I32: 45930 | R32: 0.75 | S32: 1 | AA32: =SUM(L32:Z32) -> 1.75 | AD32: 0 | AE32: =AA32-AD32 -> 1.75 | AF32: 추가투입
C33: 디자인 | D33: 앱웹 화면 UI 디자인 | E33: 초급 | F33: 이경진 | H33: 45748 | I33: 45961 | N33: 1 | O33: 1 | P33: 1 | Q33: 1 | R33: 1 | S33: 1 | T33: 1 | AA33: =SUM(L33:Z33) -> 7 | AD33: 7 | AE33: =AA33-AD33 -> 0
C34: 디자인 | D34: 앱웹 화면 UI 디자인 | E34: 초급 | F34: 박성호 | H34: 45748 | I34: 45961 | N34: 1 | O34: 1 | P34: 1 | Q34: 1 | R34: 1 | S34: 1 | T34: 1 | AA34: =SUM(L34:Z34) -> 7 | AD34: 7 | AE34: =AA34-AD34 -> 0
C35: 디자인 | D35: 합계 | I35: mm | L35: =SUM(L24:L34) -> 0 | M35: =SUM(M24:M34) -> 3 | N35: =SUM(N24:N34) -> 7 | O35: =SUM(O24:O34) -> 7 | P35: =SUM(P24:P34) -> 9 | Q35: =SUM(Q24:Q34) -> 9 | R35: =SUM(R24:R34) -> 9 | S35: =SUM(S24:S34) -> 9 | ... AA35: =SUM(AA24:AA34) -> 77.5 | AD35: =SUM(AD24:AD34) -> 73 | AE35: =SUM(AE24:AE34) -> 4.5
C37: 합계 | I37: MM | L37: =L22+L35 -> 6.5 | M37: =M22+M35 -> 12.5 | N37: =N22+N35 -> 19 | O37: =O22+O35 -> 19 | P37: =P22+P35 -> 22 | Q37: =Q22+Q35 -> 22 | R37: =R22+R35 -> 22 | S37: =S22+S35 -> 18 | ... AA37: =AA22+AA35 -> 197 | AD37: =AD22+AD35 -> 172 | AE37: =AE22+AE35 -> 25 | AF37: 바이널씨 인력투입 추가 공수(계획)
E40: 바이널씨 내부 계획 공수 | L40: 25/02/17 시작 버전 | Q40: =TODAY() -> 45867 | R40: 현재 | W40: 투입변경 상세 내용
E41: 계약공수 | G41: 172 | L41: 등급별 계약공수 | Q41: 등급별 계획공수 | W41: 기획 부문 인력 변경
E42: 본사 추가지원 가능 공수 | G42: =204.5-G41 -> 32.5 | L42: 부문 | M42: 등급 | N42: 공수 | O42: 합계 | Q42: 부문 | R42: 등급 | S42: 공수 | T42: 합계 | U42: 차이 | W42: 변경MM | X42: 조기철수 | Y42: 추가연장
E43: 총 가용 공수 | G43: 204.5 | L43: 기획 | M43: 고급 | N43: 55 | O43: =SUM(N43:N45) -> 99 | Q43: 기획 | R43: 고급 | S43: =SUMIF($E$7:$E$21,"고급",$AA$7:$AA$21) -> 76.5 | T43: =SUM(S43:S45) -> 119.5 | U43: =N43-S43 -> -21.5 | V43: 고 | W43: =SUM(X43:Y43) -> 21.5 | X43: =AE7+AE12 -> -13.25 | Y43: =AE9+AE10+AE13+AE14+AE15+AE16 -> 34.75 | Z43: 황세진,우미숙 조기철수 ▶ 조선자,유경구,안광훈 연장, *유승용,유지현 추가
E44: *추가지원 가능 공수는 내부적으로만 소통 | M44: 중급 | N44: 25 | R44: 중급 | S44: =SUMIF($E$7:$E$21,"중급",$AA$7:$AA$21) -> 25 | U44: =N44-S44 -> 0 | V44: 중 | W44: =SUM(X44:Y44) -> 0 | X44: =AE17+AE18 -> -4 | Y44: =AE19 -> 4 | Z44: 김강현,장익준 조기철수 ▶ 김영근 연장
E45: *고객/협력사 노출 금지 | M45: 초급 | N45: 19 | R45: 초급 | S45: =SUMIF($E$7:$E$21,"초급",$AA$7:$AA$21) -> 18 | U45: =N45-S45 -> 1 | V45: 초 | W45: =SUM(X45:Y45) -> -1 | X45: =AE20 -> -3 | Y45: =AE21 -> 2 | Z45: 김세진 조기철수 ▶ 이태림 연장
...

Sheet history_@250326추가
C3: 현대백화점 New 커머스 플랫폼 구축
C4: 45742
C5: 월별 인력 투입 계획
C6: 업무구분 | D6: 역할 | E6: 계약등급 | F6: 이름 | G6: 실등급 | H6: 계약투입일 | I6: 계약철수일 | J6: 실투입일 | K6: 실철수일 | L6: M1 (2월) | M6: M2 (3월) | N6: M3 (4월) | O6: M4 (5월) | P6: M5 (6월) | Q6: M6 (7월) | R6: M7 (8월) | S6: M8 (9월) | T6: M9 (10월) | U6: M10 (11월) | V6: M11 (12월) | W6: M12 (1월) | X6: M13 (2월) | Y6: M14 (3월) | Z6: M15 (4월) | AI6: M/M계
C7: 현장관리 | D7: 기획/디자인 총괄 (바이널씨 PM) | E7: 고급 | F7: 황세진 | G7: 특급 | H7: 45691 | I7: 46127 | L7: 1 | M7: 1 | N7: 1 | O7: 1 | P7: 1 | Q7: 1 | R7: 1 | S7: 1 | T7: 1 | U7: 1 | V7: 1 | W7: 1 | X7: 1 | Y7: 1 | Z7: 0.5 | AI7: =SUM(L7:AH7) -> 14.5
C8: 기획 | D8: PL (제작가이드, 산출물 검수) | E8: 고급 | F8: 고우정 | G8: 특급 | H8: 45705 | I8: 46127 | L8: 0.5 | M8: 1 | N8: 1 | O8: 1 | P8: 1 | Q8: 1 | R8: 1 | S8: 1 | T8: 1 | U8: 1 | V8: 1 | W8: 1 | X8: 1 | Y8: 1 | Z8: 0.5 | AI8: =SUM(L8:AH8) -> 14
D9: 앱웹 Front UXUI 상세 화면설계 | E9: 고급 | F9: 우미숙 | G9: 특급 | H9: 45691 | I9: 46096 | L9: 1 | M9: 1 | N9: 1 | O9: 1 | P9: 1 | Q9: 1 | R9: 1 | S9: 1 | T9: 1 | U9: 1 | V9: 0.5 | AI9: =SUM(L9:AH9) -> 10.5
E10: 고급 | F10: 정수정 | G10: 특급 | H10: 45691 | I10: 45989 | L10: 1 | M10: 1 | N10: 1 | O10: 1 | P10: 1 | Q10: 1 | R10: 1 | S10: 1 | T10: 1 | U10: 1 | AI10: =SUM(L10:AH10) -> 10
C11: 현장관리 | E11: 고급 | F11: 유경구 | G11: 고급 | H11: 45733 | I11: 45916 | M11: 0.5 | N11: 1 | O11: 1 | P11: 1 | Q11: 1 | R11: 1 | S11: 0.5 | AI11: =SUM(L11:AH11) -> 6
C12: 현장관리 | E12: 고급 | F12: 조선자 | G12: 특급 | H12: 45748 | I12: 45961 | N12: 1 | O12: 1 | P12: 1 | Q12: 1 | R12: 1 | S12: 1 | T12: 1 | AI12: =SUM(L12:AH12) -> 7
C13: 현장관리 | E13: 고급 | F13: 안광훈 | G13: 특급 | H13: 45748 | I13: 45961 | N13: 1 | O13: 1 | P13: 1 | Q13: 1 | R13: 1 | S13: 1 | T13: 1 | AI13: =SUM(L13:AH13) -> 7
C14: 현장관리 | E14: 중급 | F14: 김강현 | G14: 고급 | H14: 45691 | I14: 45960 | L14: 1 | M14: 1 | N14: 1 | O14: 1 | P14: 1 | Q14: 1 | R14: 1 | S14: 1 | T14: 1 | AI14: =SUM(L14:AH14) -> 9
C15: 현장관리 | E15: 중급 | F15: 장익준 | G15: 고급 | H15: 45720 | I15: 46022 | M15: 1 | N15: 1 | O15: 1 | P15: 1 | Q15: 1 | R15: 1 | S15: 1 | T15: 1 | U15: 1 | V15: 1 | AI15: =SUM(L15:AH15) -> 10
C16: 현장관리 | E16: 중급 | F16: 김영근 | G16: 고급 | H16: 45720 | I16: 45900 | M16: 1 | N16: 1 | O16: 1 | P16: 1 | Q16: 1 | R16: 1 | AI16: =SUM(L16:AH16) -> 6
C17: 현장관리 | E17: 초급 | F17: 김세진 | G17: 초급 | H17: 45691 | I17: 45991 | L17: 1 | M17: 1 | N17: 1 | O17: 1 | P17: 1 | Q17: 1 | R17: 1 | S17: 1 | T17: 1 | U17: 1 | AI17: =SUM(L17:AH17) -> 10
C18: 현장관리 | E18: 초급 | F18: 이태림 | G18: 초급 | H18: 45691 | I18: 45961 | L18: 1 | M18: 1 | N18: 1 | O18: 1 | P18: 1 | Q18: 1 | R18: 1 | S18: 1 | T18: 1 | AI18: =SUM(L18:Z18) -> 9
C19: 현장관리 | AI19: =SUM(L19:Z19) -> 0
C20: 현장관리 | AI20: =SUM(L20:AH20) -> 0
C21: 현장관리 | AI21: =SUM(L21:AH21) -> 0
C22: 현장관리 | AI22: =SUM(L22:AH22) -> 0
C23: 현장관리 | AI23: =SUM(L23:AH23) -> 0
C24: 현장관리 | AI24: =SUM(L24:AH24) -> 0
C25: 현장관리 | D25: 합계 | I25: mm | L25: =SUM(L7:L24) -> 6.5 | M25: =SUM(M7:M24) -> 9.5 | N25: =SUM(N7:N24) -> 12 | O25: =SUM(O7:O24) -> 12 | P25: =SUM(P7:P24) -> 12 | Q25: =SUM(Q7:Q24) -> 12 | R25: =SUM(R7:R24) -> 12 | S25: =SUM(S7:S24) -> 10.5 | ... Z25: =SUM(Z7:Z24) -> 1 | AI25: =SUM(AI7:AI24) -> 113
C27: 디자인 | D27: PL (제작가이드, 산출물 검수) | E27: 중급 | F27: 배지효 | G27: - | H27: 45726 | I27: 46127 | M27: 0.75 | N27: 1 | O27: 1 | P27: 1 | Q27: 1 | R27: 1 | S27: 1 | T27: 1 | U27: 1 | V27: 1 | W27: 1 | X27: 1 | Y27: 1 | Z27: 0.5 | AI27: =SUM(L27:AH27) -> 13.25
D28: 앱웹 화면 UI 디자인 | E28: 중급 | F28: 윤혜림 | G28: - | H28: 45726 | I28: 46127 | M28: 0.75 | N28: 1 | O28: 1 | P28: 1 | Q28: 1 | R28: 1 | S28: 1 | T28: 1 | U28: 1 | V28: 1 | W28: 1 | X28: 1 | Y28: 1 | Z28: 0.5 | AI28: =SUM(L28:AH28) -> 13.25
E29: 중급 | F29: 박민정 | G29: 고급 | H29: 45748 | I29: 46066 | N29: 1 | O29: 1 | P29: 1 | Q29: 1 | R29: 1 | S29: 1 | T29: 1 | U29: 1 | V29: 1 | W29: 1 | X29: 0.5 | AI29: =SUM(L29:AH29) -> 10.5
C30: 디자인 | E30: 초급 | F30: 김민지 | G30: - | H30: 45726 | I30: 46127 | M30: 0.75 | N30: 1 | O30: 1 | P30: 1 | Q30: 1 | R30: 1 | S30: 1 | T30: 1 | U30: 1 | V30: 1 | W30: 1 | X30: 1 | Y30: 1 | Z30: 0.5 | AI30: =SUM(L30:AH30) -> 13.25
C31: 디자인 | E31: 초급 | F31: 이경진 | G31: - | H31: 45748 | I31: 45961 | N31: 1 | O31: 1 | P31: 1 | Q31: 1 | R31: 1 | S31: 1 | T31: 1 | AI31: =SUM(L31:AH31) -> 7
C32: 디자인 | E32: 초급 | F32: 민수연 | G32: - | H32: 45726 | I32: 45989 | M32: 0.75 | N32: 1 | O32: 1 | P32: 1 | Q32: 1 | R32: 1 | S32: 1 | T32: 1 | U32: 1 | AI32: =SUM(L32:AH32) -> 8.75
C33: 디자인 | E33: 초급 | F33: 박성호 | G33: - | H33: 45748 | I33: 45961 | N33: 1 | O33: 1 | P33: 1 | Q33: 1 | R33: 1 | S33: 1 | T33: 1 | AI33: =SUM(L33:AH33) -> 7
C34: 디자인 | E34: 고급 | AI34: 0
C35: 디자인 | E35: 중급 | AI35: 0
C36: 디자인 | E36: 초급 | AI36: 0
C37: 디자인 | E37: 고급 | AI37: 0
C38: 디자인 | E38: 중급 | AI38: 0
C39: 디자인 | E39: 초급 | AI39: 0
C40: 디자인 | D40: 인터렉션 디자인 (Interaction 설계 및 구현) | E40: 고급 | AI40: 0
C41: 디자인 | E41: 중급 | AI41: 0
C42: 디자인 | E42: 초급 | AI42: 0
C43: 디자인 | D43: 합계 | I43: mm | L43: =SUM(L27:L42) -> 0 | M43: =SUM(M27:M42) -> 3 | N43: =SUM(N27:N42) -> 7 | O43: =SUM(O27:O42) -> 7 | P43: =SUM(P27:P42) -> 7 | Q43: =SUM(Q27:Q42) -> 7 | R43: =SUM(R27:R42) -> 7 | S43: =SUM(S27:S42) -> 7 | ... Z43: =SUM(Z27:Z42) -> 1.5 | AI43: =SUM(AI27:AI42) -> 73
...

Sheet history_250425_디자인추가
C3: 현대백화점 New 커머스 플랫폼 구축
C4: 45772
C5: 월별 인력 투입 계획
C6: 업무구분 | D6: 역할 | E6: 계약등급 | F6: 이름 | G6: 실등급 | H6: 계약투입일 | I6: 계약철수일 | J6: 실투입일 | K6: 실철수일 | L6: M1 (2월) | M6: M2 (3월) | N6: M3 (4월) | O6: M4 (5월) | P6: M5 (6월) | Q6: M6 (7월) | R6: M7 (8월) | S6: M8 (9월) | T6: M9 (10월) | U6: M10 (11월) | V6: M11 (12월) | W6: M12 (1월) | X6: M13 (2월) | Y6: M14 (3월) | Z6: M15 (4월) | AI6: M/M계
C7: 현장관리 | D7: 기획/디자인 총괄 (바이널씨 PM) | E7: 고급 | F7: 황세진 | G7: 특급 | H7: 45691 | I7: 46127 | L7: 1 | M7: 1 | N7: 1 | O7: 1 | P7: 1 | Q7: 1 | R7: 1 | S7: 1 | T7: 1 | U7: 1 | V7: 1 | W7: 1 | X7: 1 | Y7: 1 | Z7: 0.5 | AI7: =SUM(L7:AH7) -> 14.5
C8: 기획 | D8: PL (제작가이드, 산출물 검수) | E8: 고급 | F8: 고우정 | G8: 특급 | H8: 45705 | I8: 46127 | L8: 0.5 | M8: 1 | N8: 1 | O8: 1 | P8: 1 | Q8: 1 | R8: 1 | S8: 1 | T8: 1 | U8: 1 | V8: 1 | W8: 1 | X8: 1 | Y8: 1 | Z8: 0.5 | AI8: =SUM(L8:AH8) -> 14
D9: 앱웹 Front UXUI 상세 화면설계 | E9: 고급 | F9: 우미숙 | G9: 특급 | H9: 45691 | I9: 46096 | L9: 1 | M9: 1 | N9: 1 | O9: 1 | P9: 1 | Q9: 1 | R9: 1 | S9: 1 | T9: 1 | U9: 1 | V9: 0.5 | AI9: =SUM(L9:AH9) -> 10.5
E10: 고급 | F10: 정수정 | G10: 특급 | H10: 45691 | I10: 45989 | L10: 1 | M10: 1 | N10: 1 | O10: 1 | P10: 1 | Q10: 1 | R10: 1 | S10: 1 | T10: 1 | U10: 1 | AI10: =SUM(L10:AH10) -> 10
C11: 현장관리 | E11: 고급 | F11: 유경구 | G11: 고급 | H11: 45733 | I11: 45916 | M11: 0.5 | N11: 1 | O11: 1 | P11: 1 | Q11: 1 | R11: 1 | S11: 0.5 | AI11: =SUM(L11:AH11) -> 6
C12: 현장관리 | E12: 고급 | F12: 조선자 | G12: 특급 | H12: 45748 | I12: 45961 | N12: 1 | O12: 1 | P12: 1 | Q12: 1 | R12: 1 | S12: 1 | T12: 1 | AI12: =SUM(L12:AH12) -> 7
C13: 현장관리 | E13: 고급 | F13: 안광훈 | G13: 특급 | H13: 45748 | I13: 45961 | N13: 1 | O13: 1 | P13: 1 | Q13: 1 | R13: 1 | S13: 1 | T13: 1 | AI13: =SUM(L13:AH13) -> 7
C14: 현장관리 | E14: 중급 | F14: 김강현 | G14: 고급 | H14: 45691 | I14: 45960 | L14: 1 | M14: 1 | N14: 1 | O14: 1 | P14: 1 | Q14: 1 | R14: 1 | S14: 1 | T14: 1 | AI14: =SUM(L14:AH14) -> 9
C15: 현장관리 | E15: 중급 | F15: 장익준 | G15: 고급 | H15: 45720 | I15: 46022 | M15: 1 | N15: 1 | O15: 1 | P15: 1 | Q15: 1 | R15: 1 | S15: 1 | T15: 1 | U15: 1 | V15: 1 | AI15: =SUM(L15:AH15) -> 10
C16: 현장관리 | E16: 중급 | F16: 김영근 | G16: 고급 | H16: 45720 | I16: 46022 | M16: 1 | N16: 1 | O16: 1 | P16: 1 | Q16: 1 | R16: 1 | AI16: =SUM(L16:AH16) -> 6
C17: 현장관리 | E17: 초급 | F17: 김세진 | G17: 초급 | H17: 45691 | I17: 45991 | L17: 1 | M17: 1 | N17: 1 | O17: 1 | P17: 1 | Q17: 1 | R17: 1 | S17: 1 | T17: 1 | U17: 1 | AI17: =SUM(L17:AH17) -> 10
C18: 현장관리 | E18: 초급 | F18: 이태림 | G18: 초급 | H18: 45691 | I18: 45961 | L18: 1 | M18: 1 | N18: 1 | O18: 1 | P18: 1 | Q18: 1 | R18: 1 | S18: 1 | T18: 1 | AI18: =SUM(L18:Z18) -> 9
C19: 현장관리 | AI19: =SUM(L19:Z19) -> 0
C20: 현장관리 | AI20: =SUM(L20:AH20) -> 0
C21: 현장관리 | AI21: =SUM(L21:AH21) -> 0
C22: 현장관리 | AI22: =SUM(L22:AH22) -> 0
C23: 현장관리 | AI23: =SUM(L23:AH23) -> 0
C24: 현장관리 | AI24: =SUM(L24:AH24) -> 0
C25: 현장관리 | D25: 합계 | I25: mm | L25: =SUM(L7:L24) -> 6.5 | M25: =SUM(M7:M24) -> 9.5 | N25: =SUM(N7:N24) -> 12 | O25: =SUM(O7:O24) -> 12 | P25: =SUM(P7:P24) -> 12 | Q25: =SUM(Q7:Q24) -> 12 | R25: =SUM(R7:R24) -> 12 | S25: =SUM(S7:S24) -> 10.5 | ... Z25: =SUM(Z7:Z24) -> 1 | AI25: =SUM(AI7:AI24) -> 113
C27: 디자인 | D27: PL (제작가이드, 산출물 검수) | E27: 중급 | F27: 배지효 | G27: - | H27: 45726 | I27: 46127 | M27: 0.75 | N27: 1 | O27: 1 | P27: 1 | Q27: 1 | R27: 1 | S27: 1 | T27: 1 | U27: 1 | V27: 1 | W27: 1 | X27: 1 | Y27: 1 | Z27: 0.5 | AI27: =SUM(L27:AH27) -> 13.25
D28: 앱웹 화면 UI 디자인 | E28: 중급 | F28: 윤혜림 | G28: - | H28: 45726 | I28: 46127 | M28: 0.75 | N28: 1 | O28: 1 | P28: 1 | Q28: 1 | R28: 1 | S28: 1 | T28: 1 | U28: 1 | V28: 1 | W28: 1 | X28: 1 | Y28: 1 | Z28: 0.5 | AI28: =SUM(L28:AH28) -> 13.25
E29: 중급 | F29: 박민정 | G29: 고급 | H29: 45748 | I29: 46066 | N29: 1 | O29: 1 | P29: 1 | Q29: 1 | R29: 1 | S29: 1 | T29: 1 | U29: 1 | AI29: =SUM(L29:AH29) -> 8
C30: 디자인 | E30: 초급 | F30: 김단비 | P30: 1 | Q30: 1 | R30: 1 | S30: 1 | AI30: =SUM(L30:AH30) -> 4
A31: ` | C31: 디자인 | E31: 초급 | F31: 김원형 | P31: 1 | Q31: 1 | R31: 1 | S31: 1 | AI31: =SUM(L31:AH31) -> 4
C32: 디자인 | E32: 초급 | F32: 김민지 | G32: - | H32: 45726 | I32: 46127 | M32: 0.75 | N32: 1 | O32: 1 | P32: 1 | Q32: 1 | R32: 1 | S32: 1 | T32: 1 | U32: 1 | V32: 1 | W32: 1 | X32: 1 | Y32: 0.5 | AI32: =SUM(L32:AH32) -> 12.25
C33: 디자인 | E33: 초급 | F33: 이경진 | G33: - | H33: 45748 | I33: 45961 | N33: 1 | O33: 1 | P33: 1 | Q33: 1 | R33: 1 | S33: 1 | T33: 1 | AI33: =SUM(L33:AH33) -> 7
C34: 디자인 | E34: 초급 | F34: 민수연 | G34: - | H34: 45726 | I34: 45989 | M34: 0.75 | N34: 1 | O34: 1 | P34: 1 | Q34: 1 | R34: 1 | S34: 1 | T34: 1 | U34: 1 | AI34: =SUM(L34:AH34) -> 8.75
C35: 디자인 | E35: 초급 | F35: 박성호 | G35: - | H35: 45748 | I35: 45961 | N35: 1 | O35: 1 | P35: 1 | Q35: 1 | R35: 1 | S35: 1 | T35: 1 | AI35: =SUM(L35:AH35) -> 7
C36: 디자인 | E36: 고급 | AI36: 0
C37: 디자인 | E37: 중급 | AI37: 0
C38: 디자인 | E38: 초급 | AI38: 0
C39: 디자인 | E39: 고급 | AI39: 0
C40: 디자인 | E40: 중급 | AI40: 0
C41: 디자인 | E41: 초급 | AI41: 0
C42: 디자인 | D42: 인터렉션 디자인 (Interaction 설계 및 구현) | E42: 고급 | AI42: 0
C43: 디자인 | E43: 중급 | AI43: 0
...

Sheet 자리배치도
A2: 바이널씨 자리배치도
A3: 4C | D3: 4D
A7: 커 머 스 웨 어 | B7: 고우정 | D7: 황세진 | E7: 배지효 | G7: 이경진
B8: 383 | D8: 702
B9: 45695 | D9: 45691 | E9: 45726 | G9: 45748
B10: 정수정 | D10: 우미숙 | E10: 윤혜림 | G10: 박성호
B11: 346 | D11: 58
B12: 45691 | D12: 45691 | E12: 45726 | G12: 45748
B13: 김강현 | D13: 김세진 | E13: 김민지 | G13: 조선자
B14: 1012 | D14: 63
B15: 45691 | D15: 45691 | E15: 45726 | G15: 45748
B16: 장익준 | D16: 이태림 | E16: 민수연 | G16: 안광훈
B17: 419 | D17: 1017
B18: 45720 | D18: 45691 | E18: 45726 | G18: 45748
B19: 김영근 | D19: 유경구 | E19: 박민정
B20: 320
B21: 45720 | D21: 45733 | E21: 45748
