Workbook
Name 프로젝트유형: [1]기준!$B$28:$B$34

Sheet 자리배치도
A2: 바이널씨 자리배치도
A3: 4C | D3: 4D
B7: 조선자 | D7: 안광훈 | E7: 배지효 | G7: 고우정 | H7: 유승용
B8: 417 | D8: 1020 | E8: 415 | G8: 383
B9: 45748 | D9: 45748 | E9: 45726 | G9: 45695 | H9: 45824
B10: 정수정 | D10: 우미숙 | E10: 윤혜림 | G10: 이경진 | H10: 유지현
B11: 346 | D11: 58 | E11: 711 | G11: 51
B12: 45691 | D12: 45691 | E12: 45726 | G12: 45748 | H12: 45824
B13: 김강현 | D13: 김세진 | E13: 김민지 | G13: 박성호
B14: 1012 | D14: 63 | E14: 105 | G14: 810
B15: 45691 | D15: 45691 | E15: 45726 | G15: 45748
B16: 장익준 | D16: 이태림 | E16: 민수연 | G16: 김단비
B17: 419 | D17: 1017 | E17: 311
B18: 45720 | D18: 45691 | E18: 45726 | G18: 45810
B19: 김영근 | D19: 유경구 | E19: 박민정 | G19: 김원경
B20: 320 | D20: 323 | E20: 760
B21: 45720 | D21: 45733 | E21: 45748 | G21: 45810

Sheet 250117 (제출본-최초)
C3: 현대백화점 New 커머스 플랫폼 구축
C4: 45674
C6: 업무구분 | D6: 역할 | E6: 계약등급 | F6: 이름 | G6: 실등급 | H6: 계약투입일 | I6: 계약철수일 | J6: 실투입일 | K6: 실철수일 | L6: M1 (2월) | M6: M2 (3월) | N6: M3 (4월) | O6: M4 (5월) | P6: M5 (6월) | Q6: M6 (7월) | R6: M7 (8월) | S6: M8 (9월) | T6: M9 (10월) | U6: M10 (11월) | V6: M11 (12월) | W6: M12 (1월) | X6: M13 (2월) | Y6: M14 (3월) | Z6: M15 (4월) | AI6: M/M계
C7: 현장관리 | D7: 기획/디자인 총괄 (바이널씨 PM) | E7: 고급 | F7: 황세진 | G7: 특급 | H7: 45691 | I7: 46127 | L7: 1 | M7: 1 | N7: 1 | O7: 1 | P7: 1 | Q7: 1 | R7: 1 | S7: 1 | T7: 1 | U7: 1 | V7: 1 | W7: 1 | X7: 1 | Y7: 1 | Z7: 0.5 | AI7: =SUM(L7:AH7) -> 14.5
C8: 기획 | D8: PL (제작가이드, 산출물 검수) | E8: 고급 | F8: 고우정 | G8: 특급 | H8: 45705 | I8: 46127 | L8: 0.5 | M8: 1 | N8: 1 | O8: 1 | P8: 1 | Q8: 1 | R8: 1 | S8: 1 | T8: 1 | U8: 1 | V8: 1 | W8: 1 | X8: 1 | Y8: 1 | Z8: 0.5 | AI8: =SUM(L8:AH8) -> 14
D9: 앱웹 Front UXUI 상세 화면설계 | E9: 고급 | F9: 우미숙 | G9: 특급 | H9: 45691 | I9: 46096 | L9: 1 | M9: 1 | N9: 1 | O9: 1 | P9: 1 | Q9: 1 | R9: 1 | S9: 1 | T9: 1 | U9: 1 | V9: 1 | W9: 1 | X9: 1 | Y9: 0.5 | AI9: =SUM(L9:AH9) -> 13.5
E10: 고급 | F10: 정수정 | G10: - | H10: 45691 | I10: 46081 | L10: 1 | M10: 1 | N10: 1 | O10: 1 | P10: 1 | Q10: 1 | R10: 1 | S10: 1 | T10: 1 | U10: 1 | V10: 1 | W10: 1 | X10: 1 | AI10: =SUM(L10:AH10) -> 13
C11: 현장관리 | E11: 중급 | F11: 최철원 | G11: 고급 | H11: 45719 | I11: 46096 | L11: 0 | M11: 1 | N11: 1 | O11: 1 | P11: 1 | Q11: 1 | R11: 1 | S11: 1 | T11: 1 | U11: 1 | V11: 1 | W11: 1 | X11: 1 | Y11: 0.5 | AI11: =SUM(L11:AH11) -> 12.5
C12: 현장관리 | E12: 중급 | F12: 김강현 | G12: 고급 | H12: 45691 | I12: 46068 | L12: 1 | M12: 1 | N12: 1 | O12: 1 | P12: 1 | Q12: 1 | R12: 1 | S12: 1 | T12: 1 | U12: 1 | V12: 1 | W12: 1 | X12: 0.5 | AI12: =SUM(L12:AH12) -> 12.5
C13: 현장관리 | E13: 초급 | F13: 김세진 | G13: - | H13: 45691 | I13: 46022 | L13: 1 | M13: 1 | N13: 1 | O13: 1 | P13: 1 | Q13: 1 | R13: 1 | S13: 1 | T13: 1 | U13: 1 | V13: 1 | AI13: =SUM(L13:AH13) -> 11
C14: 현장관리 | E14: 초급 | F14: 이태림 | G14: - | H14: 45691 | I14: 45930 | L14: 1 | M14: 1 | N14: 1 | O14: 1 | P14: 1 | Q14: 1 | R14: 1 | S14: 1 | AI14: =SUM(L14:AH14) -> 8
C15: 현장관리 | E15: 고급 | AI15: 0
C16: 현장관리 | E16: 중급 | AI16: 0
C17: 현장관리 | E17: 초급 | AI17: 0
C18: 현장관리 | E18: 고급 | AI18: 0
C19: 현장관리 | E19: 중급 | AI19: 0
C20: 현장관리 | E20: 초급 | AI20: 0
C21: 현장관리 | D21: 합계 | I21: mm | L21: =SUM(L7:L20) -> 6.5 | M21: =SUM(M7:M20) -> 8 | N21: =SUM(N7:N20) -> 8 | O21: =SUM(O7:O20) -> 8 | P21: =SUM(P7:P20) -> 8 | Q21: =SUM(Q7:Q20) -> 8 | R21: =SUM(R7:R20) -> 8 | S21: =SUM(S7:S20) -> 8 | ... Z21: =SUM(Z7:Z20) -> 1 | AI21: =SUM(AI7:AI20) -> 99
C23: 디자인 | D23: PL (제작가이드, 산출물 검수) | E23: 중급 | F23: 배지효 | G23: - | H23: 45740 | I23: 46127 | M23: 0.25 | N23: 1 | O23: 1 | P23: 1 | Q23: 1 | R23: 1 | S23: 1 | T23: 1 | U23: 1 | V23: 1 | W23: 1 | X23: 1 | Y23: 1 | Z23: 0.5 | AI23: =SUM(M23:AH23) -> 12.75
D24: 앱웹 화면 UI 디자인 | E24: 중급 | F24: 윤혜림 | G24: - | H24: 45740 | I24: 46112 | M24: 0.25 | N24: 1 | O24: 1 | P24: 1 | Q24: 1 | R24: 1 | S24: 1 | T24: 1 | U24: 1 | V24: 1 | W24: 1 | X24: 1 | Y24: 1 | AI24: =SUM(M24:AH24) -> 12.25
E25: 중급 | F25: 박민정 | G25: 고급 | H25: 45748 | I25: 46112 | N25: 1 | O25: 1 | P25: 1 | Q25: 1 | R25: 1 | S25: 1 | T25: 1 | U25: 1 | V25: 1 | W25: 1 | X25: 1 | Y25: 1 | AI25: =SUM(M25:AH25) -> 12
C26: 디자인 | E26: 초급 | F26: 김민지 | G26: - | H26: 45740 | I26: 46112 | M26: 0.25 | N26: 1 | O26: 1 | P26: 1 | Q26: 1 | R26: 1 | S26: 1 | T26: 1 | U26: 1 | V26: 1 | W26: 1 | X26: 1 | Y26: 1 | AI26: =SUM(M26:AH26) -> 12.25
C27: 디자인 | E27: 초급 | F27: 이경진 | G27: - | H27: 45740 | I27: 45991 | M27: 0.25 | N27: 1 | O27: 1 | P27: 1 | Q27: 1 | R27: 1 | S27: 1 | T27: 1 | U27: 1 | AI27: =SUM(M27:AH27) -> 8.25
C28: 디자인 | E28: 초급 | F28: 민수연 | G28: - | H28: 45748 | I28: 45991 | N28: 1 | O28: 1 | P28: 1 | Q28: 1 | R28: 1 | S28: 1 | T28: 1 | U28: 1 | AI28: =SUM(M28:AH28) -> 8
C29: 디자인 | E29: 초급 | F29: 박성호 | G29: 고급 | H29: 45748 | I29: 45976 | N29: 1 | O29: 1 | P29: 1 | Q29: 1 | R29: 1 | S29: 1 | T29: 1 | U29: 0.5 | AI29: =SUM(M29:AH29) -> 7.5
C30: 디자인 | E30: 고급 | AI30: 0
C31: 디자인 | E31: 중급 | AI31: 0
C32: 디자인 | E32: 초급 | AI32: 0
C33: 디자인 | E33: 고급 | AI33: 0
C34: 디자인 | E34: 중급 | AI34: 0
C35: 디자인 | E35: 초급 | AI35: 0
C36: 디자인 | D36: 인터렉션 디자인 (Interaction 설계 및 구현) | E36: 고급 | AI36: 0
C37: 디자인 | E37: 중급 | AI37: 0
C38: 디자인 | E38: 초급 | AI38: 0
C39: 디자인 | D39: 합계 | I39: mm | L39: =SUM(L23:L38) -> 0 | M39: =SUM(M23:M38) -> 1 | N39: =SUM(N23:N38) -> 7 | O39: =SUM(O23:O38) -> 7 | P39: =SUM(P23:P38) -> 7 | Q39: =SUM(Q23:Q38) -> 7 | R39: =SUM(R23:R38) -> 7 | S39: =SUM(S23:S38) -> 7 | ... Z39: =SUM(Z23:Z38) -> 0.5 | AI39: =SUM(AI23:AI38) -> 73
C41: 합계 | I41: MM | L41: =L21+L39 -> 6.5 | M41: =M21+M39 -> 9 | N41: =N21+N39 -> 15 | O41: =O21+O39 -> 15 | P41: =P21+P39 -> 15 | Q41: =Q21+Q39 -> 15 | R41: =R21+R39 -> 15 | S41: =S21+S39 -> 15 | ... Z41: =Z21+Z39 -> 1.5 | AI41: =AI21+AI39 -> 172
S44: 등급별 계획공수 | X44: 계획공수
S45: 부문 | T45: 등급 | U45: 공수 | V45: 합계 | X45: 계약공수 | Z45: 172
S46: 기획 | T46: 고급 | U46: =SUMIF($E$7:$E$14,"고급",$AI$7:$AI$14) -> 55 | V46: =SUM(U46:U48) -> 99 | X46: 본사 추가지원 공수 | Z46: =204.5-Z45 -> 32.5
T47: 중급 | U47: =SUMIF($E$7:$E$14,"중급",$AI$7:$AI$14) -> 25 | X47: 총 가용 공수 | Z47: 204.5
...

Sheet 250217 (제출본-최종)
C3: 현대백화점 New 커머스 플랫폼 구축
C4: 45705
C5: 월별 인력 투입 계획
C6: 업무구분 | D6: 역할 | E6: 계약등급 | F6: 이름 | G6: 실등급 | H6: 계약투입일 | I6: 계약철수일 | J6: 실투입일 | K6: 실철수일 | L6: M1 (2월) | M6: M2 (3월) | N6: M3 (4월) | O6: M4 (5월) | P6: M5 (6월) | Q6: M6 (7월) | R6: M7 (8월) | S6: M8 (9월) | T6: M9 (10월) | U6: M10 (11월) | V6: M11 (12월) | W6: M12 (1월) | X6: M13 (2월) | Y6: M14 (3월) | Z6: M15 (4월) | AI6: M/M계
C7: 현장관리 | D7: 기획/디자인 총괄 (바이널씨 PM) | E7: 고급 | F7: 황세진 | G7: 특급 | H7: 45691 | I7: 46127 | L7: 1 | M7: 1 | N7: 1 | O7: 1 | P7: 1 | Q7: 1 | R7: 1 | S7: 1 | T7: 1 | U7: 1 | V7: 1 | W7: 1 | X7: 1 | Y7: 1 | Z7: 0.5 | AI7: =SUM(L7:AH7) -> 14.5
C8: 기획 | D8: PL (제작가이드, 산출물 검수) | E8: 고급 | F8: 고우정 | G8: 특급 | H8: 45705 | I8: 46127 | L8: 0.5 | M8: 1 | N8: 1 | O8: 1 | P8: 1 | Q8: 1 | R8: 1 | S8: 1 | T8: 1 | U8: 1 | V8: 1 | W8: 1 | X8: 1 | Y8: 1 | Z8: 0.5 | AI8: =SUM(L8:AH8) -> 14
D9: 앱웹 Front UXUI 상세 화면설계 | E9: 고급 | F9: 우미숙 | G9: 특급 | H9: 45691 | I9: 46096 | L9: 1 | M9: 1 | N9: 1 | O9: 1 | P9: 1 | Q9: 1 | R9: 1 | S9: 1 | T9: 1 | U9: 1 | V9: 0.5 | AI9: =SUM(L9:AH9) -> 10.5
E10: 고급 | F10: 정수정 | G10: 특급 | H10: 45691 | I10: 45989 | L10: 1 | M10: 1 | N10: 1 | O10: 1 | P10: 1 | Q10: 1 | R10: 1 | S10: 1 | T10: 1 | U10: 1 | AI10: =SUM(L10:AH10) -> 10
C11: 현장관리 | E11: 고급 | F11: TBD | G11: 고급 | H11: 45748 | I11: 45930 | N11: 1 | O11: 1 | P11: 1 | Q11: 1 | R11: 1 | S11: 1 | AI11: =SUM(L11:AH11) -> 6
C12: 현장관리 | E12: 중급 | F12: 김강현 | G12: 고급 | H12: 45691 | I12: 45960 | L12: 1 | M12: 1 | N12: 1 | O12: 1 | P12: 1 | Q12: 1 | R12: 1 | S12: 1 | T12: 1 | AI12: =SUM(L12:AH12) -> 9
C13: 현장관리 | E13: 중급 | F13: 장익준 | G13: 고급 | H13: 45720 | I13: 46022 | M13: 1 | N13: 1 | O13: 1 | P13: 1 | Q13: 1 | R13: 1 | S13: 1 | T13: 1 | U13: 1 | V13: 1 | AI13: =SUM(L13:AH13) -> 10
C14: 현장관리 | E14: 중급 | F14: 김영근 | G14: 고급 | H14: 45720 | I14: 45900 | M14: 1 | N14: 1 | O14: 1 | P14: 1 | Q14: 1 | R14: 1 | AI14: =SUM(L14:AH14) -> 6
C15: 현장관리 | E15: 초급 | F15: 김세진 | G15: 초급 | H15: 45691 | I15: 45991 | L15: 1 | M15: 1 | N15: 1 | O15: 1 | P15: 1 | Q15: 1 | R15: 1 | S15: 1 | T15: 1 | U15: 1 | AI15: =SUM(L15:AH15) -> 10
C16: 현장관리 | E16: 초급 | F16: 이태림 | G16: 초급 | H16: 45691 | I16: 45961 | L16: 1 | M16: 1 | N16: 1 | O16: 1 | P16: 1 | Q16: 1 | R16: 1 | S16: 1 | T16: 1 | AI16: =SUM(L16:Z16) -> 9
C17: 현장관리 | AI17: =SUM(L17:Z17) -> 0
C18: 현장관리 | AI18: =SUM(L18:AH18) -> 0
C19: 현장관리 | AI19: =SUM(L19:AH19) -> 0
C20: 현장관리 | AI20: =SUM(L20:AH20) -> 0
C21: 현장관리 | AI21: =SUM(L21:AH21) -> 0
C22: 현장관리 | AI22: =SUM(L22:AH22) -> 0
C23: 현장관리 | D23: 합계 | I23: mm | L23: =SUM(L7:L22) -> 6.5 | M23: =SUM(M7:M22) -> 9 | N23: =SUM(N7:N22) -> 10 | O23: =SUM(O7:O22) -> 10 | P23: =SUM(P7:P22) -> 10 | Q23: =SUM(Q7:Q22) -> 10 | R23: =SUM(R7:R22) -> 10 | S23: =SUM(S7:S22) -> 9 | ... Z23: =SUM(Z7:Z22) -> 1 | AI23: =SUM(AI7:AI22) -> 99
C25: 디자인 | D25: PL (제작가이드, 산출물 검수) | E25: 중급 | F25: 배지효 | G25: - | H25: 45726 | I25: 46127 | M25: 0.75 | N25: 1 | O25: 1 | P25: 1 | Q25: 1 | R25: 1 | S25: 1 | T25: 1 | U25: 1 | V25: 1 | W25: 1 | X25: 1 | Y25: 1 | Z25: 0.5 | AI25: =SUM(L25:AH25) -> 13.25
D26: 앱웹 화면 UI 디자인 | E26: 중급 | F26: 윤혜림 | G26: - | H26: 45726 | I26: 46127 | M26: 0.75 | N26: 1 | O26: 1 | P26: 1 | Q26: 1 | R26: 1 | S26: 1 | T26: 1 | U26: 1 | V26: 1 | W26: 1 | X26: 1 | Y26: 1 | Z26: 0.5 | AI26: =SUM(L26:AH26) -> 13.25
E27: 중급 | F27: 박민정 | G27: 고급 | H27: 45748 | I27: 46066 | N27: 1 | O27: 1 | P27: 1 | Q27: 1 | R27: 1 | S27: 1 | T27: 1 | U27: 1 | V27: 1 | W27: 1 | X27: 0.5 | AI27: =SUM(L27:AH27) -> 10.5
C28: 디자인 | E28: 초급 | F28: 김민지 | G28: - | H28: 45726 | I28: 46127 | M28: 0.75 | N28: 1 | O28: 1 | P28: 1 | Q28: 1 | R28: 1 | S28: 1 | T28: 1 | U28: 1 | V28: 1 | W28: 1 | X28: 1 | Y28: 1 | Z28: 0.5 | AI28: =SUM(L28:AH28) -> 13.25
C29: 디자인 | E29: 초급 | F29: 이경진 | G29: - | H29: 45748 | I29: 45961 | N29: 1 | O29: 1 | P29: 1 | Q29: 1 | R29: 1 | S29: 1 | T29: 1 | AI29: =SUM(L29:AH29) -> 7
C30: 디자인 | E30: 초급 | F30: 민수연 | G30: - | H30: 45726 | I30: 45989 | M30: 0.75 | N30: 1 | O30: 1 | P30: 1 | Q30: 1 | R30: 1 | S30: 1 | T30: 1 | U30: 1 | AI30: =SUM(L30:AH30) -> 8.75
C31: 디자인 | E31: 초급 | F31: 박성호 | G31: - | H31: 45748 | I31: 45961 | N31: 1 | O31: 1 | P31: 1 | Q31: 1 | R31: 1 | S31: 1 | T31: 1 | AI31: =SUM(L31:AH31) -> 7
C32: 디자인 | E32: 고급 | AI32: 0
C33: 디자인 | E33: 중급 | AI33: 0
C34: 디자인 | E34: 초급 | AI34: 0
C35: 디자인 | E35: 고급 | AI35: 0
C36: 디자인 | E36: 중급 | AI36: 0
C37: 디자인 | E37: 초급 | AI37: 0
C38: 디자인 | D38: 인터렉션 디자인 (Interaction 설계 및 구현) | E38: 고급 | AI38: 0
C39: 디자인 | E39: 중급 | AI39: 0
C40: 디자인 | E40: 초급 | AI40: 0
C41: 디자인 | D41: 합계 | I41: mm | L41: =SUM(L25:L40) -> 0 | M41: =SUM(M25:M40) -> 3 | N41: =SUM(N25:N40) -> 7 | O41: =SUM(O25:O40) -> 7 | P41: =SUM(P25:P40) -> 7 | Q41: =SUM(Q25:Q40) -> 7 | R41: =SUM(R25:R40) -> 7 | S41: =SUM(S25:S40) -> 7 | ... Z41: =SUM(Z25:Z40) -> 1.5 | AI41: =SUM(AI25:AI40) -> 73
C43: 합계 | I43: MM | L43: =L23+L41 -> 6.5 | M43: =M23+M41 -> 12 | N43: =N23+N41 -> 17 | O43: =O23+O41 -> 17 | P43: =P23+P41 -> 17 | Q43: =Q23+Q41 -> 17 | R43: =R23+R41 -> 17 | S43: =S23+S41 -> 16 | ... Z43: =Z23+Z41 -> 2.5 | AI43: =AI23+AI41 -> 172
C45: > 최초 인력투입 계획 (1/17)에서는 정수정님, 김강현님이 2월까지로 되어 있었으나, 실제 두 분 계약은 각각 11월/10월로 되어있어서 수정
...

Sheet 250305
C3: 현대백화점 New 커머스 플랫폼 구축
C4: 45742
C5: 월별 인력 투입 계획
C6: 업무구분 | D6: 역할 | E6: 계약등급 | F6: 이름 | G6: 실등급 | H6: 계약투입일 | I6: 계약철수일 | J6: 실투입일 | K6: 실철수일 | L6: M1 (2월) | M6: M2 (3월) | N6: M3 (4월) | O6: M4 (5월) | P6: M5 (6월) | Q6: M6 (7월) | R6: M7 (8월) | S6: M8 (9월) | T6: M9 (10월) | U6: M10 (11월) | V6: M11 (12월) | W6: M12 (1월) | X6: M13 (2월) | Y6: M14 (3월) | Z6: M15 (4월) | AI6: M/M계
C7: 현장관리 | D7: 기획/디자인 총괄 (바이널씨 PM) | E7: 고급 | F7: 황세진 | G7: 특급 | H7: 45691 | I7: 46127 | L7: 1 | M7: 1 | N7: 1 | O7: 1 | P7: 1 | Q7: 1 | R7: 1 | S7: 1 | T7: 1 | U7: 1 | V7: 1 | W7: 1 | X7: 1 | Y7: 1 | Z7: 0.5 | AI7: =SUM(L7:AH7) -> 14.5
C8: 기획 | D8: PL (제작가이드, 산출물 검수) | E8: 고급 | F8: 고우정 | G8: 특급 | H8: 45705 | I8: 46127 | L8: 0.5 | M8: 1 | N8: 1 | O8: 1 | P8: 1 | Q8: 1 | R8: 1 | S8: 1 | T8: 1 | U8: 1 | V8: 1 | W8: 1 | X8: 1 | Y8: 1 | Z8: 0.5 | AI8: =SUM(L8:AH8) -> 14
D9: 앱웹 Front UXUI 상세 화면설계 | E9: 고급 | F9: 우미숙 | G9: 특급 | H9: 45691 | I9: 46096 | L9: 1 | M9: 1 | N9: 1 | O9: 1 | P9: 1 | Q9: 1 | R9: 1 | S9: 1 | T9: 1 | U9: 1 | V9: 0.5 | AI9: =SUM(L9:AH9) -> 10.5
E10: 고급 | F10: 정수정 | G10: 특급 | H10: 45691 | I10: 45989 | L10: 1 | M10: 1 | N10: 1 | O10: 1 | P10: 1 | Q10: 1 | R10: 1 | S10: 1 | T10: 1 | U10: 1 | AI10: =SUM(L10:AH10) -> 10
C11: 현장관리 | E11: 고급 | F11: 유경구 | G11: 고급 | H11: 45733 | I11: 45916 | M11: 0.5 | N11: 1 | O11: 1 | P11: 1 | Q11: 1 | R11: 1 | S11: 0.5 | AI11: =SUM(L11:AH11) -> 6
C12: 현장관리 | E12: 중급 | F12: 김강현 | G12: 고급 | H12: 45691 | I12: 45960 | L12: 1 | M12: 1 | N12: 1 | O12: 1 | P12: 1 | Q12: 1 | R12: 1 | S12: 1 | T12: 1 | AI12: =SUM(L12:AH12) -> 9
C13: 현장관리 | E13: 중급 | F13: 장익준 | G13: 고급 | H13: 45720 | I13: 46022 | M13: 1 | N13: 1 | O13: 1 | P13: 1 | Q13: 1 | R13: 1 | S13: 1 | T13: 1 | U13: 1 | V13: 1 | AI13: =SUM(L13:AH13) -> 10
C14: 현장관리 | E14: 중급 | F14: 김영근 | G14: 고급 | H14: 45720 | I14: 45900 | M14: 1 | N14: 1 | O14: 1 | P14: 1 | Q14: 1 | R14: 1 | AI14: =SUM(L14:AH14) -> 6
C15: 현장관리 | E15: 초급 | F15: 김세진 | G15: 초급 | H15: 45691 | I15: 45991 | L15: 1 | M15: 1 | N15: 1 | O15: 1 | P15: 1 | Q15: 1 | R15: 1 | S15: 1 | T15: 1 | U15: 1 | AI15: =SUM(L15:AH15) -> 10
C16: 현장관리 | E16: 초급 | F16: 이태림 | G16: 초급 | H16: 45691 | I16: 45961 | L16: 1 | M16: 1 | N16: 1 | O16: 1 | P16: 1 | Q16: 1 | R16: 1 | S16: 1 | T16: 1 | AI16: =SUM(L16:Z16) -> 9
C17: 현장관리 | AI17: =SUM(L17:Z17) -> 0
C18: 현장관리 | AI18: =SUM(L18:AH18) -> 0
C19: 현장관리 | AI19: =SUM(L19:AH19) -> 0
C20: 현장관리 | AI20: =SUM(L20:AH20) -> 0
C21: 현장관리 | AI21: =SUM(L21:AH21) -> 0
C22: 현장관리 | AI22: =SUM(L22:AH22) -> 0
C23: 현장관리 | D23: 합계 | I23: mm | L23: =SUM(L7:L22) -> 6.5 | M23: =SUM(M7:M22) -> 9.5 | N23: =SUM(N7:N22) -> 10 | O23: =SUM(O7:O22) -> 10 | P23: =SUM(P7:P22) -> 10 | Q23: =SUM(Q7:Q22) -> 10 | R23: =SUM(R7:R22) -> 10 | S23: =SUM(S7:S22) -> 8.5 | ... Z23: =SUM(Z7:Z22) -> 1 | AI23: =SUM(AI7:AI22) -> 99
C25: 디자인 | D25: PL (제작가이드, 산출물 검수) | E25: 중급 | F25: 배지효 | G25: - | H25: 45726 | I25: 46127 | M25: 0.75 | N25: 1 | O25: 1 | P25: 1 | Q25: 1 | R25: 1 | S25: 1 | T25: 1 | U25: 1 | V25: 1 | W25: 1 | X25: 1 | Y25: 1 | Z25: 0.5 | AI25: =SUM(L25:AH25) -> 13.25
D26: 앱웹 화면 UI 디자인 | E26: 중급 | F26: 윤혜림 | G26: - | H26: 45726 | I26: 46127 | M26: 0.75 | N26: 1 | O26: 1 | P26: 1 | Q26: 1 | R26: 1 | S26: 1 | T26: 1 | U26: 1 | V26: 1 | W26: 1 | X26: 1 | Y26: 1 | Z26: 0.5 | AI26: =SUM(L26:AH26) -> 13.25
E27: 중급 | F27: 박민정 | G27: 고급 | H27: 45748 | I27: 46066 | N27: 1 | O27: 1 | P27: 1 | Q27: 1 | R27: 1 | S27: 1 | T27: 1 | U27: 1 | V27: 1 | W27: 1 | X27: 0.5 | AI27: =SUM(L27:AH27) -> 10.5
C28: 디자인 | E28: 초급 | F28: 김민지 | G28: - | H28: 45726 | I28: 46127 | M28: 0.75 | N28: 1 | O28: 1 | P28: 1 | Q28: 1 | R28: 1 | S28: 1 | T28: 1 | U28: 1 | V28: 1 | W28: 1 | X28: 1 | Y28: 1 | Z28: 0.5 | AI28: =SUM(L28:AH28) -> 13.25
C29: 디자인 | E29: 초급 | F29: 이경진 | G29: - | H29: 45748 | I29: 45961 | N29: 1 | O29: 1 | P29: 1 | Q29: 1 | R29: 1 | S29: 1 | T29: 1 | AI29: =SUM(L29:AH29) -> 7
C30: 디자인 | E30: 초급 | F30: 민수연 | G30: - | H30: 45726 | I30: 45989 | M30: 0.75 | N30: 1 | O30: 1 | P30: 1 | Q30: 1 | R30: 1 | S30: 1 | T30: 1 | U30: 1 | AI30: =SUM(L30:AH30) -> 8.75
C31: 디자인 | E31: 초급 | F31: 박성호 | G31: - | H31: 45748 | I31: 45961 | N31: 1 | O31: 1 | P31: 1 | Q31: 1 | R31: 1 | S31: 1 | T31: 1 | AI31: =SUM(L31:AH31) -> 7
C32: 디자인 | E32: 고급 | AI32: 0
C33: 디자인 | E33: 중급 | AI33: 0
C34: 디자인 | E34: 초급 | AI34: 0
C35: 디자인 | E35: 고급 | AI35: 0
C36: 디자인 | E36: 중급 | AI36: 0
C37: 디자인 | E37: 초급 | AI37: 0
C38: 디자인 | D38: 인터렉션 디자인 (Interaction 설계 및 구현) | E38: 고급 | AI38: 0
C39: 디자인 | E39: 중급 | AI39: 0
C40: 디자인 | E40: 초급 | AI40: 0
C41: 디자인 | D41: 합계 | I41: mm | L41: =SUM(L25:L40) -> 0 | M41: =SUM(M25:M40) -> 3 | N41: =SUM(N25:N40) -> 7 | O41: =SUM(O25:O40) -> 7 | P41: =SUM(P25:P40) -> 7 | Q41: =SUM(Q25:Q40) -> 7 | R41: =SUM(R25:R40) -> 7 | S41: =SUM(S25:S40) -> 7 | ... Z41: =SUM(Z25:Z40) -> 1.5 | AI41: =SUM(AI25:AI40) -> 73
C43: 합계 | I43: MM | L43: =L23+L41 -> 6.5 | M43: =M23+M41 -> 12.5 | N43: =N23+N41 -> 17 | O43: =O23+O41 -> 17 | P43: =P23+P41 -> 17 | Q43: =Q23+Q41 -> 17 | R43: =R23+R41 -> 17 | S43: =S23+S41 -> 15.5 | ... Z43: =Z23+Z41 -> 2.5 | AI43: =AI23+AI41 -> 172
C45: > 최초 인력투입 계획 (1/17)에서는 정수정님, 김강현님이 2월까지로 되어 있었으나, 실제 두 분 계약은 각각 11월/10월로 되어있어서 수정
...

Sheet 250326
C3: 현대백화점 New 커머스 플랫폼 구축
C4: 45742
C5: 월별 인력 투입 계획
C6: 업무구분 | D6: 역할 | E6: 계약등급 | F6: 이름 | G6: 실등급 | H6: 계약투입일 | I6: 계약철수일 | J6: 실투입일 | K6: 실철수일 | L6: M1 (2월) | M6: M2 (3월) | N6: M3 (4월) | O6: M4 (5월) | P6: M5 (6월) | Q6: M6 (7월) | R6: M7 (8월) | S6: M8 (9월) | T6: M9 (10월) | U6: M10 (11월) | V6: M11 (12월) | W6: M12 (1월) | X6: M13 (2월) | Y6: M14 (3월) | Z6: M15 (4월) | AI6: M/M계
C7: 현장관리 | D7: 기획/디자인 총괄 (바이널씨 PM) | E7: 고급 | F7: 황세진 | G7: 특급 | H7: 45691 | I7: 46127 | L7: 1 | M7: 1 | N7: 1 | O7: 1 | P7: 1 | Q7: 1 | R7: 1 | S7: 1 | T7: 1 | U7: 1 | V7: 1 | W7: 1 | X7: 1 | Y7: 1 | Z7: 0.5 | AI7: =SUM(L7:AH7) -> 14.5
C8: 기획 | D8: PL (제작가이드, 산출물 검수) | E8: 고급 | F8: 고우정 | G8: 특급 | H8: 45705 | I8: 46127 | L8: 0.5 | M8: 1 | N8: 1 | O8: 1 | P8: 1 | Q8: 1 | R8: 1 | S8: 1 | T8: 1 | U8: 1 | V8: 1 | W8: 1 | X8: 1 | Y8: 1 | Z8: 0.5 | AI8: =SUM(L8:AH8) -> 14
D9: 앱웹 Front UXUI 상세 화면설계 | E9: 고급 | F9: 우미숙 | G9: 특급 | H9: 45691 | I9: 46096 | L9: 1 | M9: 1 | N9: 1 | O9: 1 | P9: 1 | Q9: 1 | R9: 1 | S9: 1 | T9: 1 | U9: 1 | V9: 0.5 | AI9: =SUM(L9:AH9) -> 10.5
E10: 고급 | F10: 정수정 | G10: 특급 | H10: 45691 | I10: 45989 | L10: 1 | M10: 1 | N10: 1 | O10: 1 | P10: 1 | Q10: 1 | R10: 1 | S10: 1 | T10: 1 | U10: 1 | AI10: =SUM(L10:AH10) -> 10
C11: 현장관리 | E11: 고급 | F11: 유경구 | G11: 고급 | H11: 45733 | I11: 45916 | M11: 0.5 | N11: 1 | O11: 1 | P11: 1 | Q11: 1 | R11: 1 | S11: 0.5 | AI11: =SUM(L11:AH11) -> 6
C12: 현장관리 | E12: 고급 | F12: 조선자 | G12: 특급 | H12: 45748 | I12: 45961 | N12: 1 | O12: 1 | P12: 1 | Q12: 1 | R12: 1 | S12: 1 | T12: 1 | AI12: =SUM(L12:AH12) -> 7
C13: 현장관리 | E13: 고급 | F13: 안광훈 | G13: 특급 | H13: 45748 | I13: 45961 | N13: 1 | O13: 1 | P13: 1 | Q13: 1 | R13: 1 | S13: 1 | T13: 1 | AI13: =SUM(L13:AH13) -> 7
C14: 현장관리 | E14: 중급 | F14: 김강현 | G14: 고급 | H14: 45691 | I14: 45960 | L14: 1 | M14: 1 | N14: 1 | O14: 1 | P14: 1 | Q14: 1 | R14: 1 | S14: 1 | T14: 1 | AI14: =SUM(L14:AH14) -> 9
C15: 현장관리 | E15: 중급 | F15: 장익준 | G15: 고급 | H15: 45720 | I15: 46022 | M15: 1 | N15: 1 | O15: 1 | P15: 1 | Q15: 1 | R15: 1 | S15: 1 | T15: 1 | U15: 1 | V15: 1 | AI15: =SUM(L15:AH15) -> 10
C16: 현장관리 | E16: 중급 | F16: 김영근 | G16: 고급 | H16: 45720 | I16: 45900 | M16: 1 | N16: 1 | O16: 1 | P16: 1 | Q16: 1 | R16: 1 | AI16: =SUM(L16:AH16) -> 6
C17: 현장관리 | E17: 초급 | F17: 김세진 | G17: 초급 | H17: 45691 | I17: 45991 | L17: 1 | M17: 1 | N17: 1 | O17: 1 | P17: 1 | Q17: 1 | R17: 1 | S17: 1 | T17: 1 | U17: 1 | AI17: =SUM(L17:AH17) -> 10
C18: 현장관리 | E18: 초급 | F18: 이태림 | G18: 초급 | H18: 45691 | I18: 45961 | L18: 1 | M18: 1 | N18: 1 | O18: 1 | P18: 1 | Q18: 1 | R18: 1 | S18: 1 | T18: 1 | AI18: =SUM(L18:Z18) -> 9
C19: 현장관리 | AI19: =SUM(L19:Z19) -> 0
C20: 현장관리 | AI20: =SUM(L20:AH20) -> 0
C21: 현장관리 | AI21: =SUM(L21:AH21) -> 0
C22: 현장관리 | AI22: =SUM(L22:AH22) -> 0
C23: 현장관리 | AI23: =SUM(L23:AH23) -> 0
C24: 현장관리 | AI24: =SUM(L24:AH24) -> 0
C25: 현장관리 | D25: 합계 | I25: mm | L25: =SUM(L7:L24) -> 6.5 | M25: =SUM(M7:M24) -> 9.5 | N25: =SUM(N7:N24) -> 12 | O25: =SUM(O7:O24) -> 12 | P25: =SUM(P7:P24) -> 12 | Q25: =SUM(Q7:Q24) -> 12 | R25: =SUM(R7:R24) -> 12 | S25: =SUM(S7:S24) -> 10.5 | ... Z25: =SUM(Z7:Z24) -> 1 | AI25: =SUM(AI7:AI24) -> 113
C27: 디자인 | D27: PL (제작가이드, 산출물 검수) | E27: 중급 | F27: 배지효 | G27: - | H27: 45726 | I27: 46127 | M27: 0.75 | N27: 1 | O27: 1 | P27: 1 | Q27: 1 | R27: 1 | S27: 1 | T27: 1 | U27: 1 | V27: 1 | W27: 1 | X27: 1 | Y27: 1 | Z27: 0.5 | AI27: =SUM(L27:AH27) -> 13.25
D28: 앱웹 화면 UI 디자인 | E28: 중급 | F28: 윤혜림 | G28: - | H28: 45726 | I28: 46127 | M28: 0.75 | N28: 1 | O28: 1 | P28: 1 | Q28: 1 | R28: 1 | S28: 1 | T28: 1 | U28: 1 | V28: 1 | W28: 1 | X28: 1 | Y28: 1 | Z28: 0.5 | AI28: =SUM(L28:AH28) -> 13.25
E29: 중급 | F29: 박민정 | G29: 고급 | H29: 45748 | I29: 46066 | N29: 1 | O29: 1 | P29: 1 | Q29: 1 | R29: 1 | S29: 1 | T29: 1 | U29: 1 | V29: 1 | W29: 1 | X29: 0.5 | AI29: =SUM(L29:AH29) -> 10.5
C30: 디자인 | E30: 초급 | F30: 김민지 | G30: - | H30: 45726 | I30: 46127 | M30: 0.75 | N30: 1 | O30: 1 | P30: 1 | Q30: 1 | R30: 1 | S30: 1 | T30: 1 | U30: 1 | V30: 1 | W30: 1 | X30: 1 | Y30: 1 | Z30: 0.5 | AI30: =SUM(L30:AH30) -> 13.25
C31: 디자인 | E31: 초급 | F31: 이경진 | G31: - | H31: 45748 | I31: 45961 | N31: 1 | O31: 1 | P31: 1 | Q31: 1 | R31: 1 | S31: 1 | T31: 1 | AI31: =SUM(L31:AH31) -> 7
C32: 디자인 | E32: 초급 | F32: 민수연 | G32: - | H32: 45726 | I32: 45989 | M32: 0.75 | N32: 1 | O32: 1 | P32: 1 | Q32: 1 | R32: 1 | S32: 1 | T32: 1 | U32: 1 | AI32: =SUM(L32:AH32) -> 8.75
C33: 디자인 | E33: 초급 | F33: 박성호 | G33: - | H33: 45748 | I33: 45961 | N33: 1 | O33: 1 | P33: 1 | Q33: 1 | R33: 1 | S33: 1 | T33: 1 | AI33: =SUM(L33:AH33) -> 7
C34: 디자인 | E34: 고급 | AI34: 0
C35: 디자인 | E35: 중급 | AI35: 0
C36: 디자인 | E36: 초급 | AI36: 0
C37: 디자인 | E37: 고급 | AI37: 0
C38: 디자인 | E38: 중급 | AI38: 0
C39: 디자인 | E39: 초급 | AI39: 0
C40: 디자인 | D40: 인터렉션 디자인 (Interaction 설계 및 구현) | E40: 고급 | AI40: 0
C41: 디자인 | E41: 중급 | AI41: 0
C42: 디자인 | E42: 초급 | AI42: 0
C43: 디자인 | D43: 합계 | I43: mm | L43: =SUM(L27:L42) -> 0 | M43: =SUM(M27:M42) -> 3 | N43: =SUM(N27:N42) -> 7 | O43: =SUM(O27:O42) -> 7 | P43: =SUM(P27:P42) -> 7 | Q43: =SUM(Q27:Q42) -> 7 | R43: =SUM(R27:R42) -> 7 | S43: =SUM(S27:S42) -> 7 | ... Z43: =SUM(Z27:Z42) -> 1.5 | AI43: =SUM(AI27:AI42) -> 73
...

Sheet 250411
C3: 현대백화점 New 커머스 플랫폼 구축
C4: 45758
C5: 월별 인력 투입 계획
C6: 업무구분 | D6: 역할 | E6: 계약등급 | F6: 이름 | G6: 실등급 | H6: 계약투입일 | I6: 계약철수일 | J6: 실투입일 | K6: 실철수일 | L6: M1 (2월) | M6: M2 (3월) | N6: M3 (4월) | O6: M4 (5월) | P6: M5 (6월) | Q6: M6 (7월) | R6: M7 (8월) | S6: M8 (9월) | T6: M9 (10월) | U6: M10 (11월) | V6: M11 (12월) | W6: M12 (1월) | X6: M13 (2월) | Y6: M14 (3월) | Z6: M15 (4월) | AI6: M/M계
C7: 현장관리 | D7: 기획/디자인 총괄 (바이널씨 PM) | E7: 고급 | F7: 황세진 | G7: 특급 | H7: 45691 | I7: 46127 | L7: 1 | M7: 1 | N7: 1 | O7: 1 | P7: 1 | Q7: 1 | R7: 1 | S7: 1 | T7: 1 | U7: 1 | V7: 1 | W7: 1 | X7: 1 | Y7: 1 | Z7: 0.5 | AI7: =SUM(L7:AH7) -> 14.5
C8: 기획 | D8: PL (제작가이드, 산출물 검수) | E8: 고급 | F8: 고우정 | G8: 특급 | H8: 45705 | I8: 46127 | L8: 0.5 | M8: 1 | N8: 1 | O8: 1 | P8: 1 | Q8: 1 | R8: 1 | S8: 1 | T8: 1 | U8: 1 | V8: 1 | W8: 1 | X8: 1 | Y8: 1 | Z8: 0.5 | AI8: =SUM(L8:AH8) -> 14
D9: 앱웹 Front UXUI 상세 화면설계 | E9: 고급 | F9: 우미숙 | G9: 특급 | H9: 45691 | I9: 46096 | L9: 1 | M9: 1 | N9: 1 | O9: 1 | P9: 1 | Q9: 1 | R9: 1 | S9: 1 | T9: 1 | U9: 1 | V9: 0.5 | AI9: =SUM(L9:AH9) -> 10.5
E10: 고급 | F10: 정수정 | G10: 특급 | H10: 45691 | I10: 45989 | L10: 1 | M10: 1 | N10: 1 | O10: 1 | P10: 1 | Q10: 1 | R10: 1 | S10: 1 | T10: 1 | U10: 1 | AI10: =SUM(L10:AH10) -> 10
C11: 현장관리 | E11: 고급 | F11: 유경구 | G11: 고급 | H11: 45733 | I11: 45916 | M11: 0.5 | N11: 1 | O11: 1 | P11: 1 | Q11: 1 | R11: 1 | S11: 0.5 | AI11: =SUM(L11:AH11) -> 6
C12: 현장관리 | E12: 고급 | F12: 조선자 | G12: 특급 | H12: 45748 | I12: 45961 | N12: 1 | O12: 1 | P12: 1 | Q12: 1 | R12: 1 | S12: 1 | T12: 1 | AI12: =SUM(L12:AH12) -> 7
C13: 현장관리 | E13: 고급 | F13: 안광훈 | G13: 특급 | H13: 45748 | I13: 45961 | N13: 1 | O13: 1 | P13: 1 | Q13: 1 | R13: 1 | S13: 1 | T13: 1 | AI13: =SUM(L13:AH13) -> 7
C14: 현장관리 | E14: 중급 | F14: 김강현 | G14: 고급 | H14: 45691 | I14: 45960 | L14: 1 | M14: 1 | N14: 1 | O14: 1 | P14: 1 | Q14: 1 | R14: 1 | S14: 1 | T14: 1 | AI14: =SUM(L14:AH14) -> 9
C15: 현장관리 | E15: 중급 | F15: 장익준 | G15: 고급 | H15: 45720 | I15: 46022 | M15: 1 | N15: 1 | O15: 1 | P15: 1 | Q15: 1 | R15: 1 | S15: 1 | T15: 1 | U15: 1 | V15: 1 | AI15: =SUM(L15:AH15) -> 10
C16: 현장관리 | E16: 중급 | F16: 김영근 | G16: 고급 | H16: 45720 | I16: 45900 | M16: 1 | N16: 1 | O16: 1 | P16: 1 | Q16: 1 | R16: 1 | S16: 1 | T16: 1 | U16: 1 | V16: 1 | AI16: =SUM(L16:AH16) -> 10
C17: 현장관리 | E17: 초급 | F17: 김세진 | G17: 초급 | H17: 45691 | I17: 45991 | L17: 1 | M17: 1 | N17: 1 | O17: 1 | P17: 1 | Q17: 1 | R17: 1 | S17: 1 | T17: 1 | U17: 1 | AI17: =SUM(L17:AH17) -> 10
C18: 현장관리 | E18: 초급 | F18: 이태림 | G18: 초급 | H18: 45691 | I18: 45961 | L18: 1 | M18: 1 | N18: 1 | O18: 1 | P18: 1 | Q18: 1 | R18: 1 | S18: 1 | T18: 1 | AI18: =SUM(L18:Z18) -> 9
C19: 현장관리 | AI19: =SUM(L19:Z19) -> 0
C20: 현장관리 | AI20: =SUM(L20:AH20) -> 0
C21: 현장관리 | AI21: =SUM(L21:AH21) -> 0
C22: 현장관리 | AI22: =SUM(L22:AH22) -> 0
C23: 현장관리 | AI23: =SUM(L23:AH23) -> 0
C24: 현장관리 | AI24: =SUM(L24:AH24) -> 0
C25: 현장관리 | D25: 합계 | I25: mm | L25: =SUM(L7:L24) -> 6.5 | M25: =SUM(M7:M24) -> 9.5 | N25: =SUM(N7:N24) -> 12 | O25: =SUM(O7:O24) -> 12 | P25: =SUM(P7:P24) -> 12 | Q25: =SUM(Q7:Q24) -> 12 | R25: =SUM(R7:R24) -> 12 | S25: =SUM(S7:S24) -> 11.5 | ... Z25: =SUM(Z7:Z24) -> 1 | AI25: =SUM(AI7:AI24) -> 117
C27: 디자인 | D27: PL (제작가이드, 산출물 검수) | E27: 중급 | F27: 배지효 | G27: - | H27: 45726 | I27: 46127 | M27: 0.75 | N27: 1 | O27: 1 | P27: 1 | Q27: 1 | R27: 1 | S27: 1 | T27: 1 | U27: 1 | V27: 1 | W27: 1 | X27: 1 | Y27: 1 | Z27: 0.5 | AI27: =SUM(L27:AH27) -> 13.25
D28: 앱웹 화면 UI 디자인 | E28: 중급 | F28: 윤혜림 | G28: - | H28: 45726 | I28: 46127 | M28: 0.75 | N28: 1 | O28: 1 | P28: 1 | Q28: 1 | R28: 1 | S28: 1 | T28: 1 | U28: 1 | V28: 1 | W28: 1 | X28: 1 | Y28: 1 | Z28: 0.5 | AI28: =SUM(L28:AH28) -> 13.25
E29: 중급 | F29: 박민정 | G29: 고급 | H29: 45748 | I29: 46066 | N29: 1 | O29: 1 | P29: 1 | Q29: 1 | R29: 1 | S29: 1 | T29: 1 | U29: 1 | V29: 1 | W29: 1 | X29: 0.5 | AI29: =SUM(L29:AH29) -> 10.5
C30: 디자인 | E30: 초급 | F30: 김민지 | G30: - | H30: 45726 | I30: 46127 | M30: 0.75 | N30: 1 | O30: 1 | P30: 1 | Q30: 1 | R30: 1 | S30: 1 | T30: 1 | U30: 1 | V30: 1 | W30: 1 | X30: 1 | Y30: 1 | Z30: 0.5 | AI30: =SUM(L30:AH30) -> 13.25
C31: 디자인 | E31: 초급 | F31: 이경진 | G31: - | H31: 45748 | I31: 45961 | N31: 1 | O31: 1 | P31: 1 | Q31: 1 | R31: 1 | S31: 1 | T31: 1 | AI31: =SUM(L31:AH31) -> 7
C32: 디자인 | E32: 초급 | F32: 민수연 | G32: - | H32: 45726 | I32: 45989 | M32: 0.75 | N32: 1 | O32: 1 | P32: 1 | Q32: 1 | R32: 1 | S32: 1 | T32: 1 | U32: 1 | AI32: =SUM(L32:AH32) -> 8.75
C33: 디자인 | E33: 초급 | F33: 박성호 | G33: - | H33: 45748 | I33: 45961 | N33: 1 | O33: 1 | P33: 1 | Q33: 1 | R33: 1 | S33: 1 | T33: 1 | AI33: =SUM(L33:AH33) -> 7
C34: 디자인 | E34: 고급 | AI34: 0
C35: 디자인 | E35: 중급 | AI35: 0
C36: 디자인 | E36: 초급 | AI36: 0
C37: 디자인 | E37: 고급 | AI37: 0
C38: 디자인 | E38: 중급 | AI38: 0
C39: 디자인 | E39: 초급 | AI39: 0
C40: 디자인 | D40: 인터렉션 디자인 (Interaction 설계 및 구현) | E40: 고급 | AI40: 0
C41: 디자인 | E41: 중급 | AI41: 0
C42: 디자인 | E42: 초급 | AI42: 0
C43: 디자인 | D43: 합계 | I43: mm | L43: =SUM(L27:L42) -> 0 | M43: =SUM(M27:M42) -> 3 | N43: =SUM(N27:N42) -> 7 | O43: =SUM(O27:O42) -> 7 | P43: =SUM(P27:P42) -> 7 | Q43: =SUM(Q27:Q42) -> 7 | R43: =SUM(R27:R42) -> 7 | S43: =SUM(S27:S42) -> 7 | ... Z43: =SUM(Z27:Z42) -> 1.5 | AI43: =SUM(AI27:AI42) -> 73
...

Sheet 250602
C3: 현대백화점 New 커머스 플랫폼 구축
C4: 45799
C5: 월별 인력 투입 계획
C6: 업무구분 | D6: 역할 | E6: 계약등급 | F6: 이름 | G6: 실등급 | H6: 계약투입일 | I6: 계약철수일 | J6: 실투입일 | K6: 실철수일 | L6: M1 (2월) | M6: M2 (3월) | N6: M3 (4월) | O6: M4 (5월) | P6: M5 (6월) | Q6: M6 (7월) | R6: M7 (8월) | S6: M8 (9월) | T6: M9 (10월) | U6: M10 (11월) | V6: M11 (12월) | W6: M12 (1월) | X6: M13 (2월) | Y6: M14 (3월) | Z6: M15 (4월) | AI6: M/M계
C7: 현장관리 | D7: 기획/디자인 총괄 (바이널씨 PM) | E7: 고급 | F7: 황세진 | G7: 특급 | H7: 45691 | I7: 46127 | L7: 1 | M7: 1 | N7: 1 | O7: 1 | P7: 1 | Q7: 1 | R7: 1 | S7: 1 | T7: 1 | U7: 1 | V7: 1 | W7: 1 | X7: 1 | Y7: 1 | Z7: 0.5 | AI7: =SUM(L7:AH7) -> 14.5
C8: 기획 | D8: PL (제작가이드, 산출물 검수) | E8: 고급 | F8: 고우정 | G8: 특급 | H8: 45705 | I8: 46127 | L8: 0.5 | M8: 1 | N8: 1 | O8: 1 | P8: 1 | Q8: 1 | R8: 1 | S8: 1 | T8: 1 | U8: 1 | V8: 1 | W8: 1 | X8: 1 | Y8: 1 | Z8: 0.5 | AI8: =SUM(L8:AH8) -> 14
D9: 앱웹 Front UXUI 상세 화면설계 | E9: 고급 | F9: 우미숙 | G9: 특급 | H9: 45691 | I9: 45930 | L9: 1 | M9: 1 | N9: 1 | O9: 1 | P9: 1 | Q9: 1 | R9: 1 | S9: 1 | AI9: =SUM(L9:AH9) -> 8
E10: 고급 | F10: 정수정 | G10: 특급 | H10: 45691 | I10: 45991 | L10: 1 | M10: 1 | N10: 1 | O10: 1 | P10: 1 | Q10: 1 | R10: 1 | S10: 1 | T10: 1 | U10: 1 | AI10: =SUM(L10:AH10) -> 10
C11: 현장관리 | E11: 고급 | F11: 유경구 | G11: 고급 | H11: 45733 | I11: 45916 | M11: 0.5 | N11: 1 | O11: 1 | P11: 1 | Q11: 1 | R11: 1 | S11: 0.5 | AI11: =SUM(L11:AH11) -> 6
C12: 현장관리 | E12: 고급 | F12: 박지황 | G12: 특급 | H12: 45810 | I12: 46022 | P12: 1 | Q12: 1 | R12: 1 | S12: 1 | T12: 1 | U12: 1 | V12: 1 | AI12: =SUM(L12:AH12) -> 7
C13: 현장관리 | E13: 고급 | F13: 조선자 | G13: 특급 | H13: 45748 | I13: 45961 | N13: 1 | O13: 1 | P13: 1 | Q13: 1 | R13: 1 | S13: 1 | T13: 1 | AI13: =SUM(L13:AH13) -> 7
C14: 현장관리 | E14: 고급 | F14: 안광훈 | G14: 특급 | H14: 45748 | I14: 45961 | N14: 1 | O14: 1 | P14: 1 | Q14: 1 | R14: 1 | S14: 1 | T14: 1 | AI14: =SUM(L14:AH14) -> 7
C15: 현장관리 | E15: 중급 | F15: 김강현 | G15: 고급 | H15: 45691 | I15: 45961 | L15: 1 | M15: 1 | N15: 1 | O15: 1 | P15: 1 | Q15: 1 | R15: 1 | S15: 1 | T15: 1 | AI15: =SUM(L15:AH15) -> 9
C16: 현장관리 | E16: 중급 | F16: 장익준 | G16: 고급 | H16: 45720 | I16: 46022 | M16: 1 | N16: 1 | O16: 1 | P16: 1 | Q16: 1 | R16: 1 | S16: 1 | T16: 1 | U16: 1 | V16: 1 | AI16: =SUM(L16:AH16) -> 10
C17: 현장관리 | E17: 중급 | F17: 김영근 | G17: 고급 | H17: 45720 | I17: 46022 | M17: 1 | N17: 1 | O17: 1 | P17: 1 | Q17: 1 | R17: 1 | S17: 1 | T17: 1 | U17: 1 | V17: 1 | AI17: =SUM(L17:AH17) -> 10
C18: 현장관리 | E18: 초급 | F18: 김세진 | G18: 초급 | H18: 45691 | I18: 45930 | L18: 1 | M18: 1 | N18: 1 | O18: 1 | P18: 1 | Q18: 1 | R18: 1 | S18: 1 | AI18: =SUM(L18:AH18) -> 8
C19: 현장관리 | E19: 초급 | F19: 이태림 | G19: 초급 | H19: 45691 | I19: 45930 | L19: 1 | M19: 1 | N19: 1 | O19: 1 | P19: 1 | Q19: 1 | R19: 1 | S19: 1 | AI19: =SUM(L19:Z19) -> 8
C20: 현장관리 | AI20: =SUM(L20:Z20) -> 0
C21: 현장관리 | AI21: =SUM(L21:AH21) -> 0
C22: 현장관리 | AI22: =SUM(L22:AH22) -> 0
C23: 현장관리 | AI23: =SUM(L23:AH23) -> 0
C24: 현장관리 | AI24: =SUM(L24:AH24) -> 0
C25: 현장관리 | AI25: =SUM(L25:AH25) -> 0
C26: 현장관리 | D26: 합계 | I26: mm | L26: =SUM(L7:L25) -> 6.5 | M26: =SUM(M7:M25) -> 9.5 | N26: =SUM(N7:N25) -> 12 | O26: =SUM(O7:O25) -> 12 | P26: =SUM(P7:P25) -> 13 | Q26: =SUM(Q7:Q25) -> 13 | R26: =SUM(R7:R25) -> 13 | S26: =SUM(S7:S25) -> 12.5 | ... Z26: =SUM(Z7:Z25) -> 1 | AI26: =SUM(AI7:AI25) -> 118.5
C28: 디자인 | D28: PL (제작가이드, 산출물 검수) | E28: 중급 | F28: 배지효 | G28: - | H28: 45726 | I28: 46127 | M28: 0.75 | N28: 1 | O28: 1 | P28: 1 | Q28: 1 | R28: 1 | S28: 1 | T28: 1 | U28: 1 | V28: 1 | W28: 1 | X28: 1 | Y28: 1 | Z28: 0.5 | AI28: =SUM(L28:AH28) -> 13.25
D29: 앱웹 화면 UI 디자인 | E29: 중급 | F29: 윤혜림 | G29: - | H29: 45726 | I29: 46127 | M29: 0.75 | N29: 1 | O29: 1 | P29: 1 | Q29: 1 | R29: 1 | S29: 1 | T29: 1 | U29: 1 | V29: 1 | W29: 1 | X29: 1 | Y29: 1 | Z29: 0.5 | AI29: =SUM(L29:AH29) -> 13.25
E30: 중급 | F30: 박민정 | G30: 고급 | H30: 45748 | I30: 45991 | N30: 1 | O30: 1 | P30: 1 | Q30: 1 | R30: 1 | S30: 1 | T30: 1 | U30: 1 | AI30: =SUM(L30:AH30) -> 8
C31: 디자인 | E31: 초급 | F31: 김원경 | G31: - | H31: 45810 | I31: 45915 | P31: 1 | Q31: 1 | R31: 1 | S31: 1 | AI31: =SUM(L31:AH31) -> 4
C32: 디자인 | E32: 초급 | F32: 김단비 | G32: - | H32: 45810 | I32: 45915 | P32: 1 | Q32: 1 | R32: 1 | S32: 1 | AI32: =SUM(L32:AH32) -> 4
C33: 디자인 | E33: 초급 | F33: 김민지 | G33: - | H33: 45726 | I33: 45731 | M33: 0.75 | N33: 1 | O33: 1 | P33: 1 | Q33: 1 | R33: 1 | S33: 1 | T33: 1 | U33: 1 | V33: 1 | W33: 1 | X33: 1 | Y33: 0.5 | AI33: =SUM(L33:AH33) -> 12.25
C34: 디자인 | E34: 초급 | F34: 이경진 | G34: - | H34: 45748 | I34: 45961 | N34: 1 | O34: 1 | P34: 1 | Q34: 1 | R34: 1 | S34: 1 | T34: 1 | AI34: =SUM(L34:AH34) -> 7
C35: 디자인 | E35: 초급 | F35: 민수연 | G35: - | H35: 45726 | I35: 45989 | M35: 0.75 | N35: 1 | O35: 1 | P35: 1 | Q35: 1 | R35: 1 | S35: 1 | T35: 1 | U35: 1 | AI35: =SUM(L35:AH35) -> 8.75
C36: 디자인 | E36: 초급 | F36: 박성호 | G36: - | H36: 45748 | I36: 45961 | N36: 1 | O36: 1 | P36: 1 | Q36: 1 | R36: 1 | S36: 1 | T36: 1 | AI36: =SUM(L36:AH36) -> 7
C37: 디자인 | E37: 고급 | AI37: 0
C38: 디자인 | E38: 중급 | AI38: 0
C39: 디자인 | E39: 초급 | AI39: 0
C40: 디자인 | E40: 고급 | AI40: 0
C41: 디자인 | E41: 중급 | AI41: 0
C42: 디자인 | E42: 초급 | AI42: 0
C43: 디자인 | D43: 인터렉션 디자인 (Interaction 설계 및 구현) | E43: 고급 | AI43: 0
...

Sheet 250704(기본)
C3: 현대백화점 New 커머스 플랫폼 구축
C4: 45842
C5: 월별 인력 투입 계획
C6: 업무구분 | D6: 역할 | E6: 계약등급 | F6: 이름 | G6: 실등급 | H6: 계약투입일 | I6: 계약철수일 | J6: 실투입일 | K6: 실철수일 | L6: M1 (2월) | M6: M2 (3월) | N6: M3 (4월) | O6: M4 (5월) | P6: M5 (6월) | Q6: M6 (7월) | R6: M7 (8월) | S6: M8 (9월) | T6: M9 (10월) | U6: M10 (11월) | V6: M11 (12월) | W6: M12 (1월) | X6: M13 (2월) | Y6: M14 (3월) | Z6: M15 (4월) | AI6: M/M계
C7: 현장관리 | D7: 기획/디자인 총괄 (바이널씨 PM) | E7: 고급 | F7: 황세진 | G7: 특급 | H7: 45691 | I7: 45838 | L7: 1 | M7: 1 | N7: 1 | O7: 1 | P7: 0.75 | AI7: =SUM(L7:AH7) -> 4.75
D8: 기획/디자인 총괄 (바이널씨 PM) | E8: 고급 | F8: 고우정 | G8: 특급 | H8: 45705 | I8: 46127 | L8: 0.5 | M8: 1 | N8: 1 | O8: 1 | P8: 1 | Q8: 1 | R8: 1 | S8: 1 | T8: 1 | U8: 1 | V8: 1 | W8: 1 | X8: 1 | Y8: 1 | Z8: 0.5 | AI8: =SUM(L8:AH8) -> 14
C9: 기획 | D9: PL (제작가이드, 산출물 검수) | E9: 고급 | F9: 유경구 | G9: 고급 | H9: 45733 | I9: 46127 | M9: 0.5 | N9: 1 | O9: 1 | P9: 1 | Q9: 1 | R9: 1 | S9: 1 | T9: 1 | U9: 1 | V9: 1 | W9: 1 | X9: 1 | Y9: 1 | AI9: =SUM(L9:AH9) -> 12.5
C10: 현장관리 | D10: PL (제작가이드, 산출물 검수) | E10: 고급 | F10: 조선자 | G10: 특급 | H10: 45748 | I10: 46127 | N10: 1 | O10: 1 | P10: 1 | Q10: 1 | R10: 1 | S10: 1 | T10: 1 | U10: 1 | V10: 1 | W10: 1 | X10: 1 | Y10: 1 | AI10: =SUM(L10:AH10) -> 12
D11: 앱웹 Front UXUI 상세 화면설계 | E11: 고급 | F11: 정수정 | G11: 특급 | H11: 45691 | I11: 45991 | L11: 1 | M11: 1 | N11: 1 | O11: 1 | P11: 1 | Q11: 1 | R11: 1 | S11: 1 | T11: 1 | U11: 1 | AI11: =SUM(L11:AH11) -> 10
E12: 고급 | F12: 우미숙 | G12: 특급 | H12: 45691 | I12: 45930 | L12: 1 | M12: 1 | N12: 1 | O12: 1 | P12: 1 | Q12: 1 | R12: 1 | S12: 1 | AI12: =SUM(L12:AH12) -> 8
C13: 현장관리 | E13: 고급 | F13: 박지황 | G13: 특급 | H13: 45810 | I13: 45813 | P13: 0.2 | AI13: =SUM(L13:AH13) -> 0.2
C14: 현장관리 | E14: 고급 | F14: 유지현 | G14: 고급 | H14: 45824 | I14: 45900 | P14: 0.5 | Q14: 1 | R14: 1 | AI14: =SUM(L14:AH14) -> 2.5
C15: 현장관리 | E15: 고급 | F15: 유승용 | G15: 고급 | H15: 45824 | I15: 45900 | P15: 0.5 | Q15: 1 | R15: 1 | AI15: =SUM(L15:AH15) -> 2.5
C16: 현장관리 | E16: 고급 | F16: 안광훈 | G16: 특급 | H16: 45748 | I16: 45961 | N16: 1 | O16: 1 | P16: 1 | Q16: 1 | R16: 1 | S16: 1 | T16: 1 | AI16: =SUM(L16:AH16) -> 7
C17: 현장관리 | E17: 중급 | F17: 김강현 | G17: 고급 | H17: 45691 | I17: 45961 | L17: 1 | M17: 1 | N17: 1 | O17: 1 | P17: 1 | Q17: 1 | R17: 1 | S17: 1 | T17: 1 | AI17: =SUM(L17:AH17) -> 9
C18: 현장관리 | E18: 중급 | F18: 장익준 | G18: 고급 | H18: 45720 | I18: 46022 | M18: 1 | N18: 1 | O18: 1 | P18: 1 | Q18: 1 | R18: 1 | S18: 1 | T18: 1 | U18: 1 | V18: 1 | AI18: =SUM(L18:AH18) -> 10
C19: 현장관리 | E19: 중급 | F19: 김영근 | G19: 고급 | H19: 45720 | I19: 46022 | M19: 1 | N19: 1 | O19: 1 | P19: 1 | Q19: 1 | R19: 1 | S19: 1 | T19: 1 | U19: 1 | V19: 1 | AI19: =SUM(L19:AH19) -> 10
C20: 현장관리 | E20: 초급 | F20: 김세진 | G20: 초급 | H20: 45691 | I20: 45930 | L20: 1 | M20: 1 | N20: 1 | O20: 1 | P20: 1 | Q20: 1 | R20: 1 | S20: 1 | AI20: =SUM(L20:AH20) -> 8
C21: 현장관리 | E21: 초급 | F21: 이태림 | G21: 초급 | H21: 45691 | I21: 45930 | L21: 1 | M21: 1 | N21: 1 | O21: 1 | P21: 1 | Q21: 1 | R21: 1 | S21: 1 | AI21: =SUM(L21:Z21) -> 8
C22: 현장관리 | AI22: =SUM(L22:Z22) -> 0
C23: 현장관리 | AI23: =SUM(L23:AH23) -> 0
C24: 현장관리 | AI24: =SUM(L24:AH24) -> 0
C25: 현장관리 | AI25: =SUM(L25:AH25) -> 0
C26: 현장관리 | AI26: =SUM(L26:AH26) -> 0
C27: 현장관리 | AI27: =SUM(L27:AH27) -> 0
C28: 현장관리 | D28: 합계 | I28: mm | L28: =SUM(L7:L27) -> 6.5 | M28: =SUM(M7:M27) -> 9.5 | N28: =SUM(N7:N27) -> 12 | O28: =SUM(O7:O27) -> 12 | P28: =SUM(P7:P27) -> 12.95 | Q28: =SUM(Q7:Q27) -> 13 | R28: =SUM(R7:R27) -> 13 | S28: =SUM(S7:S27) -> 11 | ... Z28: =SUM(Z7:Z27) -> 0.5 | AI28: =SUM(AI7:AI27) -> 118.45
S29: ㅗ
C30: 디자인 | D30: PL (제작가이드, 산출물 검수) | E30: 중급 | F30: 배지효 | G30: - | H30: 45726 | I30: 46127 | M30: 0.75 | N30: 1 | O30: 1 | P30: 1 | Q30: 1 | R30: 1 | S30: 1 | T30: 1 | U30: 1 | V30: 1 | W30: 1 | X30: 1 | Y30: 1 | Z30: 0.5 | AI30: =SUM(L30:AH30) -> 13.25
D31: 앱웹 화면 UI 디자인 | E31: 중급 | F31: 윤혜림 | G31: - | H31: 45726 | I31: 46127 | M31: 0.75 | N31: 1 | O31: 1 | P31: 1 | Q31: 1 | R31: 1 | S31: 1 | T31: 1 | U31: 1 | V31: 1 | W31: 1 | X31: 1 | Y31: 1 | Z31: 0.5 | AI31: =SUM(L31:AH31) -> 13.25
E32: 중급 | F32: 박민정 | G32: 고급 | H32: 45748 | I32: 45991 | N32: 1 | O32: 1 | P32: 1 | Q32: 1 | R32: 1 | S32: 1 | T32: 1 | U32: 1 | AI32: =SUM(L32:AH32) -> 8
C33: 디자인 | E33: 초급 | F33: 김원경 | G33: - | H33: 45810 | I33: 45915 | P33: 1 | Q33: 1 | R33: 1 | S33: 1 | AI33: =SUM(L33:AH33) -> 4
C34: 디자인 | E34: 초급 | F34: 김단비 | G34: - | H34: 45810 | I34: 45915 | P34: 1 | Q34: 1 | R34: 1 | S34: 1 | AI34: =SUM(L34:AH34) -> 4
C35: 디자인 | E35: 초급 | F35: 김민지 | G35: - | H35: 45726 | I35: 45731 | M35: 0.75 | N35: 1 | O35: 1 | P35: 1 | Q35: 1 | R35: 1 | S35: 1 | T35: 1 | U35: 1 | V35: 1 | W35: 1 | X35: 1 | Y35: 0.5 | AI35: =SUM(L35:AH35) -> 12.25
C36: 디자인 | E36: 초급 | F36: 이경진 | G36: - | H36: 45748 | I36: 45961 | N36: 1 | O36: 1 | P36: 1 | Q36: 1 | R36: 1 | S36: 1 | T36: 1 | AI36: =SUM(L36:AH36) -> 7
C37: 디자인 | E37: 초급 | F37: 민수연 | G37: - | H37: 45726 | I37: 45989 | M37: 0.75 | N37: 1 | O37: 1 | P37: 1 | Q37: 1 | R37: 1 | S37: 1 | T37: 1 | U37: 1 | AI37: =SUM(L37:AH37) -> 8.75
C38: 디자인 | E38: 초급 | F38: 박성호 | G38: - | H38: 45748 | I38: 45961 | N38: 1 | O38: 1 | P38: 1 | Q38: 1 | R38: 1 | S38: 1 | T38: 1 | AI38: =SUM(L38:AH38) -> 7
C39: 디자인 | E39: 고급 | AI39: 0
C40: 디자인 | E40: 중급 | AI40: 0
C41: 디자인 | E41: 초급 | AI41: 0
C42: 디자인 | E42: 고급 | AI42: 0
...

Sheet 250710(기획 실질 - 디자인 2번방향)
C3: 현대백화점 New 커머스 플랫폼 구축
C4: 45842
C5: 월별 인력 투입 계획
C6: 업무구분 | D6: 역할 | E6: 계약등급 | F6: 이름 | G6: 실등급 | H6: 계약투입일 | I6: 계약철수일 | J6: 실투입일 | K6: 실철수일 | L6: M1 (2월) | M6: M2 (3월) | N6: M3 (4월) | O6: M4 (5월) | P6: M5 (6월) | Q6: M6 (7월) | R6: M7 (8월) | S6: M8 (9월) | T6: M9 (10월) | U6: M10 (11월) | V6: M11 (12월) | W6: M12 (1월) | X6: M13 (2월) | Y6: M14 (3월) | Z6: M15 (4월) | AI6: M/M계
C7: 현장관리 | D7: 기획/디자인 총괄 (바이널씨 PM) | E7: 고급 | F7: 황세진 | G7: 특급 | H7: 45691 | I7: 45838 | L7: 1 | M7: 1 | N7: 1 | O7: 1 | P7: 0.75 | AI7: =SUM(L7:AH7) -> 4.75 | AM7: 1. 기간별 TASK
D8: 기획/디자인 총괄 (바이널씨 PM) | E8: 고급 | F8: 고우정 | G8: 특급 | H8: 45705 | I8: 46127 | L8: 0.5 | M8: 1 | N8: 1 | O8: 1 | P8: 1 | Q8: 1 | R8: 1 | S8: 1 | T8: 1 | U8: 1 | V8: 1 | W8: 1 | X8: 1 | Y8: 1 | Z8: 0.5 | AI8: =SUM(L8:AH8) -> 14 | AM8: 8월 - 9월 | AN8: 단위테스트케이스 산출물 관리 / 테스트 시행 | AO8: 추가요건에 대한 설계
C9: 기획 | D9: PL (제작가이드, 산출물 검수) | E9: 고급 | F9: 유경구 | G9: 고급 | H9: 45733 | I9: 46127 | M9: 0.5 | N9: 1 | O9: 1 | P9: 1 | Q9: 1 | R9: 1 | S9: 1 | T9: 1 | U9: 1 | V9: 1 | W9: 1 | X9: 1 | Y9: 1 | AI9: =SUM(L9:AH9) -> 12.5 | AN9: 산출물(설계) 품질관리 및 현행화
C10: 현장관리 | D10: PL (제작가이드, 산출물 검수) | E10: 고급 | F10: 조선자 | G10: 특급 | H10: 45748 | I10: 46127 | N10: 1 | O10: 1 | P10: 1 | Q10: 1 | R10: 1 | S10: 1 | T10: 1 | U10: 1 | V10: 1 | W10: 1 | X10: 1 | Y10: 1 | AI10: =SUM(L10:AH10) -> 12 | AN10: 요구사항 추적표 관리
D11: 앱웹 Front UXUI 상세 화면설계 | E11: 고급 | F11: 정수정 | G11: 특급 | H11: 45691 | I11: 45991 | L11: 1 | M11: 1 | N11: 1 | O11: 1 | P11: 1 | Q11: 1 | R11: 1 | S11: 1 | T11: 1 | U11: 1 | AI11: =SUM(L11:AH11) -> 10 | AN11: 메뉴구조도 관리
E12: 고급 | F12: 우미숙 | G12: 특급 | H12: 45691 | I12: 45930 | L12: 1 | M12: 1 | N12: 1 | O12: 1 | P12: 1 | Q12: 1 | R12: 1 | AI12: =SUM(L12:AH12) -> 7 | AM12: 10월 ~ 12월 | AN12: 산출물(설계) 품질관리 및 현행화
C13: 현장관리 | E13: 고급 | F13: 박지황 | G13: 특급 | H13: 45810 | I13: 45813 | P13: 0.25 | AI13: =SUM(L13:AH13) -> 0.25 | AN13: 요구사항 추적표 관리
C14: 현장관리 | E14: 고급 | F14: 유지현 | G14: 고급 | H14: 45824 | I14: 45900 | P14: 0.5 | Q14: 1 | R14: 1 | AI14: =SUM(L14:AH14) -> 2.5 | AM14: 1월 ~ 3월 | AN14: 통합테스트 (개발대응)
C15: 현장관리 | E15: 고급 | F15: 유승용 | G15: 고급 | H15: 45824 | I15: 45900 | P15: 0.5 | Q15: 1 | R15: 1 | S15: 1 | T15: 1 | U15: 1 | V15: 1 | AI15: =SUM(L15:AH15) -> 6.5 | AN15: 산출물(설계) 품질관리 및 현행화
C16: 현장관리 | E16: 고급 | F16: 안광훈 | G16: 특급 | H16: 45748 | I16: 45961 | N16: 1 | O16: 1 | P16: 1 | Q16: 1 | R16: 1 | S16: 1 | T16: 1 | U16: 1 | V16: 1 | AI16: =SUM(L16:AH16) -> 9
C17: 현장관리 | E17: 중급 | F17: 김강현 | G17: 고급 | H17: 45691 | I17: 45961 | L17: 1 | M17: 1 | N17: 1 | O17: 1 | P17: 1 | Q17: 1 | R17: 1 | S17: 1 | AI17: =SUM(L17:AH17) -> 8
C18: 현장관리 | E18: 중급 | F18: 장익준 | G18: 고급 | H18: 45720 | I18: 46022 | M18: 1 | N18: 1 | O18: 1 | P18: 1 | Q18: 1 | R18: 1 | AI18: =SUM(L18:AH18) -> 6
C19: 현장관리 | E19: 중급 | F19: 김영근 | G19: 고급 | H19: 45720 | I19: 46022 | M19: 1 | N19: 1 | O19: 1 | P19: 1 | Q19: 1 | R19: 1 | S19: 1 | T19: 1 | U19: 1 | V19: 1 | AI19: =SUM(L19:AH19) -> 10
C20: 현장관리 | E20: 초급 | F20: 김세진 | G20: 초급 | H20: 45691 | I20: 45930 | L20: 1 | M20: 1 | N20: 1 | O20: 1 | P20: 1 | Q20: 1 | R20: 1 | S20: 1 | AI20: =SUM(L20:AH20) -> 8
C21: 현장관리 | E21: 초급 | F21: 이태림 | G21: 초급 | H21: 45691 | I21: 45930 | L21: 1 | M21: 1 | N21: 1 | O21: 1 | P21: 1 | Q21: 1 | R21: 1 | S21: 1 | T21: 1 | U21: 1 | V21: 1 | AI21: =SUM(L21:Z21) -> 11
C22: 현장관리 | AI22: =SUM(L22:Z22) -> 0
C23: 현장관리 | AI23: =SUM(L23:AH23) -> 0
C24: 현장관리 | AI24: =SUM(L24:AH24) -> 0
C25: 현장관리 | AI25: =SUM(L25:AH25) -> 0
C26: 현장관리 | AI26: =SUM(L26:AH26) -> 0
C27: 현장관리 | AI27: =SUM(L27:AH27) -> 0
C28: 현장관리 | D28: 합계 | I28: mm | L28: =SUM(L7:L27) -> 6.5 | M28: =SUM(M7:M27) -> 9.5 | N28: =SUM(N7:N27) -> 12 | O28: =SUM(O7:O27) -> 12 | P28: =SUM(P7:P27) -> 13 | Q28: =SUM(Q7:Q27) -> 13 | R28: =SUM(R7:R27) -> 13 | S28: =SUM(S7:S27) -> 10 | ... Z28: =SUM(Z7:Z27) -> 0.5 | AI28: =SUM(AI7:AI27) -> 121.5
C30: 디자인 | D30: PL (제작가이드, 산출물 검수) | E30: 중급 | F30: 배지효 | G30: - | H30: 45726 | I30: 46127 | M30: 0.75 | N30: 1 | O30: 1 | P30: 1 | Q30: 1 | R30: 1 | S30: 1 | T30: 1 | U30: 1 | V30: 1 | W30: 1 | X30: 1 | Y30: 1 | Z30: 0.5 | AI30: =SUM(L30:AH30) -> 13.25
D31: 앱웹 화면 UI 디자인 | E31: 중급 | F31: 윤혜림 | G31: - | H31: 45726 | I31: 46127 | M31: 0.75 | N31: 1 | O31: 1 | P31: 1 | Q31: 1 | R31: 1 | S31: 1 | T31: 1 | U31: 1 | V31: 1 | W31: 1 | X31: 1 | Y31: 1 | Z31: 0.5 | AI31: =SUM(L31:AH31) -> 13.25 | AM31: 2. 각 파트별 작업 영역
E32: 중급 | F32: 박민정 | G32: 고급 | H32: 45748 | N32: 1 | O32: 1 | P32: 1 | Q32: 1 | R32: 0.25 | AI32: =SUM(L32:AH32) -> 4.25 | AM32: 조선자 | AN32: 로그인, 회원, 상품, 주문, 마이페이지 관리
C33: 디자인 | E33: 중급 | F33: TBD | G33: 초급 | R33: 0.75 | S33: 1 | AI33: =SUM(L33:AH33) -> 1.75 | AM33: 정수정 | AN33: 장바구니, 주문서, 주문완료
C34: 디자인 | E34: 초급 | F34: 김원경 | G34: - | H34: 45810 | I34: 45991 | P34: 1 | Q34: 1 | R34: 1 | S34: 1 | T34: 1 | U34: 1 | AI34: =SUM(L34:AH34) -> 6 | AM34: 김영근 | AN34: 구독, 마이페이지(주문관리)
C35: 디자인 | E35: 초급 | F35: 김단비 | G35: - | H35: 45810 | I35: 45991 | P35: 1 | Q35: 1 | R35: 1 | S35: 1 | T35: 1 | U35: 1 | AI35: =SUM(L35:AH35) -> 6 | AM35: 안광훈 | AN35: 프로모션, 이벤트, 마이페이지(나의활동, 나의혜택)
C36: 디자인 | E36: 초급 | F36: 김민지 | G36: - | H36: 45726 | M36: 0.75 | N36: 1 | O36: 1 | P36: 1 | Q36: 1 | R36: 0.25 | AI36: =SUM(L36:AH36) -> 5 | AM36: (김강현) | AN36: 로그인, 회원가입, 마이페이지(나의정보)
C37: 디자인 | E37: 초급 | F37: TBD | G37: - | I37: 45930 | R37: 0.75 | S37: 1 | AI37: =SUM(L37:AH37) -> 1.75 | AM37: (장익준) | AN37: 상품 (유형, 무형)
C38: 디자인 | E38: 초급 | F38: 이경진 | G38: - | H38: 45748 | I38: 45961 | N38: 1 | O38: 1 | P38: 1 | Q38: 1 | R38: 1 | S38: 1 | T38: 1 | AI38: =SUM(L38:AH38) -> 7 | AM38: 유경구 | AN38: 모듈, 피드/샵메인, 전문관, 브랜드관, 콘텐츠, 신규기능(미스페이스, 잼/마이컬렉션) 고객센터, 공통
C39: 디자인 | E39: 초급 | F39: 민수연 | G39: - | H39: 45726 | I39: 46094 | M39: 0.75 | N39: 1 | O39: 1 | P39: 1 | Q39: 1 | R39: 1 | S39: 1 | T39: 1 | U39: 1 | V39: 1 | W39: 1 | X39: 1 | Y39: 0.5 | AI39: =SUM(L39:AH39) -> 12.25 | AM39: 김세진 | AN39: 모듈, 브랜드관, 콘텐츠
C40: 디자인 | E40: 초급 | F40: 박성호 | G40: - | H40: 45748 | I40: 45961 | N40: 1 | O40: 1 | P40: 1 | Q40: 1 | R40: 1 | S40: 1 | T40: 1 | AI40: =SUM(L40:AH40) -> 7 | AM40: 이태림 | AN40: 신규기능(미스페이스, 잼/마이컬렉션), 고객센터, 공통, 전문관
C41: 디자인 | E41: 고급 | AI41: 0
C42: 디자인 | E42: 중급 | AI42: 0
C43: 디자인 | E43: 초급 | AI43: 0
...
