Workbook

Sheet 견적대비실투입(월별)
B2: 협력사 | C2: 25.2월 | G2: 25.3월 | K2: 25.4월 | O2: 25.5월 | S2: 25.6월 | W2: 25.7월 | AA2: 25.8월 | AE2: 25.9월 | AI2: 25.10월 | AM2: 25.11월 | AQ2: 25.12월 | AU2: 26.01월 | AY2: 26.02월 | BC2: 26.03월 | BG2: 26.04월
C3: 견적 | D3: 실투입 | E3: 차이 | G3: 견적 | H3: 실투입 | I3: 차이 | K3: 견적 | L3: 실투입 | M3: 차이 | O3: 견적 | P3: 실투입 | Q3: 차이 | S3: 견적 | T3: 실투입 | U3: 차이 | W3: 견적 | X3: 실투입 | Y3: 차이 | AA3: 견적 | AB3: 실투입 | AC3: 차이 | AE3: 견적 | AF3: 실투입 | AG3: 차이 | AI3: 견적 | AJ3: 실투입 | AK3: 차이 | AM3: 견적 | AN3: 실투입 | AO3: 차이 | AQ3: 견적 | AR3: 실투입 | AS3: 차이 | AU3: 견적 | AV3: 실투입 | AW3: 차이 | AY3: 견적 | AZ3: 실투입 | BA3: 차이 | BC3: 견적 | BD3: 실투입 | BE3: 차이 | BG3: 견적 | BH3: 실투입 | BI3: 차이
B4: kt ds | C4: =견적기준통합!M4 -> 16 | D4: =협력사등급별MM!M5 -> 13.75 | E4: =D4-C4 -> -2.25 | G4: =견적기준통합!N4 -> 16.5 | H4: =협력사등급별MM!O5 -> 16.5 | I4: =H4-G4 -> 0 | K4: =견적기준통합!O4 -> 20 | L4: =협력사등급별MM!Q5 -> 17.5 | M4: =L4-K4 -> -2.5 | O4: =견적기준통합!P4 -> 21 | P4: =협력사등급별MM!S5 -> 16.7 | Q4: =P4-O4 -> -4.3 | S4: =견적기준통합!Q4 -> 23 | T4: =협력사등급별MM!U5 -> 18 | U4: =T4-S4 -> -5 | W4: =견적기준통합!R4 -> 24 | X4: =협력사등급별MM!W5 -> 23 | Y4: =X4-W4 -> -1 | AA4: =견적기준통합!S4 -> 23 | AB4: =협력사등급별MM!Y5 -> 25.5 | AC4: =AB4-AA4 -> 2.5 | AE4: =견적기준통합!T4 -> 24 | AF4: =협력사등급별MM!AA5 -> 24.5 | AG4: =AF4-AE4 -> 0.5 | AI4: =견적기준통합!U4 -> 26 | AJ4: =협력사등급별MM!AC5 -> 26 | AK4: =AJ4-AI4 -> 0 | AM4: =견적기준통합!V4 -> 27.5 | AN4: =협력사등급별MM!AE5 -> 30 | AO4: =AN4-AM4 -> 2.5 | AQ4: =견적기준통합!W4 -> 26.5 | AR4: =협력사등급별MM!AG5 -> 29.5 | AS4: =AR4-AQ4 -> 3 | AU4: =견적기준통합!X4 -> 24.5 | AV4: =협력사등급별MM!AI5 -> 27.5 | AW4: =AV4-AU4 -> 3 | AY4: =견적기준통합!Y4 -> 20 | AZ4: =협력사등급별MM!AK5 -> 21.2 | BA4: =AZ4-AY4 -> 1.2 | BC4: =견적기준통합!Z4 -> 15 | BD4: =협력사등급별MM!AM5 -> 18 | BE4: =BD4-BC4 -> 3 | BG4: =견적기준통합!AA4 -> 8 | BH4: =협력사등급별MM!AO5 -> 11.8 | BI4: =BH4-BG4 -> 3.8
B5: SGSecurity | C5: =견적기준통합!M5 -> 0 | D5: =협력사등급별MM!M6 -> 0 | E5: =D5-C5 -> 0 | G5: =견적기준통합!N5 -> 0 | H5: =협력사등급별MM!O6 -> 0.5 | I5: =H5-G5 -> 0.5 | K5: =견적기준통합!O5 -> 1 | L5: =협력사등급별MM!Q6 -> 0.5 | M5: =L5-K5 -> -0.5 | O5: =견적기준통합!P5 -> 1 | P5: =협력사등급별MM!S6 -> 0.75 | Q5: =P5-O5 -> -0.25 | S5: =견적기준통합!Q5 -> 0 | T5: =협력사등급별MM!U6 -> 0.5 | U5: =T5-S5 -> 0.5 | W5: =견적기준통합!R5 -> 0 | X5: =협력사등급별MM!W6 -> 0 | Y5: =X5-W5 -> 0 | AA5: =견적기준통합!S5 -> 0 | AB5: =협력사등급별MM!Y6 -> 0 | AC5: =AB5-AA5 -> 0 | AE5: =견적기준통합!T5 -> 0 | AF5: =협력사등급별MM!AA6 -> 0.75 | AG5: =AF5-AE5 -> 0.75 | AI5: =견적기준통합!U5 -> 0 | AJ5: =협력사등급별MM!AC6 -> 0 | AK5: =AJ5-AI5 -> 0 | AM5: =견적기준통합!V5 -> 0.5 | AN5: =협력사등급별MM!AE6 -> 1.75 | AO5: =AN5-AM5 -> 1.25 | AQ5: =견적기준통합!W5 -> 2 | AR5: =협력사등급별MM!AG6 -> 2.5 | AS5: =AR5-AQ5 -> 0.5 | AU5: =견적기준통합!X5 -> 2 | AV5: =협력사등급별MM!AI6 -> 0 | AW5: =AV5-AU5 -> -2 | AY5: =견적기준통합!Y5 -> 0.75 | AZ5: =협력사등급별MM!AK6 -> 0 | BA5: =AZ5-AY5 -> -0.75 | BC5: =견적기준통합!Z5 -> 0 | BD5: =협력사등급별MM!AM6 -> 0 | BE5: =BD5-BC5 -> 0 | BG5: =견적기준통합!AA5 -> 0 | BH5: =협력사등급별MM!AO6 -> 0 | BI5: =BH5-BG5 -> 0
B6: 비플컨설팅 | C6: =견적기준통합!M6 -> 0 | D6: =협력사등급별MM!M7 -> 0 | E6: =D6-C6 -> 0 | G6: =견적기준통합!N6 -> 0 | H6: =협력사등급별MM!O7 -> 0 | I6: =H6-G6 -> 0 | K6: =견적기준통합!O6 -> 0 | L6: =협력사등급별MM!Q7 -> 0 | M6: =L6-K6 -> 0 | O6: =견적기준통합!P6 -> 2 | P6: =협력사등급별MM!S7 -> 1.25 | Q6: =P6-O6 -> -0.75 | S6: =견적기준통합!Q6 -> 6.5 | T6: =협력사등급별MM!U7 -> 5 | U6: =T6-S6 -> -1.5 | W6: =견적기준통합!R6 -> 7 | X6: =협력사등급별MM!W7 -> 7 | Y6: =X6-W6 -> 0 | AA6: =견적기준통합!S6 -> 7 | AB6: =협력사등급별MM!Y7 -> 7 | AC6: =AB6-AA6 -> 0 | AE6: =견적기준통합!T6 -> 7 | AF6: =협력사등급별MM!AA7 -> 7 | AG6: =AF6-AE6 -> 0 | AI6: =견적기준통합!U6 -> 7.5 | AJ6: =협력사등급별MM!AC7 -> 7.5 | AK6: =AJ6-AI6 -> 0 | AM6: =견적기준통합!V6 -> 7.5 | AN6: =협력사등급별MM!AE7 -> 8 | AO6: =AN6-AM6 -> 0.5 | AQ6: =견적기준통합!W6 -> 7 | AR6: =협력사등급별MM!AG7 -> 7.5 | AS6: =AR6-AQ6 -> 0.5 | AU6: =견적기준통합!X6 -> 7 | AV6: =협력사등급별MM!AI7 -> 7 | AW6: =AV6-AU6 -> 0 | AY6: =견적기준통합!Y6 -> 7 | AZ6: =협력사등급별MM!AK7 -> 7 | BA6: =AZ6-AY6 -> 0 | BC6: =견적기준통합!Z6 -> 4 | BD6: =협력사등급별MM!AM7 -> 4.5 | BE6: =BD6-BC6 -> 0.5 | BG6: =견적기준통합!AA6 -> 0 | BH6: =협력사등급별MM!AO7 -> 1.25 | BI6: =BH6-BG6 -> 1.25
B7: 이너웨이브 | C7: =견적기준통합!M7 -> 2 | D7: =협력사등급별MM!M8 -> 2 | E7: =D7-C7 -> 0 | G7: =견적기준통합!N7 -> 4 | H7: =협력사등급별MM!O8 -> 2 | I7: =H7-G7 -> -2 | K7: =견적기준통합!O7 -> 5 | L7: =협력사등급별MM!Q8 -> 5 | M7: =L7-K7 -> 0 | O7: =견적기준통합!P7 -> 5 | P7: =협력사등급별MM!S8 -> 5 | Q7: =P7-O7 -> 0 | S7: =견적기준통합!Q7 -> 4 | T7: =협력사등급별MM!U8 -> 5 | U7: =T7-S7 -> 1 | W7: =견적기준통합!R7 -> 5 | X7: =협력사등급별MM!W8 -> 5 | Y7: =X7-W7 -> 0 | AA7: =견적기준통합!S7 -> 4 | AB7: =협력사등급별MM!Y8 -> 4 | AC7: =AB7-AA7 -> 0 | AE7: =견적기준통합!T7 -> 3 | AF7: =협력사등급별MM!AA8 -> 3 | AG7: =AF7-AE7 -> 0 | AI7: =견적기준통합!U7 -> 3 | AJ7: =협력사등급별MM!AC8 -> 3 | AK7: =AJ7-AI7 -> 0 | AM7: =견적기준통합!V7 -> 2 | AN7: =협력사등급별MM!AE8 -> 3 | AO7: =AN7-AM7 -> 1 | AQ7: =견적기준통합!W7 -> 2 | AR7: =협력사등급별MM!AG8 -> 2 | AS7: =AR7-AQ7 -> 0 | AU7: =견적기준통합!X7 -> 2 | AV7: =협력사등급별MM!AI8 -> 2 | AW7: =AV7-AU7 -> 0 | AY7: =견적기준통합!Y7 -> 2 | AZ7: =협력사등급별MM!AK8 -> 2 | BA7: =AZ7-AY7 -> 0 | BC7: =견적기준통합!Z7 -> 2 | BD7: =협력사등급별MM!AM8 -> 2 | BE7: =BD7-BC7 -> 0 | BG7: =견적기준통합!AA7 -> 2 | BH7: =협력사등급별MM!AO8 -> 2 | BI7: =BH7-BG7 -> 0
B8: 바이널씨 | C8: =견적기준통합!M8 -> 11 | D8: =협력사등급별MM!M9 -> 6.5 | E8: =D8-C8 -> -4.5 | G8: =견적기준통합!N8 -> 12 | H8: =협력사등급별MM!O9 -> 12 | I8: =H8-G8 -> 0 | K8: =견적기준통합!O8 -> 15 | L8: =협력사등급별MM!Q9 -> 17 | M8: =L8-K8 -> 2 | O8: =견적기준통합!P8 -> 15 | P8: =협력사등급별MM!S9 -> 17 | Q8: =P8-O8 -> 2 | S8: =견적기준통합!Q8 -> 14.5 | T8: =협력사등급별MM!U9 -> 17 | U8: =T8-S8 -> 2.5 | W8: =견적기준통합!R8 -> 14 | X8: =협력사등급별MM!W9 -> 17 | Y8: =X8-W8 -> 3 | AA8: =견적기준통합!S8 -> 14 | AB8: =협력사등급별MM!Y9 -> 17 | AC8: =AB8-AA8 -> 3 | AE8: =견적기준통합!T8 -> 14 | AF8: =협력사등급별MM!AA9 -> 15.75 | AG8: =AF8-AE8 -> 1.75 | AI8: =견적기준통합!U8 -> 14 | AJ8: =협력사등급별MM!AC9 -> 15 | AK8: =AJ8-AI8 -> 1 | AM8: =견적기준통합!V8 -> 12 | AN8: =협력사등급별MM!AE9 -> 11 | AO8: =AN8-AM8 -> -1 | AQ8: =견적기준통합!W8 -> 11 | AR8: =협력사등급별MM!AG9 -> 7.5 | AS8: =AR8-AQ8 -> -3.5 | AU8: =견적기준통합!X8 -> 9.5 | AV8: =협력사등급별MM!AI9 -> 6.25 | AW8: =AV8-AU8 -> -3.25 | AY8: =견적기준통합!Y8 -> 8 | AZ8: =협력사등급별MM!AK9 -> 5.5 | BA8: =AZ8-AY8 -> -2.5 | BC8: =견적기준통합!Z8 -> 6 | BD8: =협력사등급별MM!AM9 -> 5 | BE8: =BD8-BC8 -> -1 | BG8: =견적기준통합!AA8 -> 2 | BH8: =협력사등급별MM!AO9 -> 2.5 | BI8: =BH8-BG8 -> 0.5
B9: 커머스웨어 | C9: =견적기준통합!M9 -> 16 | D9: =협력사등급별MM!M10 -> 16.75 | E9: =D9-C9 -> 0.75 | G9: =견적기준통합!N9 -> 16 | H9: =협력사등급별MM!O10 -> 18 | I9: =H9-G9 -> 2 | K9: =견적기준통합!O9 -> 16 | L9: =협력사등급별MM!Q10 -> 19 | M9: =L9-K9 -> 3 | O9: =견적기준통합!P9 -> 16.5 | P9: =협력사등급별MM!S10 -> 19 | Q9: =P9-O9 -> 2.5 | S9: =견적기준통합!Q9 -> 42 | T9: =협력사등급별MM!U10 -> 41 | U9: =T9-S9 -> -1 | W9: =견적기준통합!R9 -> 42 | X9: =협력사등급별MM!W10 -> 43.5 | Y9: =X9-W9 -> 1.5 | AA9: =견적기준통합!S9 -> 45 | AB9: =협력사등급별MM!Y10 -> 46 | AC9: =AB9-AA9 -> 1 | AE9: =견적기준통합!T9 -> 45 | AF9: =협력사등급별MM!AA10 -> 46 | AG9: =AF9-AE9 -> 1 | AI9: =견적기준통합!U9 -> 45 | AJ9: =협력사등급별MM!AC10 -> 46 | AK9: =AJ9-AI9 -> 1 | AM9: =견적기준통합!V9 -> 45 | AN9: =협력사등급별MM!AE10 -> 46 | AO9: =AN9-AM9 -> 1 | AQ9: =견적기준통합!W9 -> 45 | AR9: =협력사등급별MM!AG10 -> 46 | AS9: =AR9-AQ9 -> 1 | AU9: =견적기준통합!X9 -> 45 | AV9: =협력사등급별MM!AI10 -> 46 | AW9: =AV9-AU9 -> 1 | AY9: =견적기준통합!Y9 -> 45 | AZ9: =협력사등급별MM!AK10 -> 46 | BA9: =AZ9-AY9 -> 1 | BC9: =견적기준통합!Z9 -> 45 | BD9: =협력사등급별MM!AM10 -> 46 | BE9: =BD9-BC9 -> 1 | BG9: =견적기준통합!AA9 -> 26 | BH9: =협력사등급별MM!AO10 -> 34 | BI9: =BH9-BG9 -> 8
B10: 아이온 | C10: =견적기준통합!M10 -> 1.25 | D10: =협력사등급별MM!M11 -> 0 | E10: =D10-C10 -> -1.25 | G10: =견적기준통합!N10 -> 0.75 | H10: =협력사등급별MM!O11 -> 0 | I10: =H10-G10 -> -0.75 | K10: =견적기준통합!O10 -> 0.5 | L10: =협력사등급별MM!Q11 -> 0 | M10: =L10-K10 -> -0.5 | O10: =견적기준통합!P10 -> 0.5 | P10: =협력사등급별MM!S11 -> 0 | Q10: =P10-O10 -> -0.5 | S10: =견적기준통합!Q10 -> 3.25 | T10: =협력사등급별MM!U11 -> 0 | U10: =T10-S10 -> -3.25 | W10: =견적기준통합!R10 -> 2.5 | X10: =협력사등급별MM!W11 -> 0 | Y10: =X10-W10 -> -2.5 | AA10: =견적기준통합!S10 -> 2.5 | AB10: =협력사등급별MM!Y11 -> 0 | AC10: =AB10-AA10 -> -2.5 | AE10: =견적기준통합!T10 -> 2.5 | AF10: =협력사등급별MM!AA11 -> 0 | AG10: =AF10-AE10 -> -2.5 | AI10: =견적기준통합!U10 -> 3.5 | AJ10: =협력사등급별MM!AC11 -> 0 | AK10: =AJ10-AI10 -> -3.5 | AM10: =견적기준통합!V10 -> 3.5 | AN10: =협력사등급별MM!AE11 -> 0 | AO10: =AN10-AM10 -> -3.5 | AQ10: =견적기준통합!W10 -> 3.75 | AR10: =협력사등급별MM!AG11 -> 0 | AS10: =AR10-AQ10 -> -3.75 | AU10: =견적기준통합!X10 -> 3.5 | AV10: =협력사등급별MM!AI11 -> 0 | AW10: =AV10-AU10 -> -3.5 | AY10: =견적기준통합!Y10 -> 2.5 | AZ10: =협력사등급별MM!AK11 -> 0 | BA10: =AZ10-AY10 -> -2.5 | BC10: =견적기준통합!Z10 -> 0.5 | BD10: =협력사등급별MM!AM11 -> 0 | BE10: =BD10-BC10 -> -0.5 | BG10: =견적기준통합!AA10 -> 0.5 | BH10: =협력사등급별MM!AO11 -> 0 | BI10: =BH10-BG10 -> -0.5
B11: 씨엔씨네트웍스 | C11: =견적기준통합!M11 -> 2 | D11: =협력사등급별MM!M12 -> 2 | E11: =D11-C11 -> 0 | G11: =견적기준통합!N11 -> 2.5 | H11: =협력사등급별MM!O12 -> 3.4 | I11: =H11-G11 -> 0.9 | K11: =견적기준통합!O11 -> 4.5 | L11: =협력사등급별MM!Q12 -> 4 | M11: =L11-K11 -> -0.5 | O11: =견적기준통합!P11 -> 5.5 | P11: =협력사등급별MM!S12 -> 5.4 | Q11: =P11-O11 -> -0.1 | S11: =견적기준통합!Q11 -> 7.5 | T11: =협력사등급별MM!U12 -> 9 | U11: =T11-S11 -> 1.5 | W11: =견적기준통합!R11 -> 8 | X11: =협력사등급별MM!W12 -> 9 | Y11: =X11-W11 -> 1 | AA11: =견적기준통합!S11 -> 8 | AB11: =협력사등급별MM!Y12 -> 7 | AC11: =AB11-AA11 -> -1 | AE11: =견적기준통합!T11 -> 8 | AF11: =협력사등급별MM!AA12 -> 7 | AG11: =AF11-AE11 -> -1 | AI11: =견적기준통합!U11 -> 8 | AJ11: =협력사등급별MM!AC12 -> 6.5 | AK11: =AJ11-AI11 -> -1.5 | AM11: =견적기준통합!V11 -> 8 | AN11: =협력사등급별MM!AE12 -> 6 | AO11: =AN11-AM11 -> -2 | AQ11: =견적기준통합!W11 -> 8 | AR11: =협력사등급별MM!AG12 -> 6 | AS11: =AR11-AQ11 -> -2 | AU11: =견적기준통합!X11 -> 8 | AV11: =협력사등급별MM!AI12 -> 3 | AW11: =AV11-AU11 -> -5 | AY11: =견적기준통합!Y11 -> 8 | AZ11: =협력사등급별MM!AK12 -> 2.3 | BA11: =AZ11-AY11 -> -5.7 | BC11: =견적기준통합!Z11 -> 5.5 | BD11: =협력사등급별MM!AM12 -> 1 | BE11: =BD11-BC11 -> -4.5 | BG11: =견적기준통합!AA11 -> 1.5 | BH11: =협력사등급별MM!AO12 -> 0.5 | BI11: =BH11-BG11 -> -1
B12: 투비소프트 | C12: =견적기준통합!M12 -> 6 | D12: =협력사등급별MM!M13 -> 2.75 | E12: =D12-C12 -> -3.25 | G12: =견적기준통합!N12 -> 12 | H12: =협력사등급별MM!O13 -> 7.45 | I12: =H12-G12 -> -4.55 | K12: =견적기준통합!O12 -> 12 | L12: =협력사등급별MM!Q13 -> 11.35 | M12: =L12-K12 -> -0.65 | O12: =견적기준통합!P12 -> 15 | P12: =협력사등급별MM!S13 -> 17.05 | Q12: =P12-O12 -> 2.05 | S12: =견적기준통합!Q12 -> 22 | T12: =협력사등급별MM!U13 -> 16.5 | U12: =T12-S12 -> -5.5 | W12: =견적기준통합!R12 -> 19 | X12: =협력사등급별MM!W13 -> 22 | Y12: =X12-W12 -> 3 | AA12: =견적기준통합!S12 -> 17 | AB12: =협력사등급별MM!Y13 -> 21 | AC12: =AB12-AA12 -> 4 | AE12: =견적기준통합!T12 -> 17 | AF12: =협력사등급별MM!AA13 -> 17.95 | AG12: =AF12-AE12 -> 0.95 | AI12: =견적기준통합!U12 -> 17 | AJ12: =협력사등급별MM!AC13 -> 17 | AK12: =AJ12-AI12 -> 0 | AM12: =견적기준통합!V12 -> 17 | AN12: =협력사등급별MM!AE13 -> 17 | AO12: =AN12-AM12 -> 0 | AQ12: =견적기준통합!W12 -> 16 | AR12: =협력사등급별MM!AG13 -> 18 | AS12: =AR12-AQ12 -> 2 | AU12: =견적기준통합!X12 -> 16 | AV12: =협력사등급별MM!AI13 -> 17.5 | AW12: =AV12-AU12 -> 1.5 | AY12: =견적기준통합!Y12 -> 15 | AZ12: =협력사등급별MM!AK13 -> 15 | BA12: =AZ12-AY12 -> 0 | BC12: =견적기준통합!Z12 -> 13 | BD12: =협력사등급별MM!AM13 -> 6.25 | BE12: =BD12-BC12 -> -6.75 | BG12: =견적기준통합!AA12 -> 7 | BH12: =협력사등급별MM!AO13 -> 0 | BI12: =BH12-BG12 -> -7
B13: A&T | C13: =견적기준통합!M13 -> 4 | D13: =협력사등급별MM!M14 -> 4 | E13: =D13-C13 -> 0 | G13: =견적기준통합!N13 -> 6 | H13: =협력사등급별MM!O14 -> 5 | I13: =H13-G13 -> -1 | K13: =견적기준통합!O13 -> 7 | L13: =협력사등급별MM!Q14 -> 6 | M13: =L13-K13 -> -1 | O13: =견적기준통합!P13 -> 7 | P13: =협력사등급별MM!S14 -> 7 | Q13: =P13-O13 -> 0 | S13: =견적기준통합!Q13 -> 9 | T13: =협력사등급별MM!U14 -> 9.5 | U13: =T13-S13 -> 0.5 | W13: =견적기준통합!R13 -> 9 | X13: =협력사등급별MM!W14 -> 10 | Y13: =X13-W13 -> 1 | AA13: =견적기준통합!S13 -> 9 | AB13: =협력사등급별MM!Y14 -> 10 | AC13: =AB13-AA13 -> 1 | AE13: =견적기준통합!T13 -> 9 | AF13: =협력사등급별MM!AA14 -> 10 | AG13: =AF13-AE13 -> 1 | AI13: =견적기준통합!U13 -> 9 | AJ13: =협력사등급별MM!AC14 -> 10 | AK13: =AJ13-AI13 -> 1 | AM13: =견적기준통합!V13 -> 9 | AN13: =협력사등급별MM!AE14 -> 9.5 | AO13: =AN13-AM13 -> 0.5 | AQ13: =견적기준통합!W13 -> 8 | AR13: =협력사등급별MM!AG14 -> 7 | AS13: =AR13-AQ13 -> -1 | AU13: =견적기준통합!X13 -> 8 | AV13: =협력사등급별MM!AI14 -> 6 | AW13: =AV13-AU13 -> -2 | AY13: =견적기준통합!Y13 -> 6 | AZ13: =협력사등급별MM!AK14 -> 6 | BA13: =AZ13-AY13 -> 0 | BC13: =견적기준통합!Z13 -> 4 | BD13: =협력사등급별MM!AM14 -> 4 | BE13: =BD13-BC13 -> 0 | BG13: =견적기준통합!AA13 -> 4 | BH13: =협력사등급별MM!AO14 -> 4 | BI13: =BH13-BG13 -> 0
B14: 오브젠 | C14: =견적기준통합!M14 -> 0 | D14: =협력사등급별MM!M15 -> 0 | E14: =D14-C14 -> 0 | G14: =견적기준통합!N14 -> 0 | H14: =협력사등급별MM!O15 -> 0.4 | I14: =H14-G14 -> 0.4 | K14: =견적기준통합!O14 -> 0 | L14: =협력사등급별MM!Q15 -> 0.4 | M14: =L14-K14 -> 0.4 | O14: =견적기준통합!P14 -> 0 | P14: =협력사등급별MM!S15 -> 0.4 | Q14: =P14-O14 -> 0.4 | S14: =견적기준통합!Q14 -> 0 | T14: =협력사등급별MM!U15 -> 0.4 | U14: =T14-S14 -> 0.4 | W14: =견적기준통합!R14 -> 0 | X14: =협력사등급별MM!W15 -> 0.4 | Y14: =X14-W14 -> 0.4 | AA14: =견적기준통합!S14 -> 5 | AB14: =협력사등급별MM!Y15 -> 6 | AC14: =AB14-AA14 -> 1 | AE14: =견적기준통합!T14 -> 8 | AF14: =협력사등급별MM!AA15 -> 11 | AG14: =AF14-AE14 -> 3 | AI14: =견적기준통합!U14 -> 9 | AJ14: =협력사등급별MM!AC15 -> 11 | AK14: =AJ14-AI14 -> 2 | AM14: =견적기준통합!V14 -> 10 | AN14: =협력사등급별MM!AE15 -> 10 | AO14: =AN14-AM14 -> 0 | AQ14: =견적기준통합!W14 -> 12 | AR14: =협력사등급별MM!AG15 -> 10 | AS14: =AR14-AQ14 -> -2 | AU14: =견적기준통합!X14 -> 12 | AV14: =협력사등급별MM!AI15 -> 10 | AW14: =AV14-AU14 -> -2 | AY14: =견적기준통합!Y14 -> 12 | AZ14: =협력사등급별MM!AK15 -> 10 | BA14: =AZ14-AY14 -> -2 | BC14: =견적기준통합!Z14 -> 12 | BD14: =협력사등급별MM!AM15 -> 10 | BE14: =BD14-BC14 -> -2 | BG14: =견적기준통합!AA14 -> 0 | BH14: =협력사등급별MM!AO15 -> 0 | BI14: =BH14-BG14 -> 0
B15: 골든플래닛 | C15: =견적기준통합!M15 -> 0 | D15: =협력사등급별MM!M16 -> 0 | E15: =D15-C15 -> 0 | G15: =견적기준통합!N15 -> 0 | H15: =협력사등급별MM!O16 -> 0 | I15: =H15-G15 -> 0 | K15: =견적기준통합!O15 -> 0 | L15: =협력사등급별MM!Q16 -> 0 | M15: =L15-K15 -> 0 | O15: =견적기준통합!P15 -> 1 | P15: =협력사등급별MM!S16 -> 0 | Q15: =P15-O15 -> -1 | S15: =견적기준통합!Q15 -> 1 | T15: =협력사등급별MM!U16 -> 0 | U15: =T15-S15 -> -1 | W15: =견적기준통합!R15 -> 1 | X15: =협력사등급별MM!W16 -> 1 | Y15: =X15-W15 -> 0 | AA15: =견적기준통합!S15 -> 1 | AB15: =협력사등급별MM!Y16 -> 1 | AC15: =AB15-AA15 -> 0 | AE15: =견적기준통합!T15 -> 1 | AF15: =협력사등급별MM!AA16 -> 1 | AG15: =AF15-AE15 -> 0 | AI15: =견적기준통합!U15 -> 1 | AJ15: =협력사등급별MM!AC16 -> 1 | AK15: =AJ15-AI15 -> 0 | AM15: =견적기준통합!V15 -> 0.3 | AN15: =협력사등급별MM!AE16 -> 1 | AO15: =AN15-AM15 -> 0.7 | AQ15: =견적기준통합!W15 -> 0 | AR15: =협력사등급별MM!AG16 -> 1 | AS15: =AR15-AQ15 -> 1 | AU15: =견적기준통합!X15 -> 0 | AV15: =협력사등급별MM!AI16 -> 0.3 | AW15: =AV15-AU15 -> 0.3 | AY15: =견적기준통합!Y15 -> 0 | AZ15: =협력사등급별MM!AK16 -> 0 | BA15: =AZ15-AY15 -> 0 | BC15: =견적기준통합!Z15 -> 0 | BD15: =협력사등급별MM!AM16 -> 0 | BE15: =BD15-BC15 -> 0 | BG15: =견적기준통합!AA15 -> 0 | BH15: =협력사등급별MM!AO16 -> 0 | BI15: =BH15-BG15 -> 0
B16: 플레이투게더 | C16: =견적기준통합!M16 -> 0 | D16: =협력사등급별MM!M18 -> 1 | E16: =D16-C16 -> 1 | G16: =견적기준통합!N16 -> 4 | H16: =협력사등급별MM!O18 -> 4 | I16: =H16-G16 -> 0 | K16: =견적기준통합!O16 -> 4 | L16: =협력사등급별MM!Q18 -> 5.8 | M16: =L16-K16 -> 1.8 | O16: =견적기준통합!P16 -> 4 | P16: =협력사등급별MM!S18 -> 6.3 | Q16: =P16-O16 -> 2.3 | S16: =견적기준통합!Q16 -> 7.5 | T16: =협력사등급별MM!U18 -> 6.5 | U16: =T16-S16 -> -1 | W16: =견적기준통합!R16 -> 9 | X16: =협력사등급별MM!W18 -> 6.5 | Y16: =X16-W16 -> -2.5 | AA16: =견적기준통합!S16 -> 9 | AB16: =협력사등급별MM!Y18 -> 8 | AC16: =AB16-AA16 -> -1 | AE16: =견적기준통합!T16 -> 9 | AF16: =협력사등급별MM!AA18 -> 8 | AG16: =AF16-AE16 -> -1 | AI16: =견적기준통합!U16 -> 9 | AJ16: =협력사등급별MM!AC18 -> 9 | AK16: =AJ16-AI16 -> 0 | AM16: =견적기준통합!V16 -> 9 | AN16: =협력사등급별MM!AE18 -> 9 | AO16: =AN16-AM16 -> 0 | AQ16: =견적기준통합!W16 -> 8 | AR16: =협력사등급별MM!AG18 -> 9 | AS16: =AR16-AQ16 -> 1 | AU16: =견적기준통합!X16 -> 7 | AV16: =협력사등급별MM!AI18 -> 9 | AW16: =AV16-AU16 -> 2 | AY16: =견적기준통합!Y16 -> 7 | AZ16: =협력사등급별MM!AK18 -> 7 | BA16: =AZ16-AY16 -> 0 | BC16: =견적기준통합!Z16 -> 5.5 | BD16: =협력사등급별MM!AM18 -> 6.5 | BE16: =BD16-BC16 -> 1 | BG16: =견적기준통합!AA16 -> 0 | BH16: =협력사등급별MM!AO18 -> 0 | BI16: =BH16-BG16 -> 0
B17: 총계 | C17: =SUM(C4:C16) -> 58.25 | D17: =SUM(D4:D16) -> 48.75 | E17: =SUM(E4:E16) -> -9.5 | G17: =SUM(G4:G16) -> 73.75 | H17: =SUM(H4:H16) -> 69.25 | I17: =SUM(I4:I16) -> -4.5 | K17: =SUM(K4:K16) -> 85 | L17: =SUM(L4:L16) -> 86.55 | M17: =SUM(M4:M16) -> 1.55 | O17: =SUM(O4:O16) -> 93.5 | P17: =SUM(P4:P16) -> 95.85 | Q17: =SUM(Q4:Q16) -> 2.35 | S17: =SUM(S4:S16) -> 140.25 | T17: =SUM(T4:T16) -> 128.4 | U17: =SUM(U4:U16) -> -11.85 | W17: =SUM(W4:W16) -> 140.5 | X17: =SUM(X4:X16) -> 144.4 | Y17: =SUM(Y4:Y16) -> 3.9 | AA17: =SUM(AA4:AA16) -> 144.5 | AB17: =SUM(AB4:AB16) -> 152.5 | AC17: =SUM(AC4:AC16) -> 8 | AE17: =SUM(AE4:AE16) -> 147.5 | AF17: =SUM(AF4:AF16) -> 151.95 | AG17: =SUM(AG4:AG16) -> 4.45 | AI17: =견적기준통합!U17 -> 152 | AJ17: =협력사등급별MM!AC21 -> 156.2 | AK17: =AJ17-AI17 -> 4.2 | AM17: =견적기준통합!V17 -> 151.3 | AN17: =협력사등급별MM!AE21 -> 156.45 | AO17: =AN17-AM17 -> 5.15 | AQ17: =견적기준통합!W17 -> 149.25 | AR17: =협력사등급별MM!AG21 -> 147.4 | AS17: =AR17-AQ17 -> -1.85 | AU17: =견적기준통합!X17 -> 144.5 | AV17: =협력사등급별MM!AI21 -> 134.75 | AW17: =AV17-AU17 -> -9.75 | AY17: =견적기준통합!Y17 -> 133.25 | AZ17: =협력사등급별MM!AK21 -> 122.2 | BA17: =AZ17-AY17 -> -11.05 | BC17: =견적기준통합!Z17 -> 112.5 | BD17: =협력사등급별MM!AM21 -> 103.45 | BE17: =BD17-BC17 -> -9.05 | BG17: =견적기준통합!AA17 -> 51 | BH17: =협력사등급별MM!AO21 -> 56.05 | BI17: =BH17-BG17 -> 5.05
B18: 누적차이 | C18: =C17 -> 58.25 | D18: =D17 -> 48.75 | E18: =E17 -> -9.5 | G18: =C18+G17 -> 132 | H18: =D18+H17 -> 118 | I18: =E18+I17 -> -14 | K18: =G18+K17 -> 217 | L18: =H18+L17 -> 204.55 | M18: =I18+M17 -> -12.45 | O18: =K18+O17 -> 310.5 | P18: =L18+P17 -> 300.4 | Q18: =M18+Q17 -> -10.1 | S18: =O18+S17 -> 450.75 | T18: =P18+T17 -> 428.8 | U18: =Q18+U17 -> -21.95 | W18: =S18+W17 -> 591.25 | X18: =T18+X17 -> 573.2 | Y18: =U18+Y17 -> -18.05 | AA18: =W18+AA17 -> 735.75 | AB18: =X18+AB17 -> 725.7 | AC18: =Y18+AC17 -> -10.05 | AE18: =AA18+AE17 -> 883.25 | AF18: =AB18+AF17 -> 877.65 | AG18: =AC18+AG17 -> -5.6 | AI18: =AE18+AI17 -> 1035.25 | AJ18: =AF18+AJ17 -> 1033.85 | AK18: =AG18+AK17 -> -1.4 | AM18: =AI18+AM17 -> 1186.55 | AN18: =AJ18+AN17 -> 1190.3 | AO18: =AK18+AO17 -> 3.75 | AQ18: =AM18+AQ17 -> 1335.8 | AR18: =AN18+AR17 -> 1337.7 | AS18: =AO18+AS17 -> 1.9 | AU18: =AQ18+AU17 -> 1480.3 | AV18: =AR18+AV17 -> 1472.45 | AW18: =AS18+AW17 -> -7.85 | AY18: =AU18+AY17 -> 1613.55 | AZ18: =AV18+AZ17 -> 1594.65 | BA18: =AW18+BA17 -> -18.9 | BC18: =AY18+BC17 -> 1726.05 | BD18: =AZ18+BD17 -> 1698.1 | BE18: =BA18+BE17 -> -27.95 | BG18: =BC18+BG17 -> 1777.05 | BH18: =BD18+BH17 -> 1754.15 | BI18: =BE18+BI17 -> -22.9
B20: 총합
B21: 협력사 | C21: 총합
C22: 견적 | D22: 실투입 | E22: 차이
B23: kt ds | C23: =C4+G4+K4+O4+S4+W4+AA4+AE4+AI4+AM4+AQ4+AU4+AY4+BC4+BG4 -> 315 | D23: =D4+H4+L4+P4+T4+X4+AB4+AF4+AJ4+AN4+AR4+AV4+AZ4+BD4+BH4 -> 319.45 | E23: =D23-C23 -> 4.45
B24: SGSecurity | C24: =C5+G5+K5+O5+S5+W5+AA5+AE5+AI5+AM5+AQ5+AU5+AY5+BC5+BG5 -> 7.25 | D24: =D5+H5+L5+P5+T5+X5+AB5+AF5+AJ5+AN5+AR5+AV5+AZ5+BD5+BH5 -> 7.25 | E24: =D24-C24 -> 0
B25: 비플컨설팅 | C25: =C6+G6+K6+O6+S6+W6+AA6+AE6+AI6+AM6+AQ6+AU6+AY6+BC6+BG6 -> 69.5 | D25: =D6+H6+L6+P6+T6+X6+AB6+AF6+AJ6+AN6+AR6+AV6+AZ6+BD6+BH6 -> 70 | E25: =D25-C25 -> 0.5
B26: 이너웨이브 | C26: =C7+G7+K7+O7+S7+W7+AA7+AE7+AI7+AM7+AQ7+AU7+AY7+BC7+BG7 -> 47 | D26: =D7+H7+L7+P7+T7+X7+AB7+AF7+AJ7+AN7+AR7+AV7+AZ7+BD7+BH7 -> 47 | E26: =D26-C26 -> 0
B27: 바이널씨 | C27: =C8+G8+K8+O8+S8+W8+AA8+AE8+AI8+AM8+AQ8+AU8+AY8+BC8+BG8 -> 172 | D27: =D8+H8+L8+P8+T8+X8+AB8+AF8+AJ8+AN8+AR8+AV8+AZ8+BD8+BH8 -> 172 | E27: =D27-C27 -> 0
B28: 커머스웨어 | C28: =C9+G9+K9+O9+S9+W9+AA9+AE9+AI9+AM9+AQ9+AU9+AY9+BC9+BG9 -> 534.5 | D28: =D9+H9+L9+P9+T9+X9+AB9+AF9+AJ9+AN9+AR9+AV9+AZ9+BD9+BH9 -> 559.25 | E28: =D28-C28 -> 24.75
B29: 아이온 | C29: =C10+G10+K10+O10+S10+W10+AA10+AE10+AI10+AM10+AQ10+AU10+AY10+BC10+BG10 -> 31.5 | D29: =D10+H10+L10+P10+T10+X10+AB10+AF10+AJ10+AN10+AR10+AV10+AZ10+BD10+BH10 -> 0 | E29: =D29-C29 -> -31.5
B30: 씨엔씨네트웍스 | C30: =C11+G11+K11+O11+S11+W11+AA11+AE11+AI11+AM11+AQ11+AU11+AY11+BC11+BG11 -> 93 | D30: =D11+H11+L11+P11+T11+X11+AB11+AF11+AJ11+AN11+AR11+AV11+AZ11+BD11+BH11 -> 72.1 | E30: =D30-C30 -> -20.9
B31: 투비소프트 | C31: =C12+G12+K12+O12+S12+W12+AA12+AE12+AI12+AM12+AQ12+AU12+AY12+BC12+BG12 -> 221 | D31: =D12+H12+L12+P12+T12+X12+AB12+AF12+AJ12+AN12+AR12+AV12+AZ12+BD12+BH12 -> 206.8 | E31: =D31-C31 -> -14.2
B32: A&T | C32: =C13+G13+K13+O13+S13+W13+AA13+AE13+AI13+AM13+AQ13+AU13+AY13+BC13+BG13 -> 108 | D32: =D13+H13+L13+P13+T13+X13+AB13+AF13+AJ13+AN13+AR13+AV13+AZ13+BD13+BH13 -> 108 | E32: =D32-C32 -> 0
B33: 오브젠 | C33: =C14+G14+K14+O14+S14+W14+AA14+AE14+AI14+AM14+AQ14+AU14+AY14+BC14+BG14 -> 80 | D33: =D14+H14+L14+P14+T14+X14+AB14+AF14+AJ14+AN14+AR14+AV14+AZ14+BD14+BH14 -> 80 | E33: =D33-C33 -> 0
B34: 골든플래닛 | C34: =C15+G15+K15+O15+S15+W15+AA15+AE15+AI15+AM15+AQ15+AU15+AY15+BC15+BG15 -> 6.3 | D34: =D15+H15+L15+P15+T15+X15+AB15+AF15+AJ15+AN15+AR15+AV15+AZ15+BD15+BH15 -> 6.3 | E34: =D34-C34 -> 0
... B36: 총계 | C36: =C17+G17+K17+O17+S17+W17+AA17+AE17+AI17+AM17+AQ17+AU17+AY17+BC17+BG17 -> 1777.05 | D36: =D17+H17+L17+P17+T17+X17+AB17+AF17+AJ17+AN17+AR17+AV17+AZ17+BD17+BH17 -> 1754.15 | E36: =D36-C36 -> -22.9

Sheet 견적대비실투입(등급)
B2: 월별투입(실투입)
B3: 구분 | D3: 실투입 | J3: 제안기준 | P3: 차이내역(실투입-제안기준)
B4: NO | C4: 협력사 | D4: 특급 | E4: 고급 | F4: 중급 | G4: 초급 | H4: 총계 | J4: 특급 | K4: 고급 | L4: 중급 | M4: 초급 | N4: 총계 | P4: 특급 | Q4: 고급 | R4: 중급 | S4: 초급 | T4: 총계
B5: 1 | C5: kt ds | D5: =협력사등급별MM!D5 -> 157.45 | E5: =협력사등급별MM!E5 -> 71 | F5: =협력사등급별MM!F5 -> 40 | G5: =협력사등급별MM!G5 -> 51 | H5: =SUM(D5:G5) -> 319.45 | J5: =견적기준통합!D4 -> 157.5 | K5: =견적기준통합!E4 -> 76.5 | L5: =견적기준통합!F4 -> 40 | M5: =견적기준통합!G4 -> 41 | N5: =SUM(J5:M5) -> 315 | P5: =D5-J5 -> -0.05 | Q5: =E5-K5 -> -5.5 | R5: =F5-L5 -> 0 | S5: =G5-M5 -> 10 | T5: =SUM(P5:S5) -> 4.45
B6: 2 | C6: SGSecurity | D6: =협력사등급별MM!D6 -> 0 | E6: =협력사등급별MM!E6 -> 2 | F6: =협력사등급별MM!F6 -> 5.25 | G6: =협력사등급별MM!G6 -> 0 | H6: =SUM(D6:G6) -> 7.25 | J6: =견적기준통합!D5 -> 0 | K6: =견적기준통합!E5 -> 2 | L6: =견적기준통합!F5 -> 5.25 | M6: =견적기준통합!G5 -> 0 | N6: =SUM(J6:M6) -> 7.25 | P6: =D6-J6 -> 0 | Q6: =E6-K6 -> 0 | R6: =F6-L6 -> 0 | S6: =G6-M6 -> 0 | T6: =SUM(P6:S6) -> 0
B7: 3 | C7: 비플컨설팅 | D7: =협력사등급별MM!D7 -> 36 | E7: =협력사등급별MM!E7 -> 15 | F7: =협력사등급별MM!F7 -> 9.5 | G7: =협력사등급별MM!G7 -> 9.5 | H7: =SUM(D7:G7) -> 70 | J7: =견적기준통합!D6 -> 36 | K7: =견적기준통합!E6 -> 14.5 | L7: =견적기준통합!F6 -> 9.5 | M7: =견적기준통합!G6 -> 9.5 | N7: =SUM(J7:M7) -> 69.5 | P7: =D7-J7 -> 0 | Q7: =E7-K7 -> 0.5 | R7: =F7-L7 -> 0 | S7: =G7-M7 -> 0 | T7: =SUM(P7:S7) -> 0.5
B8: 4 | C8: 이너웨이브 | D8: =협력사등급별MM!D8 -> 24 | E8: =협력사등급별MM!E8 -> 0 | F8: =협력사등급별MM!F8 -> 23 | G8: =협력사등급별MM!G8 -> 0 | H8: =SUM(D8:G8) -> 47 | J8: =견적기준통합!D7 -> 22 | K8: =견적기준통합!E7 -> 0 | L8: =견적기준통합!F7 -> 23 | M8: =견적기준통합!G7 -> 2 | N8: =SUM(J8:M8) -> 47 | P8: =D8-J8 -> 2 | Q8: =E8-K8 -> 0 | R8: =F8-L8 -> 0 | S8: =G8-M8 -> -2 | T8: =SUM(P8:S8) -> 0
B9: 5 | C9: 바이널씨 | D9: =협력사등급별MM!D9 -> 14.5 | E9: =협력사등급별MM!E9 -> 34.5 | F9: =협력사등급별MM!F9 -> 68 | G9: =협력사등급별MM!G9 -> 55 | H9: =SUM(D9:G9) -> 172 | J9: =견적기준통합!D8 -> 14.5 | K9: =견적기준통합!E8 -> 40.5 | L9: =견적기준통합!F8 -> 62 | M9: =견적기준통합!G8 -> 55 | N9: =SUM(J9:M9) -> 172 | P9: =D9-J9 -> 0 | Q9: =E9-K9 -> -6 | R9: =F9-L9 -> 6 | S9: =G9-M9 -> 0 | T9: =SUM(P9:S9) -> 0
B10: 6 | C10: 커머스웨어 | D10: =협력사등급별MM!D10 -> 60 | E10: =협력사등급별MM!E10 -> 153.25 | F10: =협력사등급별MM!F10 -> 159 | G10: =협력사등급별MM!G10 -> 187 | H10: =SUM(D10:G10) -> 559.25 | J10: =견적기준통합!D9 -> 60 | K10: =견적기준통합!E9 -> 137 | L10: =견적기준통합!F9 -> 152.5 | M10: =견적기준통합!G9 -> 185 | N10: =SUM(J10:M10) -> 534.5 | P10: =D10-J10 -> 0 | Q10: =E10-K10 -> 16.25 | R10: =F10-L10 -> 6.5 | S10: =G10-M10 -> 2 | T10: =SUM(P10:S10) -> 24.75
B11: 7 | C11: 아이온 | D11: =협력사등급별MM!D11 -> 0 | E11: =협력사등급별MM!E11 -> 0 | F11: =협력사등급별MM!F11 -> 0 | G11: =협력사등급별MM!G11 -> 0 | H11: =SUM(D11:G11) -> 0 | J11: =견적기준통합!D10 -> 4 | K11: =견적기준통합!E10 -> 0 | L11: =견적기준통합!F10 -> 18.5 | M11: =견적기준통합!G10 -> 9 | N11: =SUM(J11:M11) -> 31.5 | P11: =D11-J11 -> -4 | Q11: =E11-K11 -> 0 | R11: =F11-L11 -> -18.5 | S11: =G11-M11 -> -9 | T11: =SUM(P11:S11) -> -31.5
B12: 8 | C12: 씨엔씨네트웍스 | D12: =협력사등급별MM!D12 -> 47.4 | E12: =협력사등급별MM!E12 -> 11.7 | F12: =협력사등급별MM!F12 -> 9 | G12: =협력사등급별MM!G12 -> 4 | H12: =SUM(D12:G12) -> 72.1 | J12: =견적기준통합!D11 -> 41 | K12: =견적기준통합!E11 -> 33.5 | L12: =견적기준통합!F11 -> 9.5 | M12: =견적기준통합!G11 -> 9 | N12: =SUM(J12:M12) -> 93 | P12: =D12-J12 -> 6.4 | Q12: =E12-K12 -> -21.8 | R12: =F12-L12 -> -0.5 | S12: =G12-M12 -> -5 | T12: =SUM(P12:S12) -> -20.9
B13: 9 | C13: 투비소프트 | D13: =협력사등급별MM!D13 -> 24.5 | E13: =협력사등급별MM!E13 -> 143.5 | F13: =협력사등급별MM!F13 -> 23.8 | G13: =협력사등급별MM!G13 -> 4 | H13: =SUM(D13:G13) -> 195.8 | J13: =견적기준통합!D12 -> 30 | K13: =견적기준통합!E12 -> 157 | L13: =견적기준통합!F12 -> 30 | M13: =견적기준통합!G12 -> 4 | N13: =SUM(J13:M13) -> 221 | P13: =D13-J13 -> -5.5 | Q13: =E13-K13 -> -13.5 | R13: =F13-L13 -> -6.2 | S13: =G13-M13 -> 0 | T13: =SUM(P13:S13) -> -25.2
B14: 10 | C14: A&T | D14: =협력사등급별MM!D14 -> 30 | E14: =협력사등급별MM!E14 -> 52 | F14: =협력사등급별MM!F14 -> 26 | G14: =협력사등급별MM!G14 -> 0 | H14: =SUM(D14:G14) -> 108 | J14: =견적기준통합!D13 -> 30 | K14: =견적기준통합!E13 -> 61.5 | L14: =견적기준통합!F13 -> 16.5 | M14: =견적기준통합!G13 -> 0 | N14: =SUM(J14:M14) -> 108 | P14: =D14-J14 -> 0 | Q14: =E14-K14 -> -9.5 | R14: =F14-L14 -> 9.5 | S14: =G14-M14 -> 0 | T14: =SUM(P14:S14) -> 0
B15: 11 | C15: 오브젠 | D15: =협력사등급별MM!D15 -> 26 | E15: =협력사등급별MM!E15 -> 46 | F15: =협력사등급별MM!F15 -> 0 | G15: =협력사등급별MM!G15 -> 8 | H15: =SUM(D15:G15) -> 80 | J15: =견적기준통합!D14 -> 24 | K15: =견적기준통합!E14 -> 51 | L15: =견적기준통합!F14 -> 0 | M15: =견적기준통합!G14 -> 5 | N15: =SUM(J15:M15) -> 80 | P15: =D15-J15 -> 2 | Q15: =E15-K15 -> -5 | R15: =F15-L15 -> 0 | S15: =G15-M15 -> 3 | T15: =SUM(P15:S15) -> 0
B16: 12 | C16: 골든플래닛 | D16: =협력사등급별MM!D16 -> 0 | E16: =협력사등급별MM!E16 -> 0 | F16: =협력사등급별MM!F16 -> 6.3 | G16: =협력사등급별MM!G16 -> 0 | H16: =SUM(D16:G16) -> 6.3 | J16: =견적기준통합!D15 -> 0 | K16: =견적기준통합!E15 -> 0 | L16: =견적기준통합!F15 -> 6.3 | M16: =견적기준통합!G15 -> 0 | N16: =SUM(J16:M16) -> 6.3 | P16: =D16-J16 -> 0 | Q16: =E16-K16 -> 0 | R16: =F16-L16 -> 0 | S16: =G16-M16 -> 0 | T16: =SUM(P16:S16) -> 0
B17: 14 | C17: 플레이투게더 | D17: =협력사등급별MM!D18 -> 0 | E17: =협력사등급별MM!E18 -> 67.6 | F17: =협력사등급별MM!F18 -> 19.5 | G17: =협력사등급별MM!G18 -> 8.5 | H17: =SUM(D17:G17) -> 95.6 | J17: =견적기준통합!D16 -> 0 | K17: =견적기준통합!E16 -> 66.5 | L17: =견적기준통합!F16 -> 19.5 | M17: =견적기준통합!G16 -> 6 | N17: =SUM(J17:M17) -> 92 | P17: =D17-J17 -> 0 | Q17: =E17-K17 -> 1.1 | R17: =F17-L17 -> 0 | S17: =G17-M17 -> 2.5 | T17: =SUM(P17:S17) -> 3.6
B18: 총계 | D18: =SUM(D5:D17) -> 419.85 | E18: =SUM(E5:E17) -> 596.55 | F18: =SUM(F5:F17) -> 389.35 | G18: =SUM(G5:G17) -> 327 | H18: =SUM(H5:H17) -> 1732.75 | J18: =SUM(J5:J17) -> 419 | K18: =SUM(K5:K17) -> 640 | L18: =SUM(L5:L17) -> 392.55 | M18: =SUM(M5:M17) -> 325.5 | N18: =SUM(N5:N17) -> 1777.05 | P18: =SUM(P5:P17) -> 0.85 | Q18: =SUM(Q5:Q17) -> -43.45 | R18: =SUM(R5:R17) -> -3.2 | S18: =SUM(S5:S17) -> 1.5 | T18: =SUM(P18:S18) -> -44.3

Sheet 견적기준통합
B2: 월별투입(실투입) | L2: M/M
B3: NO | C3: 협력사 | D3: 특급 | E3: 고급 | F3: 중급 | G3: 초급 | H3: 총계 | I3: 비율 | L3: 협력사 | M3: 2월 | N3: 3월 | O3: 4월 | P3: 5월 | Q3: 6월 | R3: 7월 | S3: 8월 | T3: 9월 | U3: 10월 | V3: 11월 | W3: 12월 | X3: 1월 | Y3: 2월 | Z3: 3월 | AA3: 4월 | AB3: 총계
B4: 1 | C4: kt ds | D4: =SUMIFS(견적기준!$AB$6:$AB$233,견적기준!$H$6:$H$233,$C4,견적기준!$E$6:$E$233,견적기준통합!$D$3) -> 157.5 | E4: =SUMIFS(견적기준!$AB$6:$AB$233,견적기준!$H$6:$H$233,$C4,견적기준!$E$6:$E$233,견적기준통합!$E$3) -> 76.5 | F4: =SUMIFS(견적기준!$AB$6:$AB$233,견적기준!$H$6:$H$233,$C4,견적기준!$E$6:$E$233,견적기준통합!$F$3) -> 40 | G4: =SUMIFS(견적기준!$AB$6:$AB$233,견적기준!$H$6:$H$233,$C4,견적기준!$E$6:$E$233,견적기준통합!$G$3) -> 41 | H4: =SUM(D4:G4) -> 315 | I4: =H4/$H$17 -> 0.17726007 | L4: kt ds | M4: =SUMIFS(견적기준!$M$6:$M$198,견적기준!$H$6:$H$198,견적기준통합!$L4) -> 16 | N4: =SUMIFS(견적기준!$N$6:$N$198,견적기준!$H$6:$H$198,견적기준통합!$L4) -> 16.5 | O4: =SUMIFS(견적기준!$O$6:O$198,견적기준!$H$6:$H$198,견적기준통합!$L4) -> 20 | P4: =SUMIFS(견적기준!$P$6:$P$198,견적기준!$H$6:$H$198,견적기준통합!$L4) -> 21 | Q4: =SUMIFS(견적기준!$Q$6:$Q$198,견적기준!$H$6:$H$198,견적기준통합!$L4) -> 23 | R4: =SUMIFS(견적기준!$R$6:$R$198,견적기준!$H$6:$H$198,견적기준통합!$L4) -> 24 | S4: =SUMIFS(견적기준!$S$6:$S$198,견적기준!$H$6:$H$198,견적기준통합!$L4) -> 23 | T4: =SUMIFS(견적기준!$T$6:$T$198,견적기준!$H$6:$H$198,견적기준통합!$L4) -> 24 | U4: =SUMIFS(견적기준!$U$6:$U$198,견적기준!$H$6:$H$198,견적기준통합!$L4) -> 26 | V4: =SUMIFS(견적기준!$V$6:$V$198,견적기준!$H$6:$H$198,견적기준통합!$L4) -> 27.5 | W4: =SUMIFS(견적기준!$W$6:$W$198,견적기준!$H$6:$H$198,견적기준통합!$L4) -> 26.5 | X4: =SUMIFS(견적기준!$X$6:$X$198,견적기준!$H$6:$H$198,견적기준통합!$L4) -> 24.5 | Y4: =SUMIFS(견적기준!$Y$6:$Y$198,견적기준!$H$6:$H$198,견적기준통합!$L4) -> 20 | Z4: =SUMIFS(견적기준!$Z$6:$Z$198,견적기준!$H$6:$H$198,견적기준통합!$L4) -> 15 | AA4: =SUMIFS(견적기준!$AA$6:$AA$198,견적기준!$H$6:$H$198,견적기준통합!$L4) -> 8 | AB4: =SUM(M4:AA4) -> 315
B5: 2 | C5: SGSecurity | D5: =SUMIFS(견적기준!$AB$6:$AB$233,견적기준!$H$6:$H$233,$C5,견적기준!$E$6:$E$233,견적기준통합!$D$3) -> 0 | E5: =SUMIFS(견적기준!$AB$6:$AB$233,견적기준!$H$6:$H$233,$C5,견적기준!$E$6:$E$233,견적기준통합!$E$3) -> 2 | F5: =SUMIFS(견적기준!$AB$6:$AB$233,견적기준!$H$6:$H$233,$C5,견적기준!$E$6:$E$233,견적기준통합!$F$3) -> 5.25 | G5: =SUMIFS(견적기준!$AB$6:$AB$233,견적기준!$H$6:$H$233,$C5,견적기준!$E$6:$E$233,견적기준통합!$G$3) -> 0 | H5: =SUM(D5:G5) -> 7.25 | I5: =H5/$H$17 -> 0.0040797952 | L5: SGSecurity | M5: =SUMIFS(견적기준!$M$6:$M$198,견적기준!$H$6:$H$198,견적기준통합!$L5) -> 0 | N5: =SUMIFS(견적기준!$N$6:$N$198,견적기준!$H$6:$H$198,견적기준통합!$L5) -> 0 | O5: =SUMIFS(견적기준!$O$6:O$198,견적기준!$H$6:$H$198,견적기준통합!$L5) -> 1 | P5: =SUMIFS(견적기준!$P$6:$P$198,견적기준!$H$6:$H$198,견적기준통합!$L5) -> 1 | Q5: =SUMIFS(견적기준!$Q$6:$Q$198,견적기준!$H$6:$H$198,견적기준통합!$L5) -> 0 | R5: =SUMIFS(견적기준!$R$6:$R$198,견적기준!$H$6:$H$198,견적기준통합!$L5) -> 0 | S5: =SUMIFS(견적기준!$S$6:$S$198,견적기준!$H$6:$H$198,견적기준통합!$L5) -> 0 | T5: =SUMIFS(견적기준!$T$6:$T$198,견적기준!$H$6:$H$198,견적기준통합!$L5) -> 0 | U5: =SUMIFS(견적기준!$U$6:$U$198,견적기준!$H$6:$H$198,견적기준통합!$L5) -> 0 | V5: =SUMIFS(견적기준!$V$6:$V$198,견적기준!$H$6:$H$198,견적기준통합!$L5) -> 0.5 | W5: =SUMIFS(견적기준!$W$6:$W$198,견적기준!$H$6:$H$198,견적기준통합!$L5) -> 2 | X5: =SUMIFS(견적기준!$X$6:$X$198,견적기준!$H$6:$H$198,견적기준통합!$L5) -> 2 | Y5: =SUMIFS(견적기준!$Y$6:$Y$198,견적기준!$H$6:$H$198,견적기준통합!$L5) -> 0.75 | Z5: =SUMIFS(견적기준!$Z$6:$Z$198,견적기준!$H$6:$H$198,견적기준통합!$L5) -> 0 | AA5: =SUMIFS(견적기준!$AA$6:$AA$198,견적기준!$H$6:$H$198,견적기준통합!$L5) -> 0 | AB5: =SUM(M5:AA5) -> 7.25
B6: 3 | C6: 비플컨설팅 | D6: =SUMIFS(견적기준!$AB$6:$AB$233,견적기준!$H$6:$H$233,$C6,견적기준!$E$6:$E$233,견적기준통합!$D$3) -> 36 | E6: =SUMIFS(견적기준!$AB$6:$AB$233,견적기준!$H$6:$H$233,$C6,견적기준!$E$6:$E$233,견적기준통합!$E$3) -> 14.5 | F6: =SUMIFS(견적기준!$AB$6:$AB$233,견적기준!$H$6:$H$233,$C6,견적기준!$E$6:$E$233,견적기준통합!$F$3) -> 9.5 | G6: =SUMIFS(견적기준!$AB$6:$AB$233,견적기준!$H$6:$H$233,$C6,견적기준!$E$6:$E$233,견적기준통합!$G$3) -> 9.5 | H6: =SUM(D6:G6) -> 69.5 | I6: =H6/$H$17 -> 0.039109761 | L6: 비플컨설팅 | M6: =SUMIFS(견적기준!$M$6:$M$198,견적기준!$H$6:$H$198,견적기준통합!$L6) -> 0 | N6: =SUMIFS(견적기준!$N$6:$N$198,견적기준!$H$6:$H$198,견적기준통합!$L6) -> 0 | O6: =SUMIFS(견적기준!$O$6:O$198,견적기준!$H$6:$H$198,견적기준통합!$L6) -> 0 | P6: =SUMIFS(견적기준!$P$6:$P$198,견적기준!$H$6:$H$198,견적기준통합!$L6) -> 2 | Q6: =SUMIFS(견적기준!$Q$6:$Q$198,견적기준!$H$6:$H$198,견적기준통합!$L6) -> 6.5 | R6: =SUMIFS(견적기준!$R$6:$R$198,견적기준!$H$6:$H$198,견적기준통합!$L6) -> 7 | S6: =SUMIFS(견적기준!$S$6:$S$198,견적기준!$H$6:$H$198,견적기준통합!$L6) -> 7 | T6: =SUMIFS(견적기준!$T$6:$T$198,견적기준!$H$6:$H$198,견적기준통합!$L6) -> 7 | U6: =SUMIFS(견적기준!$U$6:$U$198,견적기준!$H$6:$H$198,견적기준통합!$L6) -> 7.5 | V6: =SUMIFS(견적기준!$V$6:$V$198,견적기준!$H$6:$H$198,견적기준통합!$L6) -> 7.5 | W6: =SUMIFS(견적기준!$W$6:$W$198,견적기준!$H$6:$H$198,견적기준통합!$L6) -> 7 | X6: =SUMIFS(견적기준!$X$6:$X$198,견적기준!$H$6:$H$198,견적기준통합!$L6) -> 7 | Y6: =SUMIFS(견적기준!$Y$6:$Y$198,견적기준!$H$6:$H$198,견적기준통합!$L6) -> 7 | Z6: =SUMIFS(견적기준!$Z$6:$Z$198,견적기준!$H$6:$H$198,견적기준통합!$L6) -> 4 | AA6: =SUMIFS(견적기준!$AA$6:$AA$198,견적기준!$H$6:$H$198,견적기준통합!$L6) -> 0 | AB6: =SUM(M6:AA6) -> 69.5
B7: 4 | C7: 이너웨이브 | D7: =SUMIFS(견적기준!$AB$6:$AB$233,견적기준!$H$6:$H$233,$C7,견적기준!$E$6:$E$233,견적기준통합!$D$3) -> 22 | E7: =SUMIFS(견적기준!$AB$6:$AB$233,견적기준!$H$6:$H$233,$C7,견적기준!$E$6:$E$233,견적기준통합!$E$3) -> 0 | F7: =SUMIFS(견적기준!$AB$6:$AB$233,견적기준!$H$6:$H$233,$C7,견적기준!$E$6:$E$233,견적기준통합!$F$3) -> 23 | G7: =SUMIFS(견적기준!$AB$6:$AB$233,견적기준!$H$6:$H$233,$C7,견적기준!$E$6:$E$233,견적기준통합!$G$3) -> 2 | H7: =SUM(D7:G7) -> 47 | I7: =H7/$H$17 -> 0.026448327 | L7: 이너웨이브 | M7: =SUMIFS(견적기준!$M$6:$M$198,견적기준!$H$6:$H$198,견적기준통합!$L7) -> 2 | N7: =SUMIFS(견적기준!$N$6:$N$198,견적기준!$H$6:$H$198,견적기준통합!$L7) -> 4 | O7: =SUMIFS(견적기준!$O$6:O$198,견적기준!$H$6:$H$198,견적기준통합!$L7) -> 5 | P7: =SUMIFS(견적기준!$P$6:$P$198,견적기준!$H$6:$H$198,견적기준통합!$L7) -> 5 | Q7: =SUMIFS(견적기준!$Q$6:$Q$198,견적기준!$H$6:$H$198,견적기준통합!$L7) -> 4 | R7: =SUMIFS(견적기준!$R$6:$R$198,견적기준!$H$6:$H$198,견적기준통합!$L7) -> 5 | S7: =SUMIFS(견적기준!$S$6:$S$198,견적기준!$H$6:$H$198,견적기준통합!$L7) -> 4 | T7: =SUMIFS(견적기준!$T$6:$T$198,견적기준!$H$6:$H$198,견적기준통합!$L7) -> 3 | U7: =SUMIFS(견적기준!$U$6:$U$198,견적기준!$H$6:$H$198,견적기준통합!$L7) -> 3 | V7: =SUMIFS(견적기준!$V$6:$V$198,견적기준!$H$6:$H$198,견적기준통합!$L7) -> 2 | W7: =SUMIFS(견적기준!$W$6:$W$198,견적기준!$H$6:$H$198,견적기준통합!$L7) -> 2 | X7: =SUMIFS(견적기준!$X$6:$X$198,견적기준!$H$6:$H$198,견적기준통합!$L7) -> 2 | Y7: =SUMIFS(견적기준!$Y$6:$Y$198,견적기준!$H$6:$H$198,견적기준통합!$L7) -> 2 | Z7: =SUMIFS(견적기준!$Z$6:$Z$198,견적기준!$H$6:$H$198,견적기준통합!$L7) -> 2 | AA7: =SUMIFS(견적기준!$AA$6:$AA$198,견적기준!$H$6:$H$198,견적기준통합!$L7) -> 2 | AB7: =SUM(M7:AA7) -> 47
B8: 5 | C8: 바이널씨 | D8: =SUMIFS(견적기준!$AB$6:$AB$233,견적기준!$H$6:$H$233,$C8,견적기준!$E$6:$E$233,견적기준통합!$D$3) -> 14.5 | E8: =SUMIFS(견적기준!$AB$6:$AB$233,견적기준!$H$6:$H$233,$C8,견적기준!$E$6:$E$233,견적기준통합!$E$3) -> 40.5 | F8: =SUMIFS(견적기준!$AB$6:$AB$233,견적기준!$H$6:$H$233,$C8,견적기준!$E$6:$E$233,견적기준통합!$F$3) -> 62 | G8: =SUMIFS(견적기준!$AB$6:$AB$233,견적기준!$H$6:$H$233,$C8,견적기준!$E$6:$E$233,견적기준통합!$G$3) -> 55 | H8: =SUM(D8:G8) -> 172 | I8: =H8/$H$17 -> 0.096789623 | L8: 바이널씨 | M8: =SUMIFS(견적기준!$M$6:$M$198,견적기준!$H$6:$H$198,견적기준통합!$L8) -> 11 | N8: =SUMIFS(견적기준!$N$6:$N$198,견적기준!$H$6:$H$198,견적기준통합!$L8) -> 12 | O8: =SUMIFS(견적기준!$O$6:O$198,견적기준!$H$6:$H$198,견적기준통합!$L8) -> 15 | P8: =SUMIFS(견적기준!$P$6:$P$198,견적기준!$H$6:$H$198,견적기준통합!$L8) -> 15 | Q8: =SUMIFS(견적기준!$Q$6:$Q$198,견적기준!$H$6:$H$198,견적기준통합!$L8) -> 14.5 | R8: =SUMIFS(견적기준!$R$6:$R$198,견적기준!$H$6:$H$198,견적기준통합!$L8) -> 14 | S8: =SUMIFS(견적기준!$S$6:$S$198,견적기준!$H$6:$H$198,견적기준통합!$L8) -> 14 | T8: =SUMIFS(견적기준!$T$6:$T$198,견적기준!$H$6:$H$198,견적기준통합!$L8) -> 14 | U8: =SUMIFS(견적기준!$U$6:$U$198,견적기준!$H$6:$H$198,견적기준통합!$L8) -> 14 | V8: =SUMIFS(견적기준!$V$6:$V$198,견적기준!$H$6:$H$198,견적기준통합!$L8) -> 12 | W8: =SUMIFS(견적기준!$W$6:$W$198,견적기준!$H$6:$H$198,견적기준통합!$L8) -> 11 | X8: =SUMIFS(견적기준!$X$6:$X$198,견적기준!$H$6:$H$198,견적기준통합!$L8) -> 9.5 | Y8: =SUMIFS(견적기준!$Y$6:$Y$198,견적기준!$H$6:$H$198,견적기준통합!$L8) -> 8 | Z8: =SUMIFS(견적기준!$Z$6:$Z$198,견적기준!$H$6:$H$198,견적기준통합!$L8) -> 6 | AA8: =SUMIFS(견적기준!$AA$6:$AA$198,견적기준!$H$6:$H$198,견적기준통합!$L8) -> 2 | AB8: =SUM(M8:AA8) -> 172
B9: 6 | C9: 커머스웨어 | D9: =SUMIFS(견적기준!$AB$6:$AB$233,견적기준!$H$6:$H$233,$C9,견적기준!$E$6:$E$233,견적기준통합!$D$3) -> 60 | E9: =SUMIFS(견적기준!$AB$6:$AB$233,견적기준!$H$6:$H$233,$C9,견적기준!$E$6:$E$233,견적기준통합!$E$3) -> 137 | F9: =SUMIFS(견적기준!$AB$6:$AB$233,견적기준!$H$6:$H$233,$C9,견적기준!$E$6:$E$233,견적기준통합!$F$3) -> 152.5 | G9: =SUMIFS(견적기준!$AB$6:$AB$233,견적기준!$H$6:$H$233,$C9,견적기준!$E$6:$E$233,견적기준통합!$G$3) -> 185 | H9: =SUM(D9:G9) -> 534.5 | I9: =H9/$H$17 -> 0.30077938 | L9: 커머스웨어 | M9: =SUMIFS(견적기준!$M$6:$M$198,견적기준!$H$6:$H$198,견적기준통합!$L9) -> 16 | N9: =SUMIFS(견적기준!$N$6:$N$198,견적기준!$H$6:$H$198,견적기준통합!$L9) -> 16 | O9: =SUMIFS(견적기준!$O$6:O$198,견적기준!$H$6:$H$198,견적기준통합!$L9) -> 16 | P9: =SUMIFS(견적기준!$P$6:$P$198,견적기준!$H$6:$H$198,견적기준통합!$L9) -> 16.5 | Q9: =SUMIFS(견적기준!$Q$6:$Q$198,견적기준!$H$6:$H$198,견적기준통합!$L9) -> 42 | R9: =SUMIFS(견적기준!$R$6:$R$198,견적기준!$H$6:$H$198,견적기준통합!$L9) -> 42 | S9: =SUMIFS(견적기준!$S$6:$S$198,견적기준!$H$6:$H$198,견적기준통합!$L9) -> 45 | T9: =SUMIFS(견적기준!$T$6:$T$198,견적기준!$H$6:$H$198,견적기준통합!$L9) -> 45 | U9: =SUMIFS(견적기준!$U$6:$U$198,견적기준!$H$6:$H$198,견적기준통합!$L9) -> 45 | V9: =SUMIFS(견적기준!$V$6:$V$198,견적기준!$H$6:$H$198,견적기준통합!$L9) -> 45 | W9: =SUMIFS(견적기준!$W$6:$W$198,견적기준!$H$6:$H$198,견적기준통합!$L9) -> 45 | X9: =SUMIFS(견적기준!$X$6:$X$198,견적기준!$H$6:$H$198,견적기준통합!$L9) -> 45 | Y9: =SUMIFS(견적기준!$Y$6:$Y$198,견적기준!$H$6:$H$198,견적기준통합!$L9) -> 45 | Z9: =SUMIFS(견적기준!$Z$6:$Z$198,견적기준!$H$6:$H$198,견적기준통합!$L9) -> 45 | AA9: =SUMIFS(견적기준!$AA$6:$AA$198,견적기준!$H$6:$H$198,견적기준통합!$L9) -> 26 | AB9: =SUM(M9:AA9) -> 534.5
B10: 7 | C10: 아이온 | D10: =SUMIFS(견적기준!$AB$6:$AB$233,견적기준!$H$6:$H$233,$C10,견적기준!$E$6:$E$233,견적기준통합!$D$3) -> 4 | E10: =SUMIFS(견적기준!$AB$6:$AB$233,견적기준!$H$6:$H$233,$C10,견적기준!$E$6:$E$233,견적기준통합!$E$3) -> 0 | F10: =SUMIFS(견적기준!$AB$6:$AB$233,견적기준!$H$6:$H$233,$C10,견적기준!$E$6:$E$233,견적기준통합!$F$3) -> 18.5 | G10: =SUMIFS(견적기준!$AB$6:$AB$233,견적기준!$H$6:$H$233,$C10,견적기준!$E$6:$E$233,견적기준통합!$G$3) -> 9 | H10: =SUM(D10:G10) -> 31.5 | I10: =H10/$H$17 -> 0.017726007 | L10: 아이온 | M10: =SUMIFS(견적기준!$M$6:$M$198,견적기준!$H$6:$H$198,견적기준통합!$L10) -> 1.25 | N10: =SUMIFS(견적기준!$N$6:$N$198,견적기준!$H$6:$H$198,견적기준통합!$L10) -> 0.75 | O10: =SUMIFS(견적기준!$O$6:O$198,견적기준!$H$6:$H$198,견적기준통합!$L10) -> 0.5 | P10: =SUMIFS(견적기준!$P$6:$P$198,견적기준!$H$6:$H$198,견적기준통합!$L10) -> 0.5 | Q10: =SUMIFS(견적기준!$Q$6:$Q$198,견적기준!$H$6:$H$198,견적기준통합!$L10) -> 3.25 | R10: =SUMIFS(견적기준!$R$6:$R$198,견적기준!$H$6:$H$198,견적기준통합!$L10) -> 2.5 | S10: =SUMIFS(견적기준!$S$6:$S$198,견적기준!$H$6:$H$198,견적기준통합!$L10) -> 2.5 | T10: =SUMIFS(견적기준!$T$6:$T$198,견적기준!$H$6:$H$198,견적기준통합!$L10) -> 2.5 | U10: =SUMIFS(견적기준!$U$6:$U$198,견적기준!$H$6:$H$198,견적기준통합!$L10) -> 3.5 | V10: =SUMIFS(견적기준!$V$6:$V$198,견적기준!$H$6:$H$198,견적기준통합!$L10) -> 3.5 | W10: =SUMIFS(견적기준!$W$6:$W$198,견적기준!$H$6:$H$198,견적기준통합!$L10) -> 3.75 | X10: =SUMIFS(견적기준!$X$6:$X$198,견적기준!$H$6:$H$198,견적기준통합!$L10) -> 3.5 | Y10: =SUMIFS(견적기준!$Y$6:$Y$198,견적기준!$H$6:$H$198,견적기준통합!$L10) -> 2.5 | Z10: =SUMIFS(견적기준!$Z$6:$Z$198,견적기준!$H$6:$H$198,견적기준통합!$L10) -> 0.5 | AA10: =SUMIFS(견적기준!$AA$6:$AA$198,견적기준!$H$6:$H$198,견적기준통합!$L10) -> 0.5 | AB10: =SUM(M10:AA10) -> 31.5
B11: 8 | C11: 씨엔씨네트웍스 | D11: =SUMIFS(견적기준!$AB$6:$AB$233,견적기준!$H$6:$H$233,$C11,견적기준!$E$6:$E$233,견적기준통합!$D$3) -> 41 | E11: =SUMIFS(견적기준!$AB$6:$AB$233,견적기준!$H$6:$H$233,$C11,견적기준!$E$6:$E$233,견적기준통합!$E$3) -> 33.5 | F11: =SUMIFS(견적기준!$AB$6:$AB$233,견적기준!$H$6:$H$233,$C11,견적기준!$E$6:$E$233,견적기준통합!$F$3) -> 9.5 | G11: =SUMIFS(견적기준!$AB$6:$AB$233,견적기준!$H$6:$H$233,$C11,견적기준!$E$6:$E$233,견적기준통합!$G$3) -> 9 | H11: =SUM(D11:G11) -> 93 | I11: =H11/$H$17 -> 0.052333924 | L11: 씨엔씨네트웍스 | M11: =SUMIFS(견적기준!$M$6:$M$198,견적기준!$H$6:$H$198,견적기준통합!$L11) -> 2 | N11: =SUMIFS(견적기준!$N$6:$N$198,견적기준!$H$6:$H$198,견적기준통합!$L11) -> 2.5 | O11: =SUMIFS(견적기준!$O$6:O$198,견적기준!$H$6:$H$198,견적기준통합!$L11) -> 4.5 | P11: =SUMIFS(견적기준!$P$6:$P$198,견적기준!$H$6:$H$198,견적기준통합!$L11) -> 5.5 | Q11: =SUMIFS(견적기준!$Q$6:$Q$198,견적기준!$H$6:$H$198,견적기준통합!$L11) -> 7.5 | R11: =SUMIFS(견적기준!$R$6:$R$198,견적기준!$H$6:$H$198,견적기준통합!$L11) -> 8 | S11: =SUMIFS(견적기준!$S$6:$S$198,견적기준!$H$6:$H$198,견적기준통합!$L11) -> 8 | T11: =SUMIFS(견적기준!$T$6:$T$198,견적기준!$H$6:$H$198,견적기준통합!$L11) -> 8 | U11: =SUMIFS(견적기준!$U$6:$U$198,견적기준!$H$6:$H$198,견적기준통합!$L11) -> 8 | V11: =SUMIFS(견적기준!$V$6:$V$198,견적기준!$H$6:$H$198,견적기준통합!$L11) -> 8 | W11: =SUMIFS(견적기준!$W$6:$W$198,견적기준!$H$6:$H$198,견적기준통합!$L11) -> 8 | X11: =SUMIFS(견적기준!$X$6:$X$198,견적기준!$H$6:$H$198,견적기준통합!$L11) -> 8 | Y11: =SUMIFS(견적기준!$Y$6:$Y$198,견적기준!$H$6:$H$198,견적기준통합!$L11) -> 8 | Z11: =SUMIFS(견적기준!$Z$6:$Z$198,견적기준!$H$6:$H$198,견적기준통합!$L11) -> 5.5 | AA11: =SUMIFS(견적기준!$AA$6:$AA$198,견적기준!$H$6:$H$198,견적기준통합!$L11) -> 1.5 | AB11: =SUM(M11:AA11) -> 93
B12: 9 | C12: 투비소프트 | D12: =SUMIFS(견적기준!$AB$6:$AB$233,견적기준!$H$6:$H$233,$C12,견적기준!$E$6:$E$233,견적기준통합!$D$3) -> 30 | E12: =SUMIFS(견적기준!$AB$6:$AB$233,견적기준!$H$6:$H$233,$C12,견적기준!$E$6:$E$233,견적기준통합!$E$3) -> 157 | F12: =SUMIFS(견적기준!$AB$6:$AB$233,견적기준!$H$6:$H$233,$C12,견적기준!$E$6:$E$233,견적기준통합!$F$3) -> 30 | G12: =SUMIFS(견적기준!$AB$6:$AB$233,견적기준!$H$6:$H$233,$C12,견적기준!$E$6:$E$233,견적기준통합!$G$3) -> 4 | H12: =SUM(D12:G12) -> 221 | I12: =H12/$H$17 -> 0.12436341 | L12: 투비소프트 | M12: =SUMIFS(견적기준!$M$6:$M$198,견적기준!$H$6:$H$198,견적기준통합!$L12) -> 6 | N12: =SUMIFS(견적기준!$N$6:$N$198,견적기준!$H$6:$H$198,견적기준통합!$L12) -> 12 | O12: =SUMIFS(견적기준!$O$6:O$198,견적기준!$H$6:$H$198,견적기준통합!$L12) -> 12 | P12: =SUMIFS(견적기준!$P$6:$P$198,견적기준!$H$6:$H$198,견적기준통합!$L12) -> 15 | Q12: =SUMIFS(견적기준!$Q$6:$Q$198,견적기준!$H$6:$H$198,견적기준통합!$L12) -> 22 | R12: =SUMIFS(견적기준!$R$6:$R$198,견적기준!$H$6:$H$198,견적기준통합!$L12) -> 19 | S12: =SUMIFS(견적기준!$S$6:$S$198,견적기준!$H$6:$H$198,견적기준통합!$L12) -> 17 | T12: =SUMIFS(견적기준!$T$6:$T$198,견적기준!$H$6:$H$198,견적기준통합!$L12) -> 17 | U12: =SUMIFS(견적기준!$U$6:$U$198,견적기준!$H$6:$H$198,견적기준통합!$L12) -> 17 | V12: =SUMIFS(견적기준!$V$6:$V$198,견적기준!$H$6:$H$198,견적기준통합!$L12) -> 17 | W12: =SUMIFS(견적기준!$W$6:$W$198,견적기준!$H$6:$H$198,견적기준통합!$L12) -> 16 | X12: =SUMIFS(견적기준!$X$6:$X$198,견적기준!$H$6:$H$198,견적기준통합!$L12) -> 16 | Y12: =SUMIFS(견적기준!$Y$6:$Y$198,견적기준!$H$6:$H$198,견적기준통합!$L12) -> 15 | Z12: =SUMIFS(견적기준!$Z$6:$Z$198,견적기준!$H$6:$H$198,견적기준통합!$L12) -> 13 | AA12: =SUMIFS(견적기준!$AA$6:$AA$198,견적기준!$H$6:$H$198,견적기준통합!$L12) -> 7 | AB12: =SUM(M12:AA12) -> 221
B13: 10 | C13: A&T | D13: =SUMIFS(견적기준!$AB$6:$AB$233,견적기준!$H$6:$H$233,$C13,견적기준!$E$6:$E$233,견적기준통합!$D$3) -> 30 | E13: =SUMIFS(견적기준!$AB$6:$AB$233,견적기준!$H$6:$H$233,$C13,견적기준!$E$6:$E$233,견적기준통합!$E$3) -> 61.5 | F13: =SUMIFS(견적기준!$AB$6:$AB$233,견적기준!$H$6:$H$233,$C13,견적기준!$E$6:$E$233,견적기준통합!$F$3) -> 16.5 | G13: =SUMIFS(견적기준!$AB$6:$AB$233,견적기준!$H$6:$H$233,$C13,견적기준!$E$6:$E$233,견적기준통합!$G$3) -> 0 | H13: =SUM(D13:G13) -> 108 | I13: =H13/$H$17 -> 0.06077488 | L13: A&T | M13: =SUMIFS(견적기준!$M$6:$M$198,견적기준!$H$6:$H$198,견적기준통합!$L13) -> 4 | N13: =SUMIFS(견적기준!$N$6:$N$198,견적기준!$H$6:$H$198,견적기준통합!$L13) -> 6 | O13: =SUMIFS(견적기준!$O$6:O$198,견적기준!$H$6:$H$198,견적기준통합!$L13) -> 7 | P13: =SUMIFS(견적기준!$P$6:$P$198,견적기준!$H$6:$H$198,견적기준통합!$L13) -> 7 | Q13: =SUMIFS(견적기준!$Q$6:$Q$198,견적기준!$H$6:$H$198,견적기준통합!$L13) -> 9 | R13: =SUMIFS(견적기준!$R$6:$R$198,견적기준!$H$6:$H$198,견적기준통합!$L13) -> 9 | S13: =SUMIFS(견적기준!$S$6:$S$198,견적기준!$H$6:$H$198,견적기준통합!$L13) -> 9 | T13: =SUMIFS(견적기준!$T$6:$T$198,견적기준!$H$6:$H$198,견적기준통합!$L13) -> 9 | U13: =SUMIFS(견적기준!$U$6:$U$198,견적기준!$H$6:$H$198,견적기준통합!$L13) -> 9 | V13: =SUMIFS(견적기준!$V$6:$V$198,견적기준!$H$6:$H$198,견적기준통합!$L13) -> 9 | W13: =SUMIFS(견적기준!$W$6:$W$198,견적기준!$H$6:$H$198,견적기준통합!$L13) -> 8 | X13: =SUMIFS(견적기준!$X$6:$X$198,견적기준!$H$6:$H$198,견적기준통합!$L13) -> 8 | Y13: =SUMIFS(견적기준!$Y$6:$Y$198,견적기준!$H$6:$H$198,견적기준통합!$L13) -> 6 | Z13: =SUMIFS(견적기준!$Z$6:$Z$198,견적기준!$H$6:$H$198,견적기준통합!$L13) -> 4 | AA13: =SUMIFS(견적기준!$AA$6:$AA$198,견적기준!$H$6:$H$198,견적기준통합!$L13) -> 4 | AB13: =SUM(M13:AA13) -> 108
B14: 11 | C14: 오브젠 | D14: =SUMIFS(견적기준!$AB$6:$AB$233,견적기준!$H$6:$H$233,$C14,견적기준!$E$6:$E$233,견적기준통합!$D$3) -> 24 | E14: =SUMIFS(견적기준!$AB$6:$AB$233,견적기준!$H$6:$H$233,$C14,견적기준!$E$6:$E$233,견적기준통합!$E$3) -> 51 | F14: =SUMIFS(견적기준!$AB$6:$AB$233,견적기준!$H$6:$H$233,$C14,견적기준!$E$6:$E$233,견적기준통합!$F$3) -> 0 | G14: =SUMIFS(견적기준!$AB$6:$AB$233,견적기준!$H$6:$H$233,$C14,견적기준!$E$6:$E$233,견적기준통합!$G$3) -> 5 | H14: =SUM(D14:G14) -> 80 | I14: =H14/$H$17 -> 0.045018429 | L14: 오브젠 | M14: =SUMIFS(견적기준!$M$6:$M$198,견적기준!$H$6:$H$198,견적기준통합!$L14) -> 0 | N14: =SUMIFS(견적기준!$N$6:$N$198,견적기준!$H$6:$H$198,견적기준통합!$L14) -> 0 | O14: =SUMIFS(견적기준!$O$6:O$198,견적기준!$H$6:$H$198,견적기준통합!$L14) -> 0 | P14: =SUMIFS(견적기준!$P$6:$P$198,견적기준!$H$6:$H$198,견적기준통합!$L14) -> 0 | Q14: =SUMIFS(견적기준!$Q$6:$Q$198,견적기준!$H$6:$H$198,견적기준통합!$L14) -> 0 | R14: =SUMIFS(견적기준!$R$6:$R$198,견적기준!$H$6:$H$198,견적기준통합!$L14) -> 0 | S14: =SUMIFS(견적기준!$S$6:$S$198,견적기준!$H$6:$H$198,견적기준통합!$L14) -> 5 | T14: =SUMIFS(견적기준!$T$6:$T$198,견적기준!$H$6:$H$198,견적기준통합!$L14) -> 8 | U14: =SUMIFS(견적기준!$U$6:$U$198,견적기준!$H$6:$H$198,견적기준통합!$L14) -> 9 | V14: =SUMIFS(견적기준!$V$6:$V$198,견적기준!$H$6:$H$198,견적기준통합!$L14) -> 10 | W14: =SUMIFS(견적기준!$W$6:$W$198,견적기준!$H$6:$H$198,견적기준통합!$L14) -> 12 | X14: =SUMIFS(견적기준!$X$6:$X$198,견적기준!$H$6:$H$198,견적기준통합!$L14) -> 12 | Y14: =SUMIFS(견적기준!$Y$6:$Y$198,견적기준!$H$6:$H$198,견적기준통합!$L14) -> 12 | Z14: =SUMIFS(견적기준!$Z$6:$Z$198,견적기준!$H$6:$H$198,견적기준통합!$L14) -> 12 | AA14: =SUMIFS(견적기준!$AA$6:$AA$198,견적기준!$H$6:$H$198,견적기준통합!$L14) -> 0 | AB14: =SUM(M14:AA14) -> 80
B15: 12 | C15: 골든플래닛 | D15: =SUMIFS(견적기준!$AB$6:$AB$233,견적기준!$H$6:$H$233,$C15,견적기준!$E$6:$E$233,견적기준통합!$D$3) -> 0 | E15: =SUMIFS(견적기준!$AB$6:$AB$233,견적기준!$H$6:$H$233,$C15,견적기준!$E$6:$E$233,견적기준통합!$E$3) -> 0 | F15: =SUMIFS(견적기준!$AB$6:$AB$233,견적기준!$H$6:$H$233,$C15,견적기준!$E$6:$E$233,견적기준통합!$F$3) -> 6.3 | G15: =SUMIFS(견적기준!$AB$6:$AB$233,견적기준!$H$6:$H$233,$C15,견적기준!$E$6:$E$233,견적기준통합!$G$3) -> 0 | H15: =SUM(D15:G15) -> 6.3 | I15: =H15/$H$17 -> 0.0035452013 | L15: 골든플래닛 | M15: =SUMIFS(견적기준!$M$6:$M$198,견적기준!$H$6:$H$198,견적기준통합!$L15) -> 0 | N15: =SUMIFS(견적기준!$N$6:$N$198,견적기준!$H$6:$H$198,견적기준통합!$L15) -> 0 | O15: =SUMIFS(견적기준!$O$6:O$198,견적기준!$H$6:$H$198,견적기준통합!$L15) -> 0 | P15: =SUMIFS(견적기준!$P$6:$P$198,견적기준!$H$6:$H$198,견적기준통합!$L15) -> 1 | Q15: =SUMIFS(견적기준!$Q$6:$Q$198,견적기준!$H$6:$H$198,견적기준통합!$L15) -> 1 | R15: =SUMIFS(견적기준!$R$6:$R$198,견적기준!$H$6:$H$198,견적기준통합!$L15) -> 1 | S15: =SUMIFS(견적기준!$S$6:$S$198,견적기준!$H$6:$H$198,견적기준통합!$L15) -> 1 | T15: =SUMIFS(견적기준!$T$6:$T$198,견적기준!$H$6:$H$198,견적기준통합!$L15) -> 1 | U15: =SUMIFS(견적기준!$U$6:$U$198,견적기준!$H$6:$H$198,견적기준통합!$L15) -> 1 | V15: =SUMIFS(견적기준!$V$6:$V$198,견적기준!$H$6:$H$198,견적기준통합!$L15) -> 0.3 | W15: =SUMIFS(견적기준!$W$6:$W$198,견적기준!$H$6:$H$198,견적기준통합!$L15) -> 0 | X15: =SUMIFS(견적기준!$X$6:$X$198,견적기준!$H$6:$H$198,견적기준통합!$L15) -> 0 | Y15: =SUMIFS(견적기준!$Y$6:$Y$198,견적기준!$H$6:$H$198,견적기준통합!$L15) -> 0 | Z15: =SUMIFS(견적기준!$Z$6:$Z$198,견적기준!$H$6:$H$198,견적기준통합!$L15) -> 0 | AA15: =SUMIFS(견적기준!$AA$6:$AA$198,견적기준!$H$6:$H$198,견적기준통합!$L15) -> 0 | AB15: =SUM(M15:AA15) -> 6.3
B16: 14 | C16: 플레이투게더 | D16: =SUMIFS(견적기준!$AB$6:$AB$233,견적기준!$H$6:$H$233,$C16,견적기준!$E$6:$E$233,견적기준통합!$D$3) -> 0 | E16: =SUMIFS(견적기준!$AB$6:$AB$233,견적기준!$H$6:$H$233,$C16,견적기준!$E$6:$E$233,견적기준통합!$E$3) -> 66.5 | F16: =SUMIFS(견적기준!$AB$6:$AB$233,견적기준!$H$6:$H$233,$C16,견적기준!$E$6:$E$233,견적기준통합!$F$3) -> 19.5 | G16: =SUMIFS(견적기준!$AB$6:$AB$233,견적기준!$H$6:$H$233,$C16,견적기준!$E$6:$E$233,견적기준통합!$G$3) -> 6 | H16: =SUM(D16:G16) -> 92 | I16: =H16/$H$17 -> 0.051771194 | L16: 플레이투게더 | M16: =SUMIFS(견적기준!$M$6:$M$198,견적기준!$H$6:$H$198,견적기준통합!$L16) -> 0 | N16: =SUMIFS(견적기준!$N$6:$N$198,견적기준!$H$6:$H$198,견적기준통합!$L16) -> 4 | O16: =SUMIFS(견적기준!$O$6:O$198,견적기준!$H$6:$H$198,견적기준통합!$L16) -> 4 | P16: =SUMIFS(견적기준!$P$6:$P$198,견적기준!$H$6:$H$198,견적기준통합!$L16) -> 4 | Q16: =SUMIFS(견적기준!$Q$6:$Q$198,견적기준!$H$6:$H$198,견적기준통합!$L16) -> 7.5 | R16: =SUMIFS(견적기준!$R$6:$R$198,견적기준!$H$6:$H$198,견적기준통합!$L16) -> 9 | S16: =SUMIFS(견적기준!$S$6:$S$198,견적기준!$H$6:$H$198,견적기준통합!$L16) -> 9 | T16: =SUMIFS(견적기준!$T$6:$T$198,견적기준!$H$6:$H$198,견적기준통합!$L16) -> 9 | U16: =SUMIFS(견적기준!$U$6:$U$198,견적기준!$H$6:$H$198,견적기준통합!$L16) -> 9 | V16: =SUMIFS(견적기준!$V$6:$V$198,견적기준!$H$6:$H$198,견적기준통합!$L16) -> 9 | W16: =SUMIFS(견적기준!$W$6:$W$198,견적기준!$H$6:$H$198,견적기준통합!$L16) -> 8 | X16: =SUMIFS(견적기준!$X$6:$X$198,견적기준!$H$6:$H$198,견적기준통합!$L16) -> 7 | Y16: =SUMIFS(견적기준!$Y$6:$Y$198,견적기준!$H$6:$H$198,견적기준통합!$L16) -> 7 | Z16: =SUMIFS(견적기준!$Z$6:$Z$198,견적기준!$H$6:$H$198,견적기준통합!$L16) -> 5.5 | AA16: =SUMIFS(견적기준!$AA$6:$AA$198,견적기준!$H$6:$H$198,견적기준통합!$L16) -> 0 | AB16: =SUM(M16:AA16) -> 92
B17: 총계 | D17: =SUM(D4:D16) -> 419 | E17: =SUM(E4:E16) -> 640 | F17: =SUM(F4:F16) -> 392.55 | G17: =SUM(G4:G16) -> 325.5 | H17: =SUM(H4:H16) -> 1777.05 | I17: =H17/$H$17 -> 1 | L17: 총계 | M17: =SUM(M4:M16) -> 58.25 | N17: =SUM(N4:N16) -> 73.75 | O17: =SUM(O4:O16) -> 85 | P17: =SUM(P4:P16) -> 93.5 | Q17: =SUM(Q4:Q16) -> 140.25 | R17: =SUM(R4:R16) -> 140.5 | S17: =SUM(S4:S16) -> 144.5 | T17: =SUM(T4:T16) -> 147.5 | ... AB17: =SUM(AB4:AB16) -> 1777.05
L19: 자연인
L20: 협력사 | M20: 2월 | N20: 3월 | O20: 4월 | P20: 5월 | Q20: 6월 | R20: 7월 | S20: 8월 | T20: 9월 | U20: 10월 | V20: 11월 | W20: 12월 | X20: 1월 | Y20: 2월 | Z20: 3월 | AA20: 4월 | AB20: 총계
L21: kt ds | M21: =COUNTIFS(견적기준!$M$6:$M$198,">0",견적기준!$H$6:$H$198,견적기준통합!$L21) -> 16 | N21: =COUNTIFS(견적기준!$N$6:$N$198,">0",견적기준!$H$6:$H$198,견적기준통합!$L21) -> 17 | O21: =COUNTIFS(견적기준!$O$6:$O$198,">0",견적기준!$H$6:$H$198,견적기준통합!$L21) -> 21 | P21: =COUNTIFS(견적기준!$P$6:$P$198,">0",견적기준!$H$6:$H$198,견적기준통합!$L21) -> 22 | Q21: =COUNTIFS(견적기준!$Q$6:$Q$198,">0",견적기준!$H$6:$H$198,견적기준통합!$L21) -> 23 | R21: =COUNTIFS(견적기준!$R$6:$R$198,">0",견적기준!$H$6:$H$198,견적기준통합!$L21) -> 24 | S21: =COUNTIFS(견적기준!$S$6:$S$198,">0",견적기준!$H$6:$H$198,견적기준통합!$L21) -> 23 | T21: =COUNTIFS(견적기준!$T$6:$T$198,">0",견적기준!$H$6:$H$198,견적기준통합!$L21) -> 25 | U21: =COUNTIFS(견적기준!$U$6:$U$198,">0",견적기준!$H$6:$H$198,견적기준통합!$L21) -> 26 | V21: =COUNTIFS(견적기준!$V$6:$V$198,">0",견적기준!$H$6:$H$198,견적기준통합!$L21) -> 29 | W21: =COUNTIFS(견적기준!$W$6:$W$198,">0",견적기준!$H$6:$H$198,견적기준통합!$L21) -> 27 | X21: =COUNTIFS(견적기준!$X$6:$X$198,">0",견적기준!$H$6:$H$198,견적기준통합!$L21) -> 27 | Y21: =COUNTIFS(견적기준!$Y$6:$Y$198,">0",견적기준!$H$6:$H$198,견적기준통합!$L21) -> 21 | Z21: =COUNTIFS(견적기준!$Z$6:$Z$198,">0",견적기준!$H$6:$H$198,견적기준통합!$L21) -> 16 | AA21: =COUNTIFS(견적기준!$AA$6:$AA$198,">0",견적기준!$H$6:$H$198,견적기준통합!$L21) -> 8 | AB21: =SUM(M21:AA21) -> 325
L22: SGSecurity | M22: =COUNTIFS(견적기준!$M$6:$M$198,">0",견적기준!$H$6:$H$198,견적기준통합!$L22) -> 0 | N22: =COUNTIFS(견적기준!$N$6:$N$198,">0",견적기준!$H$6:$H$198,견적기준통합!$L22) -> 0 | O22: =COUNTIFS(견적기준!$O$6:$O$198,">0",견적기준!$H$6:$H$198,견적기준통합!$L22) -> 1 | P22: =COUNTIFS(견적기준!$P$6:$P$198,">0",견적기준!$H$6:$H$198,견적기준통합!$L22) -> 1 | Q22: =COUNTIFS(견적기준!$Q$6:$Q$198,">0",견적기준!$H$6:$H$198,견적기준통합!$L22) -> 0 | R22: =COUNTIFS(견적기준!$R$6:$R$198,">0",견적기준!$H$6:$H$198,견적기준통합!$L22) -> 0 | S22: =COUNTIFS(견적기준!$S$6:$S$198,">0",견적기준!$H$6:$H$198,견적기준통합!$L22) -> 0 | T22: =COUNTIFS(견적기준!$T$6:$T$198,">0",견적기준!$H$6:$H$198,견적기준통합!$L22) -> 0 | U22: =COUNTIFS(견적기준!$U$6:$U$198,">0",견적기준!$H$6:$H$198,견적기준통합!$L22) -> 0 | V22: =COUNTIFS(견적기준!$V$6:$V$198,">0",견적기준!$H$6:$H$198,견적기준통합!$L22) -> 1 | W22: =COUNTIFS(견적기준!$W$6:$W$198,">0",견적기준!$H$6:$H$198,견적기준통합!$L22) -> 2 | X22: =COUNTIFS(견적기준!$X$6:$X$198,">0",견적기준!$H$6:$H$198,견적기준통합!$L22) -> 2 | Y22: =COUNTIFS(견적기준!$Y$6:$Y$198,">0",견적기준!$H$6:$H$198,견적기준통합!$L22) -> 2 | Z22: =COUNTIFS(견적기준!$Z$6:$Z$198,">0",견적기준!$H$6:$H$198,견적기준통합!$L22) -> 0 | AA22: =COUNTIFS(견적기준!$AA$6:$AA$198,">0",견적기준!$H$6:$H$198,견적기준통합!$L22) -> 0 | AB22: =SUM(M22:AA22) -> 9
L23: 비플컨설팅 | M23: =COUNTIFS(견적기준!$M$6:$M$198,">0",견적기준!$H$6:$H$198,견적기준통합!$L23) -> 0 | N23: =COUNTIFS(견적기준!$N$6:$N$198,">0",견적기준!$H$6:$H$198,견적기준통합!$L23) -> 0 | O23: =COUNTIFS(견적기준!$O$6:$O$198,">0",견적기준!$H$6:$H$198,견적기준통합!$L23) -> 0 | P23: =COUNTIFS(견적기준!$P$6:$P$198,">0",견적기준!$H$6:$H$198,견적기준통합!$L23) -> 2 | Q23: =COUNTIFS(견적기준!$Q$6:$Q$198,">0",견적기준!$H$6:$H$198,견적기준통합!$L23) -> 7 | R23: =COUNTIFS(견적기준!$R$6:$R$198,">0",견적기준!$H$6:$H$198,견적기준통합!$L23) -> 7 | S23: =COUNTIFS(견적기준!$S$6:$S$198,">0",견적기준!$H$6:$H$198,견적기준통합!$L23) -> 7 | T23: =COUNTIFS(견적기준!$T$6:$T$198,">0",견적기준!$H$6:$H$198,견적기준통합!$L23) -> 7 | U23: =COUNTIFS(견적기준!$U$6:$U$198,">0",견적기준!$H$6:$H$198,견적기준통합!$L23) -> 8 | V23: =COUNTIFS(견적기준!$V$6:$V$198,">0",견적기준!$H$6:$H$198,견적기준통합!$L23) -> 8 | W23: =COUNTIFS(견적기준!$W$6:$W$198,">0",견적기준!$H$6:$H$198,견적기준통합!$L23) -> 7 | X23: =COUNTIFS(견적기준!$X$6:$X$198,">0",견적기준!$H$6:$H$198,견적기준통합!$L23) -> 7 | Y23: =COUNTIFS(견적기준!$Y$6:$Y$198,">0",견적기준!$H$6:$H$198,견적기준통합!$L23) -> 7 | Z23: =COUNTIFS(견적기준!$Z$6:$Z$198,">0",견적기준!$H$6:$H$198,견적기준통합!$L23) -> 7 | AA23: =COUNTIFS(견적기준!$AA$6:$AA$198,">0",견적기준!$H$6:$H$198,견적기준통합!$L23) -> 0 | AB23: =SUM(M23:AA23) -> 74
L24: 이너웨이브 | M24: =COUNTIFS(견적기준!$M$6:$M$198,">0",견적기준!$H$6:$H$198,견적기준통합!$L24) -> 2 | N24: =COUNTIFS(견적기준!$N$6:$N$198,">0",견적기준!$H$6:$H$198,견적기준통합!$L24) -> 4 | O24: =COUNTIFS(견적기준!$O$6:$O$198,">0",견적기준!$H$6:$H$198,견적기준통합!$L24) -> 5 | P24: =COUNTIFS(견적기준!$P$6:$P$198,">0",견적기준!$H$6:$H$198,견적기준통합!$L24) -> 5 | Q24: =COUNTIFS(견적기준!$Q$6:$Q$198,">0",견적기준!$H$6:$H$198,견적기준통합!$L24) -> 4 | R24: =COUNTIFS(견적기준!$R$6:$R$198,">0",견적기준!$H$6:$H$198,견적기준통합!$L24) -> 5 | S24: =COUNTIFS(견적기준!$S$6:$S$198,">0",견적기준!$H$6:$H$198,견적기준통합!$L24) -> 4 | T24: =COUNTIFS(견적기준!$T$6:$T$198,">0",견적기준!$H$6:$H$198,견적기준통합!$L24) -> 3 | U24: =COUNTIFS(견적기준!$U$6:$U$198,">0",견적기준!$H$6:$H$198,견적기준통합!$L24) -> 3 | V24: =COUNTIFS(견적기준!$V$6:$V$198,">0",견적기준!$H$6:$H$198,견적기준통합!$L24) -> 2 | W24: =COUNTIFS(견적기준!$W$6:$W$198,">0",견적기준!$H$6:$H$198,견적기준통합!$L24) -> 2 | X24: =COUNTIFS(견적기준!$X$6:$X$198,">0",견적기준!$H$6:$H$198,견적기준통합!$L24) -> 2 | Y24: =COUNTIFS(견적기준!$Y$6:$Y$198,">0",견적기준!$H$6:$H$198,견적기준통합!$L24) -> 2 | Z24: =COUNTIFS(견적기준!$Z$6:$Z$198,">0",견적기준!$H$6:$H$198,견적기준통합!$L24) -> 2 | AA24: =COUNTIFS(견적기준!$AA$6:$AA$198,">0",견적기준!$H$6:$H$198,견적기준통합!$L24) -> 2 | AB24: =SUM(M24:AA24) -> 47
L25: 바이널씨 | M25: =COUNTIFS(견적기준!$M$6:$M$198,">0",견적기준!$H$6:$H$198,견적기준통합!$L25) -> 11 | N25: =COUNTIFS(견적기준!$N$6:$N$198,">0",견적기준!$H$6:$H$198,견적기준통합!$L25) -> 12 | O25: =COUNTIFS(견적기준!$O$6:$O$198,">0",견적기준!$H$6:$H$198,견적기준통합!$L25) -> 15 | P25: =COUNTIFS(견적기준!$P$6:$P$198,">0",견적기준!$H$6:$H$198,견적기준통합!$L25) -> 15 | Q25: =COUNTIFS(견적기준!$Q$6:$Q$198,">0",견적기준!$H$6:$H$198,견적기준통합!$L25) -> 15 | R25: =COUNTIFS(견적기준!$R$6:$R$198,">0",견적기준!$H$6:$H$198,견적기준통합!$L25) -> 14 | S25: =COUNTIFS(견적기준!$S$6:$S$198,">0",견적기준!$H$6:$H$198,견적기준통합!$L25) -> 14 | T25: =COUNTIFS(견적기준!$T$6:$T$198,">0",견적기준!$H$6:$H$198,견적기준통합!$L25) -> 14 | U25: =COUNTIFS(견적기준!$U$6:$U$198,">0",견적기준!$H$6:$H$198,견적기준통합!$L25) -> 14 | V25: =COUNTIFS(견적기준!$V$6:$V$198,">0",견적기준!$H$6:$H$198,견적기준통합!$L25) -> 12 | W25: =COUNTIFS(견적기준!$W$6:$W$198,">0",견적기준!$H$6:$H$198,견적기준통합!$L25) -> 11 | X25: =COUNTIFS(견적기준!$X$6:$X$198,">0",견적기준!$H$6:$H$198,견적기준통합!$L25) -> 10 | Y25: =COUNTIFS(견적기준!$Y$6:$Y$198,">0",견적기준!$H$6:$H$198,견적기준통합!$L25) -> 9 | Z25: =COUNTIFS(견적기준!$Z$6:$Z$198,">0",견적기준!$H$6:$H$198,견적기준통합!$L25) -> 7 | AA25: =COUNTIFS(견적기준!$AA$6:$AA$198,">0",견적기준!$H$6:$H$198,견적기준통합!$L25) -> 4 | AB25: =SUM(M25:AA25) -> 177
L26: 커머스웨어 | M26: =COUNTIFS(견적기준!$M$6:$M$198,">0",견적기준!$H$6:$H$198,견적기준통합!$L26) -> 16 | N26: =COUNTIFS(견적기준!$N$6:$N$198,">0",견적기준!$H$6:$H$198,견적기준통합!$L26) -> 16 | O26: =COUNTIFS(견적기준!$O$6:$O$198,">0",견적기준!$H$6:$H$198,견적기준통합!$L26) -> 16 | P26: =COUNTIFS(견적기준!$P$6:$P$198,">0",견적기준!$H$6:$H$198,견적기준통합!$L26) -> 17 | Q26: =COUNTIFS(견적기준!$Q$6:$Q$198,">0",견적기준!$H$6:$H$198,견적기준통합!$L26) -> 42 | R26: =COUNTIFS(견적기준!$R$6:$R$198,">0",견적기준!$H$6:$H$198,견적기준통합!$L26) -> 42 | S26: =COUNTIFS(견적기준!$S$6:$S$198,">0",견적기준!$H$6:$H$198,견적기준통합!$L26) -> 45 | T26: =COUNTIFS(견적기준!$T$6:$T$198,">0",견적기준!$H$6:$H$198,견적기준통합!$L26) -> 45 | U26: =COUNTIFS(견적기준!$U$6:$U$198,">0",견적기준!$H$6:$H$198,견적기준통합!$L26) -> 45 | V26: =COUNTIFS(견적기준!$V$6:$V$198,">0",견적기준!$H$6:$H$198,견적기준통합!$L26) -> 45 | W26: =COUNTIFS(견적기준!$W$6:$W$198,">0",견적기준!$H$6:$H$198,견적기준통합!$L26) -> 45 | X26: =COUNTIFS(견적기준!$X$6:$X$198,">0",견적기준!$H$6:$H$198,견적기준통합!$L26) -> 45 | Y26: =COUNTIFS(견적기준!$Y$6:$Y$198,">0",견적기준!$H$6:$H$198,견적기준통합!$L26) -> 45 | Z26: =COUNTIFS(견적기준!$Z$6:$Z$198,">0",견적기준!$H$6:$H$198,견적기준통합!$L26) -> 45 | AA26: =COUNTIFS(견적기준!$AA$6:$AA$198,">0",견적기준!$H$6:$H$198,견적기준통합!$L26) -> 26 | AB26: =SUM(M26:AA26) -> 535
L27: 아이온 | M27: =COUNTIFS(견적기준!$M$6:$M$198,">0",견적기준!$H$6:$H$198,견적기준통합!$L27) -> 2 | N27: =COUNTIFS(견적기준!$N$6:$N$198,">0",견적기준!$H$6:$H$198,견적기준통합!$L27) -> 2 | O27: =COUNTIFS(견적기준!$O$6:$O$198,">0",견적기준!$H$6:$H$198,견적기준통합!$L27) -> 1 | P27: =COUNTIFS(견적기준!$P$6:$P$198,">0",견적기준!$H$6:$H$198,견적기준통합!$L27) -> 1 | Q27: =COUNTIFS(견적기준!$Q$6:$Q$198,">0",견적기준!$H$6:$H$198,견적기준통합!$L27) -> 7 | R27: =COUNTIFS(견적기준!$R$6:$R$198,">0",견적기준!$H$6:$H$198,견적기준통합!$L27) -> 5 | S27: =COUNTIFS(견적기준!$S$6:$S$198,">0",견적기준!$H$6:$H$198,견적기준통합!$L27) -> 5 | T27: =COUNTIFS(견적기준!$T$6:$T$198,">0",견적기준!$H$6:$H$198,견적기준통합!$L27) -> 5 | U27: =COUNTIFS(견적기준!$U$6:$U$198,">0",견적기준!$H$6:$H$198,견적기준통합!$L27) -> 5 | V27: =COUNTIFS(견적기준!$V$6:$V$198,">0",견적기준!$H$6:$H$198,견적기준통합!$L27) -> 5 | W27: =COUNTIFS(견적기준!$W$6:$W$198,">0",견적기준!$H$6:$H$198,견적기준통합!$L27) -> 6 | X27: =COUNTIFS(견적기준!$X$6:$X$198,">0",견적기준!$H$6:$H$198,견적기준통합!$L27) -> 5 | Y27: =COUNTIFS(견적기준!$Y$6:$Y$198,">0",견적기준!$H$6:$H$198,견적기준통합!$L27) -> 5 | Z27: =COUNTIFS(견적기준!$Z$6:$Z$198,">0",견적기준!$H$6:$H$198,견적기준통합!$L27) -> 1 | AA27: =COUNTIFS(견적기준!$AA$6:$AA$198,">0",견적기준!$H$6:$H$198,견적기준통합!$L27) -> 1 | AB27: =SUM(M27:AA27) -> 56
L28: 씨엔씨네트웍스 | M28: =COUNTIFS(견적기준!$M$6:$M$198,">0",견적기준!$H$6:$H$198,견적기준통합!$L28) -> 2 | N28: =COUNTIFS(견적기준!$N$6:$N$198,">0",견적기준!$H$6:$H$198,견적기준통합!$L28) -> 3 | O28: =COUNTIFS(견적기준!$O$6:$O$198,">0",견적기준!$H$6:$H$198,견적기준통합!$L28) -> 5 | P28: =COUNTIFS(견적기준!$P$6:$P$198,">0",견적기준!$H$6:$H$198,견적기준통합!$L28) -> 6 | Q28: =COUNTIFS(견적기준!$Q$6:$Q$198,">0",견적기준!$H$6:$H$198,견적기준통합!$L28) -> 8 | R28: =COUNTIFS(견적기준!$R$6:$R$198,">0",견적기준!$H$6:$H$198,견적기준통합!$L28) -> 8 | S28: =COUNTIFS(견적기준!$S$6:$S$198,">0",견적기준!$H$6:$H$198,견적기준통합!$L28) -> 8 | T28: =COUNTIFS(견적기준!$T$6:$T$198,">0",견적기준!$H$6:$H$198,견적기준통합!$L28) -> 8 | U28: =COUNTIFS(견적기준!$U$6:$U$198,">0",견적기준!$H$6:$H$198,견적기준통합!$L28) -> 8 | V28: =COUNTIFS(견적기준!$V$6:$V$198,">0",견적기준!$H$6:$H$198,견적기준통합!$L28) -> 8 | W28: =COUNTIFS(견적기준!$W$6:$W$198,">0",견적기준!$H$6:$H$198,견적기준통합!$L28) -> 8 | X28: =COUNTIFS(견적기준!$X$6:$X$198,">0",견적기준!$H$6:$H$198,견적기준통합!$L28) -> 8 | Y28: =COUNTIFS(견적기준!$Y$6:$Y$198,">0",견적기준!$H$6:$H$198,견적기준통합!$L28) -> 8 | Z28: =COUNTIFS(견적기준!$Z$6:$Z$198,">0",견적기준!$H$6:$H$198,견적기준통합!$L28) -> 7 | AA28: =COUNTIFS(견적기준!$AA$6:$AA$198,">0",견적기준!$H$6:$H$198,견적기준통합!$L28) -> 3 | AB28: =SUM(M28:AA28) -> 98
L29: 투비소프트 | M29: =COUNTIFS(견적기준!$M$6:$M$198,">0",견적기준!$H$6:$H$198,견적기준통합!$L29) -> 6 | N29: =COUNTIFS(견적기준!$N$6:$N$198,">0",견적기준!$H$6:$H$198,견적기준통합!$L29) -> 12 | O29: =COUNTIFS(견적기준!$O$6:$O$198,">0",견적기준!$H$6:$H$198,견적기준통합!$L29) -> 12 | P29: =COUNTIFS(견적기준!$P$6:$P$198,">0",견적기준!$H$6:$H$198,견적기준통합!$L29) -> 15 | Q29: =COUNTIFS(견적기준!$Q$6:$Q$198,">0",견적기준!$H$6:$H$198,견적기준통합!$L29) -> 22 | R29: =COUNTIFS(견적기준!$R$6:$R$198,">0",견적기준!$H$6:$H$198,견적기준통합!$L29) -> 19 | S29: =COUNTIFS(견적기준!$S$6:$S$198,">0",견적기준!$H$6:$H$198,견적기준통합!$L29) -> 17 | T29: =COUNTIFS(견적기준!$T$6:$T$198,">0",견적기준!$H$6:$H$198,견적기준통합!$L29) -> 17 | U29: =COUNTIFS(견적기준!$U$6:$U$198,">0",견적기준!$H$6:$H$198,견적기준통합!$L29) -> 17 | V29: =COUNTIFS(견적기준!$V$6:$V$198,">0",견적기준!$H$6:$H$198,견적기준통합!$L29) -> 17 | W29: =COUNTIFS(견적기준!$W$6:$W$198,">0",견적기준!$H$6:$H$198,견적기준통합!$L29) -> 16 | X29: =COUNTIFS(견적기준!$X$6:$X$198,">0",견적기준!$H$6:$H$198,견적기준통합!$L29) -> 16 | Y29: =COUNTIFS(견적기준!$Y$6:$Y$198,">0",견적기준!$H$6:$H$198,견적기준통합!$L29) -> 15 | Z29: =COUNTIFS(견적기준!$Z$6:$Z$198,">0",견적기준!$H$6:$H$198,견적기준통합!$L29) -> 13 | AA29: =COUNTIFS(견적기준!$AA$6:$AA$198,">0",견적기준!$H$6:$H$198,견적기준통합!$L29) -> 7 | AB29: =SUM(M29:AA29) -> 221
L30: A&T | M30: =COUNTIFS(견적기준!$M$6:$M$198,">0",견적기준!$H$6:$H$198,견적기준통합!$L30) -> 4 | N30: =COUNTIFS(견적기준!$N$6:$N$198,">0",견적기준!$H$6:$H$198,견적기준통합!$L30) -> 7 | O30: =COUNTIFS(견적기준!$O$6:$O$198,">0",견적기준!$H$6:$H$198,견적기준통합!$L30) -> 7 | P30: =COUNTIFS(견적기준!$P$6:$P$198,">0",견적기준!$H$6:$H$198,견적기준통합!$L30) -> 7 | Q30: =COUNTIFS(견적기준!$Q$6:$Q$198,">0",견적기준!$H$6:$H$198,견적기준통합!$L30) -> 9 | R30: =COUNTIFS(견적기준!$R$6:$R$198,">0",견적기준!$H$6:$H$198,견적기준통합!$L30) -> 9 | S30: =COUNTIFS(견적기준!$S$6:$S$198,">0",견적기준!$H$6:$H$198,견적기준통합!$L30) -> 9 | T30: =COUNTIFS(견적기준!$T$6:$T$198,">0",견적기준!$H$6:$H$198,견적기준통합!$L30) -> 9 | U30: =COUNTIFS(견적기준!$U$6:$U$198,">0",견적기준!$H$6:$H$198,견적기준통합!$L30) -> 9 | V30: =COUNTIFS(견적기준!$V$6:$V$198,">0",견적기준!$H$6:$H$198,견적기준통합!$L30) -> 9 | W30: =COUNTIFS(견적기준!$W$6:$W$198,">0",견적기준!$H$6:$H$198,견적기준통합!$L30) -> 8 | X30: =COUNTIFS(견적기준!$X$6:$X$198,">0",견적기준!$H$6:$H$198,견적기준통합!$L30) -> 8 | Y30: =COUNTIFS(견적기준!$Y$6:$Y$198,">0",견적기준!$H$6:$H$198,견적기준통합!$L30) -> 6 | Z30: =COUNTIFS(견적기준!$Z$6:$Z$198,">0",견적기준!$H$6:$H$198,견적기준통합!$L30) -> 4 | AA30: =COUNTIFS(견적기준!$AA$6:$AA$198,">0",견적기준!$H$6:$H$198,견적기준통합!$L30) -> 4 | AB30: =SUM(M30:AA30) -> 109
L31: 오브젠 | M31: =COUNTIFS(견적기준!$M$6:$M$198,">0",견적기준!$H$6:$H$198,견적기준통합!$L31) -> 0 | N31: =COUNTIFS(견적기준!$N$6:$N$198,">0",견적기준!$H$6:$H$198,견적기준통합!$L31) -> 0 | O31: =COUNTIFS(견적기준!$O$6:$O$198,">0",견적기준!$H$6:$H$198,견적기준통합!$L31) -> 0 | P31: =COUNTIFS(견적기준!$P$6:$P$198,">0",견적기준!$H$6:$H$198,견적기준통합!$L31) -> 0 | Q31: =COUNTIFS(견적기준!$Q$6:$Q$198,">0",견적기준!$H$6:$H$198,견적기준통합!$L31) -> 0 | R31: =COUNTIFS(견적기준!$R$6:$R$198,">0",견적기준!$H$6:$H$198,견적기준통합!$L31) -> 0 | S31: =COUNTIFS(견적기준!$S$6:$S$198,">0",견적기준!$H$6:$H$198,견적기준통합!$L31) -> 5 | T31: =COUNTIFS(견적기준!$T$6:$T$198,">0",견적기준!$H$6:$H$198,견적기준통합!$L31) -> 8 | U31: =COUNTIFS(견적기준!$U$6:$U$198,">0",견적기준!$H$6:$H$198,견적기준통합!$L31) -> 9 | V31: =COUNTIFS(견적기준!$V$6:$V$198,">0",견적기준!$H$6:$H$198,견적기준통합!$L31) -> 10 | W31: =COUNTIFS(견적기준!$W$6:$W$198,">0",견적기준!$H$6:$H$198,견적기준통합!$L31) -> 12 | X31: =COUNTIFS(견적기준!$X$6:$X$198,">0",견적기준!$H$6:$H$198,견적기준통합!$L31) -> 12 | Y31: =COUNTIFS(견적기준!$Y$6:$Y$198,">0",견적기준!$H$6:$H$198,견적기준통합!$L31) -> 12 | Z31: =COUNTIFS(견적기준!$Z$6:$Z$198,">0",견적기준!$H$6:$H$198,견적기준통합!$L31) -> 12 | AA31: =COUNTIFS(견적기준!$AA$6:$AA$198,">0",견적기준!$H$6:$H$198,견적기준통합!$L31) -> 0 | AB31: =SUM(M31:AA31) -> 80
